Workbook
Name סביבות: 'הגדרות'!$A$2:$A$7
Name הדפסים: 'הגדרות'!$A$11:$D$25
Name שמות_הדפסים: 'הגדרות'!$A$11:$A$25
Name קווי_מוצר: 'הגדרות'!$A$29:$A$36
Name מוצרים: 'הגדרות'!$A$40:$C$63
Name OverGarment: 'הגדרות'!$B$40:$B$51
Name Hide_Site: 'הגדרות'!$B$52:$B$54
Name Platform_Hide_Site: 'הגדרות'!$B$55:$B$55
Name Uniform: 'הגדרות'!$B$56:$B$57
Name Blankets: 'הגדרות'!$B$58:$B$59
Name Urban: 'הגדרות'!$B$60:$B$60
Name Platform_On_The_Move: 'הגדרות'!$B$61:$B$62
Name Accessories: 'הגדרות'!$B$63:$B$63
Name סוגי_בד: 'הגדרות'!$A$67:$A$78
Name סטטוסים: 'הגדרות'!$A$82:$A$85
Name כן_לא: 'הגדרות'!$A$89:$A$90
Name מידות: 'הגדרות'!$A$94:$A$100
Name מקטים: 'הגדרות'!$A$104:$D$123

Sheet לוח בקרה
A1: סביבה | B1: קו מוצר | C1: מוצר | D1: גרסה | E1: סוג בד | F1: מידה
A2: הכל | B2: הכל | C2: הכל | D2: הכל | E2: הכל | F2: הכל
A3: סטטוס | B3: מדינה | C3: תקינות ויזואלית | D3: תקינות תרמית | E3: גרסה סופית
A4: הכל | B4: הכל | C4: הכל | D4: הכל | E4: הכל
A5: סיכום
A6: סה"כ פריטים תואמים | D6: =SUMPRODUCT((מלאי!$D$2:$500<>"")*(--מלאי!$AE$2:$500)*(IF($B$2="הכל",1,מלאי!$A$2:$500=$B$2))*(IF($C$2="הכל",1,מלאי!$B$2:$500=$C$2))*(IF($D$2="הכל",1,מלאי!$C$2:$500=$D$2))*(IF($E$2="הכל",1,מלאי!$G$2:$500=$E$2))*(IF($F$2="הכל",1,מלאי!$I$2:$500=$F$2))*(IF($A$4="הכל",1,מלאי!$X$2:$500=$A$4))*(IF($B$4="הכל",1,מלאי!$Z$2:$500=$B$4))*(IF($C$4="הכל",1,מלאי!$O$2:$500=$C$4))*(IF($D$4="הכל",1,מלאי!$U$2:$500=$D$4))*(IF($E$4="הכל",1,מלאי!$K$2:$500=$E$4)))
A7: כמות תקין לגמרי | D7: =SUMPRODUCT((מלאי!$D$2:$500<>"")*(--מלאי!$AE$2:$500)*(IF($B$2="הכל",1,מלאי!$A$2:$500=$B$2))*(IF($C$2="הכל",1,מלאי!$B$2:$500=$C$2))*(IF($D$2="הכל",1,מלאי!$C$2:$500=$D$2))*(IF($E$2="הכל",1,מלאי!$G$2:$500=$E$2))*(IF($F$2="הכל",1,מלאי!$I$2:$500=$F$2))*(IF($A$4="הכל",1,מלאי!$X$2:$500=$A$4))*(IF($B$4="הכל",1,מלאי!$Z$2:$500=$B$4))*(IF($C$4="הכל",1,מלאי!$O$2:$500=$C$4))*(IF($D$4="הכל",1,מלאי!$U$2:$500=$D$4))*(IF($E$4="הכל",1,מלאי!$K$2:$500=$E$4))*(--מלאי!$AF$2:$500))
A8: כמות תקין ויזואלית בלבד | D8: =SUMPRODUCT((מלאי!$D$2:$500<>"")*(--מלאי!$AE$2:$500)*(IF($B$2="הכל",1,מלאי!$A$2:$500=$B$2))*(IF($C$2="הכל",1,מלאי!$B$2:$500=$C$2))*(IF($D$2="הכל",1,מלאי!$C$2:$500=$D$2))*(IF($E$2="הכל",1,מלאי!$G$2:$500=$E$2))*(IF($F$2="הכל",1,מלאי!$I$2:$500=$F$2))*(IF($A$4="הכל",1,מלאי!$X$2:$500=$A$4))*(IF($B$4="הכל",1,מלאי!$Z$2:$500=$B$4))*(IF($C$4="הכל",1,מלאי!$O$2:$500=$C$4))*(IF($D$4="הכל",1,מלאי!$U$2:$500=$D$4))*(IF($E$4="הכל",1,מלאי!$K$2:$500=$E$4))*(--מלאי!$AG$2:$500))
A9: כמות תקין תרמית בלבד | D9: =SUMPRODUCT((מלאי!$D$2:$500<>"")*(--מלאי!$AE$2:$500)*(IF($B$2="הכל",1,מלאי!$A$2:$500=$B$2))*(IF($C$2="הכל",1,מלאי!$B$2:$500=$C$2))*(IF($D$2="הכל",1,מלאי!$C$2:$500=$D$2))*(IF($E$2="הכל",1,מלאי!$G$2:$500=$E$2))*(IF($F$2="הכל",1,מלאי!$I$2:$500=$F$2))*(IF($A$4="הכל",1,מלאי!$X$2:$500=$A$4))*(IF($B$4="הכל",1,מלאי!$Z$2:$500=$B$4))*(IF($C$4="הכל",1,מלאי!$O$2:$500=$C$4))*(IF($D$4="הכל",1,מלאי!$U$2:$500=$D$4))*(IF($E$4="הכל",1,מלאי!$K$2:$500=$E$4))*(--מלאי!$AH$2:$500))
A10: כמות במלאי | D10: =SUMPRODUCT((מלאי!$D$2:$500<>"")*(--מלאי!$AE$2:$500)*(IF($B$2="הכל",1,מלאי!$A$2:$500=$B$2))*(IF($C$2="הכל",1,מלאי!$B$2:$500=$C$2))*(IF($D$2="הכל",1,מלאי!$C$2:$500=$D$2))*(IF($E$2="הכל",1,מלאי!$G$2:$500=$E$2))*(IF($F$2="הכל",1,מלאי!$I$2:$500=$F$2))*(IF($A$4="הכל",1,מלאי!$X$2:$500=$A$4))*(IF($B$4="הכל",1,מלאי!$Z$2:$500=$B$4))*(IF($C$4="הכל",1,מלאי!$O$2:$500=$C$4))*(IF($D$4="הכל",1,מלאי!$U$2:$500=$D$4))*(IF($E$4="הכל",1,מלאי!$K$2:$500=$E$4))*(מלאי!$X$2:$500="במלאי"))
A11: כמות מושאלים | D11: =SUMPRODUCT((מלאי!$D$2:$500<>"")*(--מלאי!$AE$2:$500)*(IF($B$2="הכל",1,מלאי!$A$2:$500=$B$2))*(IF($C$2="הכל",1,מלאי!$B$2:$500=$C$2))*(IF($D$2="הכל",1,מלאי!$C$2:$500=$D$2))*(IF($E$2="הכל",1,מלאי!$G$2:$500=$E$2))*(IF($F$2="הכל",1,מלאי!$I$2:$500=$F$2))*(IF($A$4="הכל",1,מלאי!$X$2:$500=$A$4))*(IF($B$4="הכל",1,מלאי!$Z$2:$500=$B$4))*(IF($C$4="הכל",1,מלאי!$O$2:$500=$C$4))*(IF($D$4="הכל",1,מלאי!$U$2:$500=$D$4))*(IF($E$4="הכל",1,מלאי!$K$2:$500=$E$4))*(מלאי!$X$2:$500="מושאל"))
A12: כמות בחדר תצוגה | D12: =SUMPRODUCT((מלאי!$D$2:$500<>"")*(--מלאי!$AE$2:$500)*(IF($B$2="הכל",1,מלאי!$A$2:$500=$B$2))*(IF($C$2="הכל",1,מלאי!$B$2:$500=$C$2))*(IF($D$2="הכל",1,מלאי!$C$2:$500=$D$2))*(IF($E$2="הכל",1,מלאי!$G$2:$500=$E$2))*(IF($F$2="הכל",1,מלאי!$I$2:$500=$F$2))*(IF($A$4="הכל",1,מלאי!$X$2:$500=$A$4))*(IF($B$4="הכל",1,מלאי!$Z$2:$500=$B$4))*(IF($C$4="הכל",1,מלאי!$O$2:$500=$C$4))*(IF($D$4="הכל",1,מלאי!$U$2:$500=$D$4))*(IF($E$4="הכל",1,מלאי!$K$2:$500=$E$4))*(מלאי!$X$2:$500="בחדר תצוגה"))
A13: כמות בתיק הדגמה | D13: =SUMPRODUCT((מלאי!$D$2:$500<>"")*(--מלאי!$AE$2:$500)*(IF($B$2="הכל",1,מלאי!$A$2:$500=$B$2))*(IF($C$2="הכל",1,מלאי!$B$2:$500=$C$2))*(IF($D$2="הכל",1,מלאי!$C$2:$500=$D$2))*(IF($E$2="הכל",1,מלאי!$G$2:$500=$E$2))*(IF($F$2="הכל",1,מלאי!$I$2:$500=$F$2))*(IF($A$4="הכל",1,מלאי!$X$2:$500=$A$4))*(IF($B$4="הכל",1,מלאי!$Z$2:$500=$B$4))*(IF($C$4="הכל",1,מלאי!$O$2:$500=$C$4))*(IF($D$4="הכל",1,מלאי!$U$2:$500=$D$4))*(IF($E$4="הכל",1,מלאי!$K$2:$500=$E$4))*(מלאי!$X$2:$500="בתיק הדגמה"))
A14: כמות עם פער בתכולה | D14: =SUMPRODUCT((מלאי!$D$2:$500<>"")*(--מלאי!$AE$2:$500)*(IF($B$2="הכל",1,מלאי!$A$2:$500=$B$2))*(IF($C$2="הכל",1,מלאי!$B$2:$500=$C$2))*(IF($D$2="הכל",1,מלאי!$C$2:$500=$D$2))*(IF($E$2="הכל",1,מלאי!$G$2:$500=$E$2))*(IF($F$2="הכל",1,מלאי!$I$2:$500=$F$2))*(IF($A$4="הכל",1,מלאי!$X$2:$500=$A$4))*(IF($B$4="הכל",1,מלאי!$Z$2:$500=$B$4))*(IF($C$4="הכל",1,מלאי!$O$2:$500=$C$4))*(IF($D$4="הכל",1,מלאי!$U$2:$500=$D$4))*(IF($E$4="הכל",1,מלאי!$K$2:$500=$E$4))*(מלאי!$AD$2:$500="כן"))
A15: כמות גרסה מיוחדת - פיתוח | D15: =SUMPRODUCT((מלאי!$D$2:$500<>"")*(--מלאי!$AE$2:$500)*(IF($B$2="הכל",1,מלאי!$A$2:$500=$B$2))*(IF($C$2="הכל",1,מלאי!$B$2:$500=$C$2))*(IF($D$2="הכל",1,מלאי!$C$2:$500=$D$2))*(IF($E$2="הכל",1,מלאי!$G$2:$500=$E$2))*(IF($F$2="הכל",1,מלאי!$I$2:$500=$F$2))*(IF($A$4="הכל",1,מלאי!$X$2:$500=$A$4))*(IF($B$4="הכל",1,מלאי!$Z$2:$500=$B$4))*(IF($C$4="הכל",1,מלאי!$O$2:$500=$C$4))*(IF($D$4="הכל",1,מלאי!$U$2:$500=$D$4))*(IF($E$4="הכל",1,מלאי!$K$2:$500=$E$4))*(מלאי!$J$2:$500="כן"))
A16: תקינים ויזואלית אך הדפס לא מתאים לסביבה | D16: =IF($A$2="הכל","—",SUMPRODUCT((מלאי!$D$2:$500<>"")*(IF($B$2="הכל",1,מלאי!$A$2:$500=$B$2))*(IF($C$2="הכל",1,מלאי!$B$2:$500=$C$2))*(IF($D$2="הכל",1,מלאי!$C$2:$500=$D$2))*(IF($E$2="הכל",1,מלאי!$G$2:$500=$E$2))*(IF($F$2="הכל",1,מלאי!$I$2:$500=$F$2))*(IF($A$4="הכל",1,מלאי!$X$2:$500=$A$4))*(IF($B$4="הכל",1,מלאי!$Z$2:$500=$B$4))*(IF($C$4="הכל",1,מלאי!$O$2:$500=$C$4))*(IF($D$4="הכל",1,מלאי!$U$2:$500=$D$4))*(IF($E$4="הכל",1,מלאי!$K$2:$500=$E$4))*(מלאי!$AE$2:$500=FALSE)*((מלאי!$O$2:$500="כן")+(מלאי!$P$2:$500="כן")>0)))
A17: פירוט הדפסים שאינם מתאימים | D17: =IF($A$2="הכל","—",IFERROR(TEXTJOIN(", ",TRUE,UNIQUE(FILTER(מלאי!$M$2:$500,(מלאי!$D$2:$500<>"")*(מלאי!$AE$2:$500=FALSE)*((מלאי!$O$2:$500="כן")+(מלאי!$P$2:$500="כן")>0)))),""))
A19: פירוט פריטים מסוננים
A20: מזהה | B20: שם מוצר | C20: גרסה | D20: סוג בד | E20: הדפס A | F20: הדפס B | G20: תקין ויזואלי | H20: תקין תרמי | I20: סטטוס | J20: הערות | K20: row_ref
A21: =IF($K21="","",INDEX(מלאי!$D$2:$500,$K21)) | B21: =IF($K21="","",INDEX(מלאי!$B$2:$500,$K21)) | C21: =IF($K21="","",INDEX(מלאי!$C$2:$500,$K21)) | D21: =IF($K21="","",INDEX(מלאי!$G$2:$500,$K21)) | E21: =IF($K21="","",INDEX(מלאי!$M$2:$500,$K21)) | F21: =IF($K21="","",INDEX(מלאי!$N$2:$500,$K21)) | G21: =IF($K21="","",INDEX(מלאי!$O$2:$500,$K21)) | H21: =IF($K21="","",INDEX(מלאי!$U$2:$500,$K21)) | I21: =IF($K21="","",INDEX(מלאי!$X$2:$500,$K21)) | J21: =IF($K21="","",INDEX(מלאי!$AC$2:$500,$K21)) | K21: =IFERROR(SMALL(IF((מלאי!$D$2:$500<>"")*(--מלאי!$AE$2:$500)*(IF($B$2="הכל",1,מלאי!$A$2:$500=$B$2))*(IF($C$2="הכל",1,מלאי!$B$2:$500=$C$2))*(IF($D$2="הכל",1,מלאי!$C$2:$500=$D$2))*(IF($E$2="הכל",1,מלאי!$G$2:$500=$E$2))*(IF($F$2="הכל",1,מלאי!$I$2:$500=$F$2))*(IF($A$4="הכל",1,מלאי!$X$2:$500=$A$4))*(IF($B$4="הכל",1,מלאי!$Z$2:$500=$B$4))*(IF($C$4="הכל",1,מלאי!$O$2:$500=$C$4))*(IF($D$4="הכל",1,מלאי!$U$2:$500=$D$4))*(IF($E$4="הכל",1,מלאי!$K$2:$500=$E$4)),ROW(מלאי!$A$2:$A$500)-ROW(מלאי!$A$2)+1,""),1),"")
A22: =IF($K22="","",INDEX(מלאי!$D$2:$500,$K22)) | B22: =IF($K22="","",INDEX(מלאי!$B$2:$500,$K22)) | C22: =IF($K22="","",INDEX(מלאי!$C$2:$500,$K22)) | D22: =IF($K22="","",INDEX(מלאי!$G$2:$500,$K22)) | E22: =IF($K22="","",INDEX(מלאי!$M$2:$500,$K22)) | F22: =IF($K22="","",INDEX(מלאי!$N$2:$500,$K22)) | G22: =IF($K22="","",INDEX(מלאי!$O$2:$500,$K22)) | H22: =IF($K22="","",INDEX(מלאי!$U$2:$500,$K22)) | I22: =IF($K22="","",INDEX(מלאי!$X$2:$500,$K22)) | J22: =IF($K22="","",INDEX(מלאי!$AC$2:$500,$K22)) | K22: =IFERROR(SMALL(IF((מלאי!$D$2:$500<>"")*(--מלאי!$AE$2:$500)*(IF($B$2="הכל",1,מלאי!$A$2:$500=$B$2))*(IF($C$2="הכל",1,מלאי!$B$2:$500=$C$2))*(IF($D$2="הכל",1,מלאי!$C$2:$500=$D$2))*(IF($E$2="הכל",1,מלאי!$G$2:$500=$E$2))*(IF($F$2="הכל",1,מלאי!$I$2:$500=$F$2))*(IF($A$4="הכל",1,מלאי!$X$2:$500=$A$4))*(IF($B$4="הכל",1,מלאי!$Z$2:$500=$B$4))*(IF($C$4="הכל",1,מלאי!$O$2:$500=$C$4))*(IF($D$4="הכל",1,מלאי!$U$2:$500=$D$4))*(IF($E$4="הכל",1,מלאי!$K$2:$500=$E$4)),ROW(מלאי!$A$2:$A$500)-ROW(מלאי!$A$2)+1,""),2),"")
A23: =IF($K23="","",INDEX(מלאי!$D$2:$500,$K23)) | B23: =IF($K23="","",INDEX(מלאי!$B$2:$500,$K23)) | C23: =IF($K23="","",INDEX(מלאי!$C$2:$500,$K23)) | D23: =IF($K23="","",INDEX(מלאי!$G$2:$500,$K23)) | E23: =IF($K23="","",INDEX(מלאי!$M$2:$500,$K23)) | F23: =IF($K23="","",INDEX(מלאי!$N$2:$500,$K23)) | G23: =IF($K23="","",INDEX(מלאי!$O$2:$500,$K23)) | H23: =IF($K23="","",INDEX(מלאי!$U$2:$500,$K23)) | I23: =IF($K23="","",INDEX(מלאי!$X$2:$500,$K23)) | J23: =IF($K23="","",INDEX(מלאי!$AC$2:$500,$K23)) | K23: =IFERROR(SMALL(IF((מלאי!$D$2:$500<>"")*(--מלאי!$AE$2:$500)*(IF($B$2="הכל",1,מלאי!$A$2:$500=$B$2))*(IF($C$2="הכל",1,מלאי!$B$2:$500=$C$2))*(IF($D$2="הכל",1,מלאי!$C$2:$500=$D$2))*(IF($E$2="הכל",1,מלאי!$G$2:$500=$E$2))*(IF($F$2="הכל",1,מלאי!$I$2:$500=$F$2))*(IF($A$4="הכל",1,מלאי!$X$2:$500=$A$4))*(IF($B$4="הכל",1,מלאי!$Z$2:$500=$B$4))*(IF($C$4="הכל",1,מלאי!$O$2:$500=$C$4))*(IF($D$4="הכל",1,מלאי!$U$2:$500=$D$4))*(IF($E$4="הכל",1,מלאי!$K$2:$500=$E$4)),ROW(מלאי!$A$2:$A$500)-ROW(מלאי!$A$2)+1,""),3),"")
A24: =IF($K24="","",INDEX(מלאי!$D$2:$500,$K24)) | B24: =IF($K24="","",INDEX(מלאי!$B$2:$500,$K24)) | C24: =IF($K24="","",INDEX(מלאי!$C$2:$500,$K24)) | D24: =IF($K24="","",INDEX(מלאי!$G$2:$500,$K24)) | E24: =IF($K24="","",INDEX(מלאי!$M$2:$500,$K24)) | F24: =IF($K24="","",INDEX(מלאי!$N$2:$500,$K24)) | G24: =IF($K24="","",INDEX(מלאי!$O$2:$500,$K24)) | H24: =IF($K24="","",INDEX(מלאי!$U$2:$500,$K24)) | I24: =IF($K24="","",INDEX(מלאי!$X$2:$500,$K24)) | J24: =IF($K24="","",INDEX(מלאי!$AC$2:$500,$K24)) | K24: =IFERROR(SMALL(IF((מלאי!$D$2:$500<>"")*(--מלאי!$AE$2:$500)*(IF($B$2="הכל",1,מלאי!$A$2:$500=$B$2))*(IF($C$2="הכל",1,מלאי!$B$2:$500=$C$2))*(IF($D$2="הכל",1,מלאי!$C$2:$500=$D$2))*(IF($E$2="הכל",1,מלאי!$G$2:$500=$E$2))*(IF($F$2="הכל",1,מלאי!$I$2:$500=$F$2))*(IF($A$4="הכל",1,מלאי!$X$2:$500=$A$4))*(IF($B$4="הכל",1,מלאי!$Z$2:$500=$B$4))*(IF($C$4="הכל",1,מלאי!$O$2:$500=$C$4))*(IF($D$4="הכל",1,מלאי!$U$2:$500=$D$4))*(IF($E$4="הכל",1,מלאי!$K$2:$500=$E$4)),ROW(מלאי!$A$2:$A$500)-ROW(מלאי!$A$2)+1,""),4),"")
A25: =IF($K25="","",INDEX(מלאי!$D$2:$500,$K25)) | B25: =IF($K25="","",INDEX(מלאי!$B$2:$500,$K25)) | C25: =IF($K25="","",INDEX(מלאי!$C$2:$500,$K25)) | D25: =IF($K25="","",INDEX(מלאי!$G$2:$500,$K25)) | E25: =IF($K25="","",INDEX(מלאי!$M$2:$500,$K25)) | F25: =IF($K25="","",INDEX(מלאי!$N$2:$500,$K25)) | G25: =IF($K25="","",INDEX(מלאי!$O$2:$500,$K25)) | H25: =IF($K25="","",INDEX(מלאי!$U$2:$500,$K25)) | I25: =IF($K25="","",INDEX(מלאי!$X$2:$500,$K25)) | J25: =IF($K25="","",INDEX(מלאי!$AC$2:$500,$K25)) | K25: =IFERROR(SMALL(IF((מלאי!$D$2:$500<>"")*(--מלאי!$AE$2:$500)*(IF($B$2="הכל",1,מלאי!$A$2:$500=$B$2))*(IF($C$2="הכל",1,מלאי!$B$2:$500=$C$2))*(IF($D$2="הכל",1,מלאי!$C$2:$500=$D$2))*(IF($E$2="הכל",1,מלאי!$G$2:$500=$E$2))*(IF($F$2="הכל",1,מלאי!$I$2:$500=$F$2))*(IF($A$4="הכל",1,מלאי!$X$2:$500=$A$4))*(IF($B$4="הכל",1,מלאי!$Z$2:$500=$B$4))*(IF($C$4="הכל",1,מלאי!$O$2:$500=$C$4))*(IF($D$4="הכל",1,מלאי!$U$2:$500=$D$4))*(IF($E$4="הכל",1,מלאי!$K$2:$500=$E$4)),ROW(מלאי!$A$2:$A$500)-ROW(מלאי!$A$2)+1,""),5),"")
A26: =IF($K26="","",INDEX(מלאי!$D$2:$500,$K26)) | B26: =IF($K26="","",INDEX(מלאי!$B$2:$500,$K26)) | C26: =IF($K26="","",INDEX(מלאי!$C$2:$500,$K26)) | D26: =IF($K26="","",INDEX(מלאי!$G$2:$500,$K26)) | E26: =IF($K26="","",INDEX(מלאי!$M$2:$500,$K26)) | F26: =IF($K26="","",INDEX(מלאי!$N$2:$500,$K26)) | G26: =IF($K26="","",INDEX(מלאי!$O$2:$500,$K26)) | H26: =IF($K26="","",INDEX(מלאי!$U$2:$500,$K26)) | I26: =IF($K26="","",INDEX(מלאי!$X$2:$500,$K26)) | J26: =IF($K26="","",INDEX(מלאי!$AC$2:$500,$K26)) | K26: =IFERROR(SMALL(IF((מלאי!$D$2:$500<>"")*(--מלאי!$AE$2:$500)*(IF($B$2="הכל",1,מלאי!$A$2:$500=$B$2))*(IF($C$2="הכל",1,מלאי!$B$2:$500=$C$2))*(IF($D$2="הכל",1,מלאי!$C$2:$500=$D$2))*(IF($E$2="הכל",1,מלאי!$G$2:$500=$E$2))*(IF($F$2="הכל",1,מלאי!$I$2:$500=$F$2))*(IF($A$4="הכל",1,מלאי!$X$2:$500=$A$4))*(IF($B$4="הכל",1,מלאי!$Z$2:$500=$B$4))*(IF($C$4="הכל",1,מלאי!$O$2:$500=$C$4))*(IF($D$4="הכל",1,מלאי!$U$2:$500=$D$4))*(IF($E$4="הכל",1,מלאי!$K$2:$500=$E$4)),ROW(מלאי!$A$2:$A$500)-ROW(מלאי!$A$2)+1,""),6),"")
A27: =IF($K27="","",INDEX(מלאי!$D$2:$500,$K27)) | B27: =IF($K27="","",INDEX(מלאי!$B$2:$500,$K27)) | C27: =IF($K27="","",INDEX(מלאי!$C$2:$500,$K27)) | D27: =IF($K27="","",INDEX(מלאי!$G$2:$500,$K27)) | E27: =IF($K27="","",INDEX(מלאי!$M$2:$500,$K27)) | F27: =IF($K27="","",INDEX(מלאי!$N$2:$500,$K27)) | G27: =IF($K27="","",INDEX(מלאי!$O$2:$500,$K27)) | H27: =IF($K27="","",INDEX(מלאי!$U$2:$500,$K27)) | I27: =IF($K27="","",INDEX(מלאי!$X$2:$500,$K27)) | J27: =IF($K27="","",INDEX(מלאי!$AC$2:$500,$K27)) | K27: =IFERROR(SMALL(IF((מלאי!$D$2:$500<>"")*(--מלאי!$AE$2:$500)*(IF($B$2="הכל",1,מלאי!$A$2:$500=$B$2))*(IF($C$2="הכל",1,מלאי!$B$2:$500=$C$2))*(IF($D$2="הכל",1,מלאי!$C$2:$500=$D$2))*(IF($E$2="הכל",1,מלאי!$G$2:$500=$E$2))*(IF($F$2="הכל",1,מלאי!$I$2:$500=$F$2))*(IF($A$4="הכל",1,מלאי!$X$2:$500=$A$4))*(IF($B$4="הכל",1,מלאי!$Z$2:$500=$B$4))*(IF($C$4="הכל",1,מלאי!$O$2:$500=$C$4))*(IF($D$4="הכל",1,מלאי!$U$2:$500=$D$4))*(IF($E$4="הכל",1,מלאי!$K$2:$500=$E$4)),ROW(מלאי!$A$2:$A$500)-ROW(מלאי!$A$2)+1,""),7),"")
A28: =IF($K28="","",INDEX(מלאי!$D$2:$500,$K28)) | B28: =IF($K28="","",INDEX(מלאי!$B$2:$500,$K28)) | C28: =IF($K28="","",INDEX(מלאי!$C$2:$500,$K28)) | D28: =IF($K28="","",INDEX(מלאי!$G$2:$500,$K28)) | E28: =IF($K28="","",INDEX(מלאי!$M$2:$500,$K28)) | F28: =IF($K28="","",INDEX(מלאי!$N$2:$500,$K28)) | G28: =IF($K28="","",INDEX(מלאי!$O$2:$500,$K28)) | H28: =IF($K28="","",INDEX(מלאי!$U$2:$500,$K28)) | I28: =IF($K28="","",INDEX(מלאי!$X$2:$500,$K28)) | J28: =IF($K28="","",INDEX(מלאי!$AC$2:$500,$K28)) | K28: =IFERROR(SMALL(IF((מלאי!$D$2:$500<>"")*(--מלאי!$AE$2:$500)*(IF($B$2="הכל",1,מלאי!$A$2:$500=$B$2))*(IF($C$2="הכל",1,מלאי!$B$2:$500=$C$2))*(IF($D$2="הכל",1,מלאי!$C$2:$500=$D$2))*(IF($E$2="הכל",1,מלאי!$G$2:$500=$E$2))*(IF($F$2="הכל",1,מלאי!$I$2:$500=$F$2))*(IF($A$4="הכל",1,מלאי!$X$2:$500=$A$4))*(IF($B$4="הכל",1,מלאי!$Z$2:$500=$B$4))*(IF($C$4="הכל",1,מלאי!$O$2:$500=$C$4))*(IF($D$4="הכל",1,מלאי!$U$2:$500=$D$4))*(IF($E$4="הכל",1,מלאי!$K$2:$500=$E$4)),ROW(מלאי!$A$2:$A$500)-ROW(מלאי!$A$2)+1,""),8),"")
A29: =IF($K29="","",INDEX(מלאי!$D$2:$500,$K29)) | B29: =IF($K29="","",INDEX(מלאי!$B$2:$500,$K29)) | C29: =IF($K29="","",INDEX(מלאי!$C$2:$500,$K29)) | D29: =IF($K29="","",INDEX(מלאי!$G$2:$500,$K29)) | E29: =IF($K29="","",INDEX(מלאי!$M$2:$500,$K29)) | F29: =IF($K29="","",INDEX(מלאי!$N$2:$500,$K29)) | G29: =IF($K29="","",INDEX(מלאי!$O$2:$500,$K29)) | H29: =IF($K29="","",INDEX(מלאי!$U$2:$500,$K29)) | I29: =IF($K29="","",INDEX(מלאי!$X$2:$500,$K29)) | J29: =IF($K29="","",INDEX(מלאי!$AC$2:$500,$K29)) | K29: =IFERROR(SMALL(IF((מלאי!$D$2:$500<>"")*(--מלאי!$AE$2:$500)*(IF($B$2="הכל",1,מלאי!$A$2:$500=$B$2))*(IF($C$2="הכל",1,מלאי!$B$2:$500=$C$2))*(IF($D$2="הכל",1,מלאי!$C$2:$500=$D$2))*(IF($E$2="הכל",1,מלאי!$G$2:$500=$E$2))*(IF($F$2="הכל",1,מלאי!$I$2:$500=$F$2))*(IF($A$4="הכל",1,מלאי!$X$2:$500=$A$4))*(IF($B$4="הכל",1,מלאי!$Z$2:$500=$B$4))*(IF($C$4="הכל",1,מלאי!$O$2:$500=$C$4))*(IF($D$4="הכל",1,מלאי!$U$2:$500=$D$4))*(IF($E$4="הכל",1,מלאי!$K$2:$500=$E$4)),ROW(מלאי!$A$2:$A$500)-ROW(מלאי!$A$2)+1,""),9),"")
A30: =IF($K30="","",INDEX(מלאי!$D$2:$500,$K30)) | B30: =IF($K30="","",INDEX(מלאי!$B$2:$500,$K30)) | C30: =IF($K30="","",INDEX(מלאי!$C$2:$500,$K30)) | D30: =IF($K30="","",INDEX(מלאי!$G$2:$500,$K30)) | E30: =IF($K30="","",INDEX(מלאי!$M$2:$500,$K30)) | F30: =IF($K30="","",INDEX(מלאי!$N$2:$500,$K30)) | G30: =IF($K30="","",INDEX(מלאי!$O$2:$500,$K30)) | H30: =IF($K30="","",INDEX(מלאי!$U$2:$500,$K30)) | I30: =IF($K30="","",INDEX(מלאי!$X$2:$500,$K30)) | J30: =IF($K30="","",INDEX(מלאי!$AC$2:$500,$K30)) | K30: =IFERROR(SMALL(IF((מלאי!$D$2:$500<>"")*(--מלאי!$AE$2:$500)*(IF($B$2="הכל",1,מלאי!$A$2:$500=$B$2))*(IF($C$2="הכל",1,מלאי!$B$2:$500=$C$2))*(IF($D$2="הכל",1,מלאי!$C$2:$500=$D$2))*(IF($E$2="הכל",1,מלאי!$G$2:$500=$E$2))*(IF($F$2="הכל",1,מלאי!$I$2:$500=$F$2))*(IF($A$4="הכל",1,מלאי!$X$2:$500=$A$4))*(IF($B$4="הכל",1,מלאי!$Z$2:$500=$B$4))*(IF($C$4="הכל",1,מלאי!$O$2:$500=$C$4))*(IF($D$4="הכל",1,מלאי!$U$2:$500=$D$4))*(IF($E$4="הכל",1,מלאי!$K$2:$500=$E$4)),ROW(מלאי!$A$2:$A$500)-ROW(מלאי!$A$2)+1,""),10),"")
A31: =IF($K31="","",INDEX(מלאי!$D$2:$500,$K31)) | B31: =IF($K31="","",INDEX(מלאי!$B$2:$500,$K31)) | C31: =IF($K31="","",INDEX(מלאי!$C$2:$500,$K31)) | D31: =IF($K31="","",INDEX(מלאי!$G$2:$500,$K31)) | E31: =IF($K31="","",INDEX(מלאי!$M$2:$500,$K31)) | F31: =IF($K31="","",INDEX(מלאי!$N$2:$500,$K31)) | G31: =IF($K31="","",INDEX(מלאי!$O$2:$500,$K31)) | H31: =IF($K31="","",INDEX(מלאי!$U$2:$500,$K31)) | I31: =IF($K31="","",INDEX(מלאי!$X$2:$500,$K31)) | J31: =IF($K31="","",INDEX(מלאי!$AC$2:$500,$K31)) | K31: =IFERROR(SMALL(IF((מלאי!$D$2:$500<>"")*(--מלאי!$AE$2:$500)*(IF($B$2="הכל",1,מלאי!$A$2:$500=$B$2))*(IF($C$2="הכל",1,מלאי!$B$2:$500=$C$2))*(IF($D$2="הכל",1,מלאי!$C$2:$500=$D$2))*(IF($E$2="הכל",1,מלאי!$G$2:$500=$E$2))*(IF($F$2="הכל",1,מלאי!$I$2:$500=$F$2))*(IF($A$4="הכל",1,מלאי!$X$2:$500=$A$4))*(IF($B$4="הכל",1,מלאי!$Z$2:$500=$B$4))*(IF($C$4="הכל",1,מלאי!$O$2:$500=$C$4))*(IF($D$4="הכל",1,מלאי!$U$2:$500=$D$4))*(IF($E$4="הכל",1,מלאי!$K$2:$500=$E$4)),ROW(מלאי!$A$2:$A$500)-ROW(מלאי!$A$2)+1,""),11),"")
A32: =IF($K32="","",INDEX(מלאי!$D$2:$500,$K32)) | B32: =IF($K32="","",INDEX(מלאי!$B$2:$500,$K32)) | C32: =IF($K32="","",INDEX(מלאי!$C$2:$500,$K32)) | D32: =IF($K32="","",INDEX(מלאי!$G$2:$500,$K32)) | E32: =IF($K32="","",INDEX(מלאי!$M$2:$500,$K32)) | F32: =IF($K32="","",INDEX(מלאי!$N$2:$500,$K32)) | G32: =IF($K32="","",INDEX(מלאי!$O$2:$500,$K32)) | H32: =IF($K32="","",INDEX(מלאי!$U$2:$500,$K32)) | I32: =IF($K32="","",INDEX(מלאי!$X$2:$500,$K32)) | J32: =IF($K32="","",INDEX(מלאי!$AC$2:$500,$K32)) | K32: =IFERROR(SMALL(IF((מלאי!$D$2:$500<>"")*(--מלאי!$AE$2:$500)*(IF($B$2="הכל",1,מלאי!$A$2:$500=$B$2))*(IF($C$2="הכל",1,מלאי!$B$2:$500=$C$2))*(IF($D$2="הכל",1,מלאי!$C$2:$500=$D$2))*(IF($E$2="הכל",1,מלאי!$G$2:$500=$E$2))*(IF($F$2="הכל",1,מלאי!$I$2:$500=$F$2))*(IF($A$4="הכל",1,מלאי!$X$2:$500=$A$4))*(IF($B$4="הכל",1,מלאי!$Z$2:$500=$B$4))*(IF($C$4="הכל",1,מלאי!$O$2:$500=$C$4))*(IF($D$4="הכל",1,מלאי!$U$2:$500=$D$4))*(IF($E$4="הכל",1,מלאי!$K$2:$500=$E$4)),ROW(מלאי!$A$2:$A$500)-ROW(מלאי!$A$2)+1,""),12),"")
A33: =IF($K33="","",INDEX(מלאי!$D$2:$500,$K33)) | B33: =IF($K33="","",INDEX(מלאי!$B$2:$500,$K33)) | C33: =IF($K33="","",INDEX(מלאי!$C$2:$500,$K33)) | D33: =IF($K33="","",INDEX(מלאי!$G$2:$500,$K33)) | E33: =IF($K33="","",INDEX(מלאי!$M$2:$500,$K33)) | F33: =IF($K33="","",INDEX(מלאי!$N$2:$500,$K33)) | G33: =IF($K33="","",INDEX(מלאי!$O$2:$500,$K33)) | H33: =IF($K33="","",INDEX(מלאי!$U$2:$500,$K33)) | I33: =IF($K33="","",INDEX(מלאי!$X$2:$500,$K33)) | J33: =IF($K33="","",INDEX(מלאי!$AC$2:$500,$K33)) | K33: =IFERROR(SMALL(IF((מלאי!$D$2:$500<>"")*(--מלאי!$AE$2:$500)*(IF($B$2="הכל",1,מלאי!$A$2:$500=$B$2))*(IF($C$2="הכל",1,מלאי!$B$2:$500=$C$2))*(IF($D$2="הכל",1,מלאי!$C$2:$500=$D$2))*(IF($E$2="הכל",1,מלאי!$G$2:$500=$E$2))*(IF($F$2="הכל",1,מלאי!$I$2:$500=$F$2))*(IF($A$4="הכל",1,מלאי!$X$2:$500=$A$4))*(IF($B$4="הכל",1,מלאי!$Z$2:$500=$B$4))*(IF($C$4="הכל",1,מלאי!$O$2:$500=$C$4))*(IF($D$4="הכל",1,מלאי!$U$2:$500=$D$4))*(IF($E$4="הכל",1,מלאי!$K$2:$500=$E$4)),ROW(מלאי!$A$2:$A$500)-ROW(מלאי!$A$2)+1,""),13),"")
A34: =IF($K34="","",INDEX(מלאי!$D$2:$500,$K34)) | B34: =IF($K34="","",INDEX(מלאי!$B$2:$500,$K34)) | C34: =IF($K34="","",INDEX(מלאי!$C$2:$500,$K34)) | D34: =IF($K34="","",INDEX(מלאי!$G$2:$500,$K34)) | E34: =IF($K34="","",INDEX(מלאי!$M$2:$500,$K34)) | F34: =IF($K34="","",INDEX(מלאי!$N$2:$500,$K34)) | G34: =IF($K34="","",INDEX(מלאי!$O$2:$500,$K34)) | H34: =IF($K34="","",INDEX(מלאי!$U$2:$500,$K34)) | I34: =IF($K34="","",INDEX(מלאי!$X$2:$500,$K34)) | J34: =IF($K34="","",INDEX(מלאי!$AC$2:$500,$K34)) | K34: =IFERROR(SMALL(IF((מלאי!$D$2:$500<>"")*(--מלאי!$AE$2:$500)*(IF($B$2="הכל",1,מלאי!$A$2:$500=$B$2))*(IF($C$2="הכל",1,מלאי!$B$2:$500=$C$2))*(IF($D$2="הכל",1,מלאי!$C$2:$500=$D$2))*(IF($E$2="הכל",1,מלאי!$G$2:$500=$E$2))*(IF($F$2="הכל",1,מלאי!$I$2:$500=$F$2))*(IF($A$4="הכל",1,מלאי!$X$2:$500=$A$4))*(IF($B$4="הכל",1,מלאי!$Z$2:$500=$B$4))*(IF($C$4="הכל",1,מלאי!$O$2:$500=$C$4))*(IF($D$4="הכל",1,מלאי!$U$2:$500=$D$4))*(IF($E$4="הכל",1,מלאי!$K$2:$500=$E$4)),ROW(מלאי!$A$2:$A$500)-ROW(מלאי!$A$2)+1,""),14),"")
A35: =IF($K35="","",INDEX(מלאי!$D$2:$500,$K35)) | B35: =IF($K35="","",INDEX(מלאי!$B$2:$500,$K35)) | C35: =IF($K35="","",INDEX(מלאי!$C$2:$500,$K35)) | D35: =IF($K35="","",INDEX(מלאי!$G$2:$500,$K35)) | E35: =IF($K35="","",INDEX(מלאי!$M$2:$500,$K35)) | F35: =IF($K35="","",INDEX(מלאי!$N$2:$500,$K35)) | G35: =IF($K35="","",INDEX(מלאי!$O$2:$500,$K35)) | H35: =IF($K35="","",INDEX(מלאי!$U$2:$500,$K35)) | I35: =IF($K35="","",INDEX(מלאי!$X$2:$500,$K35)) | J35: =IF($K35="","",INDEX(מלאי!$AC$2:$500,$K35)) | K35: =IFERROR(SMALL(IF((מלאי!$D$2:$500<>"")*(--מלאי!$AE$2:$500)*(IF($B$2="הכל",1,מלאי!$A$2:$500=$B$2))*(IF($C$2="הכל",1,מלאי!$B$2:$500=$C$2))*(IF($D$2="הכל",1,מלאי!$C$2:$500=$D$2))*(IF($E$2="הכל",1,מלאי!$G$2:$500=$E$2))*(IF($F$2="הכל",1,מלאי!$I$2:$500=$F$2))*(IF($A$4="הכל",1,מלאי!$X$2:$500=$A$4))*(IF($B$4="הכל",1,מלאי!$Z$2:$500=$B$4))*(IF($C$4="הכל",1,מלאי!$O$2:$500=$C$4))*(IF($D$4="הכל",1,מלאי!$U$2:$500=$D$4))*(IF($E$4="הכל",1,מלאי!$K$2:$500=$E$4)),ROW(מלאי!$A$2:$A$500)-ROW(מלאי!$A$2)+1,""),15),"")
A36: =IF($K36="","",INDEX(מלאי!$D$2:$500,$K36)) | B36: =IF($K36="","",INDEX(מלאי!$B$2:$500,$K36)) | C36: =IF($K36="","",INDEX(מלאי!$C$2:$500,$K36)) | D36: =IF($K36="","",INDEX(מלאי!$G$2:$500,$K36)) | E36: =IF($K36="","",INDEX(מלאי!$M$2:$500,$K36)) | F36: =IF($K36="","",INDEX(מלאי!$N$2:$500,$K36)) | G36: =IF($K36="","",INDEX(מלאי!$O$2:$500,$K36)) | H36: =IF($K36="","",INDEX(מלאי!$U$2:$500,$K36)) | I36: =IF($K36="","",INDEX(מלאי!$X$2:$500,$K36)) | J36: =IF($K36="","",INDEX(מלאי!$AC$2:$500,$K36)) | K36: =IFERROR(SMALL(IF((מלאי!$D$2:$500<>"")*(--מלאי!$AE$2:$500)*(IF($B$2="הכל",1,מלאי!$A$2:$500=$B$2))*(IF($C$2="הכל",1,מלאי!$B$2:$500=$C$2))*(IF($D$2="הכל",1,מלאי!$C$2:$500=$D$2))*(IF($E$2="הכל",1,מלאי!$G$2:$500=$E$2))*(IF($F$2="הכל",1,מלאי!$I$2:$500=$F$2))*(IF($A$4="הכל",1,מלאי!$X$2:$500=$A$4))*(IF($B$4="הכל",1,מלאי!$Z$2:$500=$B$4))*(IF($C$4="הכל",1,מלאי!$O$2:$500=$C$4))*(IF($D$4="הכל",1,מלאי!$U$2:$500=$D$4))*(IF($E$4="הכל",1,מלאי!$K$2:$500=$E$4)),ROW(מלאי!$A$2:$A$500)-ROW(מלאי!$A$2)+1,""),16),"")
A37: =IF($K37="","",INDEX(מלאי!$D$2:$500,$K37)) | B37: =IF($K37="","",INDEX(מלאי!$B$2:$500,$K37)) | C37: =IF($K37="","",INDEX(מלאי!$C$2:$500,$K37)) | D37: =IF($K37="","",INDEX(מלאי!$G$2:$500,$K37)) | E37: =IF($K37="","",INDEX(מלאי!$M$2:$500,$K37)) | F37: =IF($K37="","",INDEX(מלאי!$N$2:$500,$K37)) | G37: =IF($K37="","",INDEX(מלאי!$O$2:$500,$K37)) | H37: =IF($K37="","",INDEX(מלאי!$U$2:$500,$K37)) | I37: =IF($K37="","",INDEX(מלאי!$X$2:$500,$K37)) | J37: =IF($K37="","",INDEX(מלאי!$AC$2:$500,$K37)) | K37: =IFERROR(SMALL(IF((מלאי!$D$2:$500<>"")*(--מלאי!$AE$2:$500)*(IF($B$2="הכל",1,מלאי!$A$2:$500=$B$2))*(IF($C$2="הכל",1,מלאי!$B$2:$500=$C$2))*(IF($D$2="הכל",1,מלאי!$C$2:$500=$D$2))*(IF($E$2="הכל",1,מלאי!$G$2:$500=$E$2))*(IF($F$2="הכל",1,מלאי!$I$2:$500=$F$2))*(IF($A$4="הכל",1,מלאי!$X$2:$500=$A$4))*(IF($B$4="הכל",1,מלאי!$Z$2:$500=$B$4))*(IF($C$4="הכל",1,מלאי!$O$2:$500=$C$4))*(IF($D$4="הכל",1,מלאי!$U$2:$500=$D$4))*(IF($E$4="הכל",1,מלאי!$K$2:$500=$E$4)),ROW(מלאי!$A$2:$A$500)-ROW(מלאי!$A$2)+1,""),17),"")
A38: =IF($K38="","",INDEX(מלאי!$D$2:$500,$K38)) | B38: =IF($K38="","",INDEX(מלאי!$B$2:$500,$K38)) | C38: =IF($K38="","",INDEX(מלאי!$C$2:$500,$K38)) | D38: =IF($K38="","",INDEX(מלאי!$G$2:$500,$K38)) | E38: =IF($K38="","",INDEX(מלאי!$M$2:$500,$K38)) | F38: =IF($K38="","",INDEX(מלאי!$N$2:$500,$K38)) | G38: =IF($K38="","",INDEX(מלאי!$O$2:$500,$K38)) | H38: =IF($K38="","",INDEX(מלאי!$U$2:$500,$K38)) | I38: =IF($K38="","",INDEX(מלאי!$X$2:$500,$K38)) | J38: =IF($K38="","",INDEX(מלאי!$AC$2:$500,$K38)) | K38: =IFERROR(SMALL(IF((מלאי!$D$2:$500<>"")*(--מלאי!$AE$2:$500)*(IF($B$2="הכל",1,מלאי!$A$2:$500=$B$2))*(IF($C$2="הכל",1,מלאי!$B$2:$500=$C$2))*(IF($D$2="הכל",1,מלאי!$C$2:$500=$D$2))*(IF($E$2="הכל",1,מלאי!$G$2:$500=$E$2))*(IF($F$2="הכל",1,מלאי!$I$2:$500=$F$2))*(IF($A$4="הכל",1,מלאי!$X$2:$500=$A$4))*(IF($B$4="הכל",1,מלאי!$Z$2:$500=$B$4))*(IF($C$4="הכל",1,מלאי!$O$2:$500=$C$4))*(IF($D$4="הכל",1,מלאי!$U$2:$500=$D$4))*(IF($E$4="הכל",1,מלאי!$K$2:$500=$E$4)),ROW(מלאי!$A$2:$A$500)-ROW(מלאי!$A$2)+1,""),18),"")
A39: =IF($K39="","",INDEX(מלאי!$D$2:$500,$K39)) | B39: =IF($K39="","",INDEX(מלאי!$B$2:$500,$K39)) | C39: =IF($K39="","",INDEX(מלאי!$C$2:$500,$K39)) | D39: =IF($K39="","",INDEX(מלאי!$G$2:$500,$K39)) | E39: =IF($K39="","",INDEX(מלאי!$M$2:$500,$K39)) | F39: =IF($K39="","",INDEX(מלאי!$N$2:$500,$K39)) | G39: =IF($K39="","",INDEX(מלאי!$O$2:$500,$K39)) | H39: =IF($K39="","",INDEX(מלאי!$U$2:$500,$K39)) | I39: =IF($K39="","",INDEX(מלאי!$X$2:$500,$K39)) | J39: =IF($K39="","",INDEX(מלאי!$AC$2:$500,$K39)) | K39: =IFERROR(SMALL(IF((מלאי!$D$2:$500<>"")*(--מלאי!$AE$2:$500)*(IF($B$2="הכל",1,מלאי!$A$2:$500=$B$2))*(IF($C$2="הכל",1,מלאי!$B$2:$500=$C$2))*(IF($D$2="הכל",1,מלאי!$C$2:$500=$D$2))*(IF($E$2="הכל",1,מלאי!$G$2:$500=$E$2))*(IF($F$2="הכל",1,מלאי!$I$2:$500=$F$2))*(IF($A$4="הכל",1,מלאי!$X$2:$500=$A$4))*(IF($B$4="הכל",1,מלאי!$Z$2:$500=$B$4))*(IF($C$4="הכל",1,מלאי!$O$2:$500=$C$4))*(IF($D$4="הכל",1,מלאי!$U$2:$500=$D$4))*(IF($E$4="הכל",1,מלאי!$K$2:$500=$E$4)),ROW(מלאי!$A$2:$A$500)-ROW(מלאי!$A$2)+1,""),19),"")
A40: =IF($K40="","",INDEX(מלאי!$D$2:$500,$K40)) | B40: =IF($K40="","",INDEX(מלאי!$B$2:$500,$K40)) | C40: =IF($K40="","",INDEX(מלאי!$C$2:$500,$K40)) | D40: =IF($K40="","",INDEX(מלאי!$G$2:$500,$K40)) | E40: =IF($K40="","",INDEX(מלאי!$M$2:$500,$K40)) | F40: =IF($K40="","",INDEX(מלאי!$N$2:$500,$K40)) | G40: =IF($K40="","",INDEX(מלאי!$O$2:$500,$K40)) | H40: =IF($K40="","",INDEX(מלאי!$U$2:$500,$K40)) | I40: =IF($K40="","",INDEX(מלאי!$X$2:$500,$K40)) | J40: =IF($K40="","",INDEX(מלאי!$AC$2:$500,$K40)) | K40: =IFERROR(SMALL(IF((מלאי!$D$2:$500<>"")*(--מלאי!$AE$2:$500)*(IF($B$2="הכל",1,מלאי!$A$2:$500=$B$2))*(IF($C$2="הכל",1,מלאי!$B$2:$500=$C$2))*(IF($D$2="הכל",1,מלאי!$C$2:$500=$D$2))*(IF($E$2="הכל",1,מלאי!$G$2:$500=$E$2))*(IF($F$2="הכל",1,מלאי!$I$2:$500=$F$2))*(IF($A$4="הכל",1,מלאי!$X$2:$500=$A$4))*(IF($B$4="הכל",1,מלאי!$Z$2:$500=$B$4))*(IF($C$4="הכל",1,מלאי!$O$2:$500=$C$4))*(IF($D$4="הכל",1,מלאי!$U$2:$500=$D$4))*(IF($E$4="הכל",1,מלאי!$K$2:$500=$E$4)),ROW(מלאי!$A$2:$A$500)-ROW(מלאי!$A$2)+1,""),20),"")
A41: =IF($K41="","",INDEX(מלאי!$D$2:$500,$K41)) | B41: =IF($K41="","",INDEX(מלאי!$B$2:$500,$K41)) | C41: =IF($K41="","",INDEX(מלאי!$C$2:$500,$K41)) | D41: =IF($K41="","",INDEX(מלאי!$G$2:$500,$K41)) | E41: =IF($K41="","",INDEX(מלאי!$M$2:$500,$K41)) | F41: =IF($K41="","",INDEX(מלאי!$N$2:$500,$K41)) | G41: =IF($K41="","",INDEX(מלאי!$O$2:$500,$K41)) | H41: =IF($K41="","",INDEX(מלאי!$U$2:$500,$K41)) | I41: =IF($K41="","",INDEX(מלאי!$X$2:$500,$K41)) | J41: =IF($K41="","",INDEX(מלאי!$AC$2:$500,$K41)) | K41: =IFERROR(SMALL(IF((מלאי!$D$2:$500<>"")*(--מלאי!$AE$2:$500)*(IF($B$2="הכל",1,מלאי!$A$2:$500=$B$2))*(IF($C$2="הכל",1,מלאי!$B$2:$500=$C$2))*(IF($D$2="הכל",1,מלאי!$C$2:$500=$D$2))*(IF($E$2="הכל",1,מלאי!$G$2:$500=$E$2))*(IF($F$2="הכל",1,מלאי!$I$2:$500=$F$2))*(IF($A$4="הכל",1,מלאי!$X$2:$500=$A$4))*(IF($B$4="הכל",1,מלאי!$Z$2:$500=$B$4))*(IF($C$4="הכל",1,מלאי!$O$2:$500=$C$4))*(IF($D$4="הכל",1,מלאי!$U$2:$500=$D$4))*(IF($E$4="הכל",1,מלאי!$K$2:$500=$E$4)),ROW(מלאי!$A$2:$A$500)-ROW(מלאי!$A$2)+1,""),21),"")
...

Sheet מלאי
A1: קו מוצר | B1: שם מוצר | C1: גרסה | D1: מזהה ייחודי | E1: מק"ט | F1: תאריך השאלה | G1: סוג בד 1 | H1: סוג בד 2 | I1: מידה | J1: גרסה מיוחדת - פיתוח | K1: גרסה סופית | L1: הערות גרסה/פיצ׳רים | M1: הדפס צד A | N1: הדפס צד B | O1: תקין ויזואלית צד A | P1: תקין ויזואלית צד B | Q1: סביבה A | R1: סביבה משנית A | S1: סביבה B | T1: סביבה משנית B | U1: תקין תרמית צד A | V1: תקין תרמית צד B | W1: פיצ׳רים תקינים | X1: סטטוס | Y1: מושאל ל | Z1: מדינה | AA1: אחראי מהחברה | AB1: החזרה משוערת | AC1: הערות | AD1: פער בתכולה | AE1: מתאים_סביבה | AF1: תקין_לגמרי | AG1: תקין_ויזואלי_בלבד | AH1: תקין_תרמי_בלבד | AI1: באיחור
A2: OverGarment | B2: Poncho Inbar | D2: INV-001 | E2: =IFERROR(INDEX('הגדרות'!$D$104:$D$123,MATCH(B2&G2&C2,'הגדרות'!$A$104:$A$123&'הגדרות'!$B$104:$B$123&'הגדרות'!$C$104:$C$123,0)),"") | F2: 45971 | G2: Inbar | I2: L | J2: לא | K2: כן | M2: Desert | N2: Forest Green | O2: לא | P2: כן | Q2: =IFERROR(VLOOKUP(M2,'הגדרות'!$A$11:$D$25,2,FALSE),"") | R2: =IFERROR(VLOOKUP(M2,'הגדרות'!$A$11:$D$25,3,FALSE),"") | S2: =IFERROR(VLOOKUP(N2,'הגדרות'!$A$11:$D$25,2,FALSE),"") | T2: =IFERROR(VLOOKUP(N2,'הגדרות'!$A$11:$D$25,3,FALSE),"") | U2: כן | V2: כן | W2: כן | X2: במלאי | Z2: ישראל | AC2: הדפס Desert ישן — אינו תקין ויזואלית | AD2: לא | AE2: =IF('לוח בקרה'!$A$2="הכל",TRUE,OR(Q2='לוח בקרה'!$A$2,R2='לוח בקרה'!$A$2,S2='לוח בקרה'!$A$2,T2='לוח בקרה'!$A$2)) | AF2: =AND(AE2,OR(AND(O2="כן",U2="כן"),AND(P2="כן",V2="כן"))) | AG2: =AND(AE2,OR(O2="כן",P2="כן"),NOT(OR(AND(O2="כן",U2="כן"),AND(P2="כן",V2="כן")))) | AH2: =AND(AE2,OR(U2="כן",V2="כן"),NOT(OR(O2="כן",P2="כן"))) | AI2: =AND(X2="מושאל",AB2<>"",AB2<TODAY())
A3: Hide Site | B3: Hide Site Standard | D3: INV-002 | E3: =IFERROR(INDEX('הגדרות'!$D$104:$D$123,MATCH(B3&G3&C3,'הגדרות'!$A$104:$A$123&'הגדרות'!$B$104:$B$123&'הגדרות'!$C$104:$C$123,0)),"") | F3: 45870 | G3: Sahar | H3: Gabardine | I3: One Size | J3: לא | K3: כן | M3: Woodland | O3: כן | Q3: =IFERROR(VLOOKUP(M3,'הגדרות'!$A$11:$D$25,2,FALSE),"") | R3: =IFERROR(VLOOKUP(M3,'הגדרות'!$A$11:$D$25,3,FALSE),"") | S3: =IFERROR(VLOOKUP(N3,'הגדרות'!$A$11:$D$25,2,FALSE),"") | T3: =IFERROR(VLOOKUP(N3,'הגדרות'!$A$11:$D$25,3,FALSE),"") | U3: כן | W3: כן | X3: מושאל | Y3: צה"ל | Z3: ישראל | AA3: יוסי כהן | AB3: 46068 | AD3: לא | AE3: =IF('לוח בקרה'!$A$2="הכל",TRUE,OR(Q3='לוח בקרה'!$A$2,R3='לוח בקרה'!$A$2,S3='לוח בקרה'!$A$2,T3='לוח בקרה'!$A$2)) | AF3: =AND(AE3,OR(AND(O3="כן",U3="כן"),AND(P3="כן",V3="כן"))) | AG3: =AND(AE3,OR(O3="כן",P3="כן"),NOT(OR(AND(O3="כן",U3="כן"),AND(P3="כן",V3="כן")))) | AH3: =AND(AE3,OR(U3="כן",V3="כן"),NOT(OR(O3="כן",P3="כן"))) | AI3: =AND(X3="מושאל",AB3<>"",AB3<TODAY())
A4: Uniform | B4: Shirt | D4: INV-003 | E4: =IFERROR(INDEX('הגדרות'!$D$104:$D$123,MATCH(B4&G4&C4,'הגדרות'!$A$104:$A$123&'הגדרות'!$B$104:$B$123&'הגדרות'!$C$104:$C$123,0)),"") | G4: Meron | I4: M | J4: לא | K4: לא | L4: דורש בדיקה נוספת | M4: Urban Green | N4: Urban | O4: כן | P4: כן | Q4: =IFERROR(VLOOKUP(M4,'הגדרות'!$A$11:$D$25,2,FALSE),"") | R4: =IFERROR(VLOOKUP(M4,'הגדרות'!$A$11:$D$25,3,FALSE),"") | S4: =IFERROR(VLOOKUP(N4,'הגדרות'!$A$11:$D$25,2,FALSE),"") | T4: =IFERROR(VLOOKUP(N4,'הגדרות'!$A$11:$D$25,3,FALSE),"") | U4: כן | V4: כן | W4: כן | X4: בחדר תצוגה | Z4: ישראל | AC4: גרסת ביניים — ממתין לאישור סופי | AD4: לא | AE4: =IF('לוח בקרה'!$A$2="הכל",TRUE,OR(Q4='לוח בקרה'!$A$2,R4='לוח בקרה'!$A$2,S4='לוח בקרה'!$A$2,T4='לוח בקרה'!$A$2)) | AF4: =AND(AE4,OR(AND(O4="כן",U4="כן"),AND(P4="כן",V4="כן"))) | AG4: =AND(AE4,OR(O4="כן",P4="כן"),NOT(OR(AND(O4="כן",U4="כן"),AND(P4="כן",V4="כן")))) | AH4: =AND(AE4,OR(U4="כן",V4="כן"),NOT(OR(O4="כן",P4="כן"))) | AI4: =AND(X4="מושאל",AB4<>"",AB4<TODAY())
A5: Blankets | B5: Survival Blanket | D5: INV-004 | E5: =IFERROR(INDEX('הגדרות'!$D$104:$D$123,MATCH(B5&G5&C5,'הגדרות'!$A$104:$A$123&'הגדרות'!$B$104:$B$123&'הגדרות'!$C$104:$C$123,0)),"") | G5: IRR | I5: One Size | J5: כן | K5: לא | L5: פרוטוטייפ | M5: Fresh Snow | O5: כן | Q5: =IFERROR(VLOOKUP(M5,'הגדרות'!$A$11:$D$25,2,FALSE),"") | R5: =IFERROR(VLOOKUP(M5,'הגדרות'!$A$11:$D$25,3,FALSE),"") | S5: =IFERROR(VLOOKUP(N5,'הגדרות'!$A$11:$D$25,2,FALSE),"") | T5: =IFERROR(VLOOKUP(N5,'הגדרות'!$A$11:$D$25,3,FALSE),"") | U5: לא | W5: כן | X5: במלאי | Z5: ישראל | AC5: דגם ניסיוני — לא לשלוח ללקוח | AD5: לא | AE5: =IF('לוח בקרה'!$A$2="הכל",TRUE,OR(Q5='לוח בקרה'!$A$2,R5='לוח בקרה'!$A$2,S5='לוח בקרה'!$A$2,T5='לוח בקרה'!$A$2)) | AF5: =AND(AE5,OR(AND(O5="כן",U5="כן"),AND(P5="כן",V5="כן"))) | AG5: =AND(AE5,OR(O5="כן",P5="כן"),NOT(OR(AND(O5="כן",U5="כן"),AND(P5="כן",V5="כן")))) | AH5: =AND(AE5,OR(U5="כן",V5="כן"),NOT(OR(O5="כן",P5="כן"))) | AI5: =AND(X5="מושאל",AB5<>"",AB5<TODAY())
A6: OverGarment | B6: Hobey Elite | D6: INV-005 | E6: =IFERROR(INDEX('הגדרות'!$D$104:$D$123,MATCH(B6&G6&C6,'הגדרות'!$A$104:$A$123&'הגדרות'!$B$104:$B$123&'הגדרות'!$C$104:$C$123,0)),"") | F6: 45992 | G6: SRV | H6: Arber | I6: XL | J6: לא | K6: כן | M6: Sand | N6: Ever-Green | O6: כן | P6: כן | Q6: =IFERROR(VLOOKUP(M6,'הגדרות'!$A$11:$D$25,2,FALSE),"") | R6: =IFERROR(VLOOKUP(M6,'הגדרות'!$A$11:$D$25,3,FALSE),"") | S6: =IFERROR(VLOOKUP(N6,'הגדרות'!$A$11:$D$25,2,FALSE),"") | T6: =IFERROR(VLOOKUP(N6,'הגדרות'!$A$11:$D$25,3,FALSE),"") | U6: כן | V6: כן | W6: כן | X6: מושאל | Y6: לוקהיד מרטין | Z6: ארה"ב | AA6: דני לוי | AB6: 46032 | AD6: לא | AE6: =IF('לוח בקרה'!$A$2="הכל",TRUE,OR(Q6='לוח בקרה'!$A$2,R6='לוח בקרה'!$A$2,S6='לוח בקרה'!$A$2,T6='לוח בקרה'!$A$2)) | AF6: =AND(AE6,OR(AND(O6="כן",U6="כן"),AND(P6="כן",V6="כן"))) | AG6: =AND(AE6,OR(O6="כן",P6="כן"),NOT(OR(AND(O6="כן",U6="כן"),AND(P6="כן",V6="כן")))) | AH6: =AND(AE6,OR(U6="כן",V6="כן"),NOT(OR(O6="כן",P6="כן"))) | AI6: =AND(X6="מושאל",AB6<>"",AB6<TODAY())
E7: =IFERROR(INDEX('הגדרות'!$D$104:$D$123,MATCH(B7&G7&C7,'הגדרות'!$A$104:$A$123&'הגדרות'!$B$104:$B$123&'הגדרות'!$C$104:$C$123,0)),"") | Q7: =IFERROR(VLOOKUP(M7,'הגדרות'!$A$11:$D$25,2,FALSE),"") | R7: =IFERROR(VLOOKUP(M7,'הגדרות'!$A$11:$D$25,3,FALSE),"") | S7: =IFERROR(VLOOKUP(N7,'הגדרות'!$A$11:$D$25,2,FALSE),"") | T7: =IFERROR(VLOOKUP(N7,'הגדרות'!$A$11:$D$25,3,FALSE),"") | AE7: =IF('לוח בקרה'!$A$2="הכל",TRUE,OR(Q7='לוח בקרה'!$A$2,R7='לוח בקרה'!$A$2,S7='לוח בקרה'!$A$2,T7='לוח בקרה'!$A$2)) | AF7: =AND(AE7,OR(AND(O7="כן",U7="כן"),AND(P7="כן",V7="כן"))) | AG7: =AND(AE7,OR(O7="כן",P7="כן"),NOT(OR(AND(O7="כן",U7="כן"),AND(P7="כן",V7="כן")))) | AH7: =AND(AE7,OR(U7="כן",V7="כן"),NOT(OR(O7="כן",P7="כן"))) | AI7: =AND(X7="מושאל",AB7<>"",AB7<TODAY())
E8: =IFERROR(INDEX('הגדרות'!$D$104:$D$123,MATCH(B8&G8&C8,'הגדרות'!$A$104:$A$123&'הגדרות'!$B$104:$B$123&'הגדרות'!$C$104:$C$123,0)),"") | Q8: =IFERROR(VLOOKUP(M8,'הגדרות'!$A$11:$D$25,2,FALSE),"") | R8: =IFERROR(VLOOKUP(M8,'הגדרות'!$A$11:$D$25,3,FALSE),"") | S8: =IFERROR(VLOOKUP(N8,'הגדרות'!$A$11:$D$25,2,FALSE),"") | T8: =IFERROR(VLOOKUP(N8,'הגדרות'!$A$11:$D$25,3,FALSE),"") | AE8: =IF('לוח בקרה'!$A$2="הכל",TRUE,OR(Q8='לוח בקרה'!$A$2,R8='לוח בקרה'!$A$2,S8='לוח בקרה'!$A$2,T8='לוח בקרה'!$A$2)) | AF8: =AND(AE8,OR(AND(O8="כן",U8="כן"),AND(P8="כן",V8="כן"))) | AG8: =AND(AE8,OR(O8="כן",P8="כן"),NOT(OR(AND(O8="כן",U8="כן"),AND(P8="כן",V8="כן")))) | AH8: =AND(AE8,OR(U8="כן",V8="כן"),NOT(OR(O8="כן",P8="כן"))) | AI8: =AND(X8="מושאל",AB8<>"",AB8<TODAY())
E9: =IFERROR(INDEX('הגדרות'!$D$104:$D$123,MATCH(B9&G9&C9,'הגדרות'!$A$104:$A$123&'הגדרות'!$B$104:$B$123&'הגדרות'!$C$104:$C$123,0)),"") | Q9: =IFERROR(VLOOKUP(M9,'הגדרות'!$A$11:$D$25,2,FALSE),"") | R9: =IFERROR(VLOOKUP(M9,'הגדרות'!$A$11:$D$25,3,FALSE),"") | S9: =IFERROR(VLOOKUP(N9,'הגדרות'!$A$11:$D$25,2,FALSE),"") | T9: =IFERROR(VLOOKUP(N9,'הגדרות'!$A$11:$D$25,3,FALSE),"") | AE9: =IF('לוח בקרה'!$A$2="הכל",TRUE,OR(Q9='לוח בקרה'!$A$2,R9='לוח בקרה'!$A$2,S9='לוח בקרה'!$A$2,T9='לוח בקרה'!$A$2)) | AF9: =AND(AE9,OR(AND(O9="כן",U9="כן"),AND(P9="כן",V9="כן"))) | AG9: =AND(AE9,OR(O9="כן",P9="כן"),NOT(OR(AND(O9="כן",U9="כן"),AND(P9="כן",V9="כן")))) | AH9: =AND(AE9,OR(U9="כן",V9="כן"),NOT(OR(O9="כן",P9="כן"))) | AI9: =AND(X9="מושאל",AB9<>"",AB9<TODAY())
E10: =IFERROR(INDEX('הגדרות'!$D$104:$D$123,MATCH(B10&G10&C10,'הגדרות'!$A$104:$A$123&'הגדרות'!$B$104:$B$123&'הגדרות'!$C$104:$C$123,0)),"") | Q10: =IFERROR(VLOOKUP(M10,'הגדרות'!$A$11:$D$25,2,FALSE),"") | R10: =IFERROR(VLOOKUP(M10,'הגדרות'!$A$11:$D$25,3,FALSE),"") | S10: =IFERROR(VLOOKUP(N10,'הגדרות'!$A$11:$D$25,2,FALSE),"") | T10: =IFERROR(VLOOKUP(N10,'הגדרות'!$A$11:$D$25,3,FALSE),"") | AE10: =IF('לוח בקרה'!$A$2="הכל",TRUE,OR(Q10='לוח בקרה'!$A$2,R10='לוח בקרה'!$A$2,S10='לוח בקרה'!$A$2,T10='לוח בקרה'!$A$2)) | AF10: =AND(AE10,OR(AND(O10="כן",U10="כן"),AND(P10="כן",V10="כן"))) | AG10: =AND(AE10,OR(O10="כן",P10="כן"),NOT(OR(AND(O10="כן",U10="כן"),AND(P10="כן",V10="כן")))) | AH10: =AND(AE10,OR(U10="כן",V10="כן"),NOT(OR(O10="כן",P10="כן"))) | AI10: =AND(X10="מושאל",AB10<>"",AB10<TODAY())
E11: =IFERROR(INDEX('הגדרות'!$D$104:$D$123,MATCH(B11&G11&C11,'הגדרות'!$A$104:$A$123&'הגדרות'!$B$104:$B$123&'הגדרות'!$C$104:$C$123,0)),"") | Q11: =IFERROR(VLOOKUP(M11,'הגדרות'!$A$11:$D$25,2,FALSE),"") | R11: =IFERROR(VLOOKUP(M11,'הגדרות'!$A$11:$D$25,3,FALSE),"") | S11: =IFERROR(VLOOKUP(N11,'הגדרות'!$A$11:$D$25,2,FALSE),"") | T11: =IFERROR(VLOOKUP(N11,'הגדרות'!$A$11:$D$25,3,FALSE),"") | AE11: =IF('לוח בקרה'!$A$2="הכל",TRUE,OR(Q11='לוח בקרה'!$A$2,R11='לוח בקרה'!$A$2,S11='לוח בקרה'!$A$2,T11='לוח בקרה'!$A$2)) | AF11: =AND(AE11,OR(AND(O11="כן",U11="כן"),AND(P11="כן",V11="כן"))) | AG11: =AND(AE11,OR(O11="כן",P11="כן"),NOT(OR(AND(O11="כן",U11="כן"),AND(P11="כן",V11="כן")))) | AH11: =AND(AE11,OR(U11="כן",V11="כן"),NOT(OR(O11="כן",P11="כן"))) | AI11: =AND(X11="מושאל",AB11<>"",AB11<TODAY())
E12: =IFERROR(INDEX('הגדרות'!$D$104:$D$123,MATCH(B12&G12&C12,'הגדרות'!$A$104:$A$123&'הגדרות'!$B$104:$B$123&'הגדרות'!$C$104:$C$123,0)),"") | Q12: =IFERROR(VLOOKUP(M12,'הגדרות'!$A$11:$D$25,2,FALSE),"") | R12: =IFERROR(VLOOKUP(M12,'הגדרות'!$A$11:$D$25,3,FALSE),"") | S12: =IFERROR(VLOOKUP(N12,'הגדרות'!$A$11:$D$25,2,FALSE),"") | T12: =IFERROR(VLOOKUP(N12,'הגדרות'!$A$11:$D$25,3,FALSE),"") | AE12: =IF('לוח בקרה'!$A$2="הכל",TRUE,OR(Q12='לוח בקרה'!$A$2,R12='לוח בקרה'!$A$2,S12='לוח בקרה'!$A$2,T12='לוח בקרה'!$A$2)) | AF12: =AND(AE12,OR(AND(O12="כן",U12="כן"),AND(P12="כן",V12="כן"))) | AG12: =AND(AE12,OR(O12="כן",P12="כן"),NOT(OR(AND(O12="כן",U12="כן"),AND(P12="כן",V12="כן")))) | AH12: =AND(AE12,OR(U12="כן",V12="כן"),NOT(OR(O12="כן",P12="כן"))) | AI12: =AND(X12="מושאל",AB12<>"",AB12<TODAY())
E13: =IFERROR(INDEX('הגדרות'!$D$104:$D$123,MATCH(B13&G13&C13,'הגדרות'!$A$104:$A$123&'הגדרות'!$B$104:$B$123&'הגדרות'!$C$104:$C$123,0)),"") | Q13: =IFERROR(VLOOKUP(M13,'הגדרות'!$A$11:$D$25,2,FALSE),"") | R13: =IFERROR(VLOOKUP(M13,'הגדרות'!$A$11:$D$25,3,FALSE),"") | S13: =IFERROR(VLOOKUP(N13,'הגדרות'!$A$11:$D$25,2,FALSE),"") | T13: =IFERROR(VLOOKUP(N13,'הגדרות'!$A$11:$D$25,3,FALSE),"") | AE13: =IF('לוח בקרה'!$A$2="הכל",TRUE,OR(Q13='לוח בקרה'!$A$2,R13='לוח בקרה'!$A$2,S13='לוח בקרה'!$A$2,T13='לוח בקרה'!$A$2)) | AF13: =AND(AE13,OR(AND(O13="כן",U13="כן"),AND(P13="כן",V13="כן"))) | AG13: =AND(AE13,OR(O13="כן",P13="כן"),NOT(OR(AND(O13="כן",U13="כן"),AND(P13="כן",V13="כן")))) | AH13: =AND(AE13,OR(U13="כן",V13="כן"),NOT(OR(O13="כן",P13="כן"))) | AI13: =AND(X13="מושאל",AB13<>"",AB13<TODAY())
E14: =IFERROR(INDEX('הגדרות'!$D$104:$D$123,MATCH(B14&G14&C14,'הגדרות'!$A$104:$A$123&'הגדרות'!$B$104:$B$123&'הגדרות'!$C$104:$C$123,0)),"") | Q14: =IFERROR(VLOOKUP(M14,'הגדרות'!$A$11:$D$25,2,FALSE),"") | R14: =IFERROR(VLOOKUP(M14,'הגדרות'!$A$11:$D$25,3,FALSE),"") | S14: =IFERROR(VLOOKUP(N14,'הגדרות'!$A$11:$D$25,2,FALSE),"") | T14: =IFERROR(VLOOKUP(N14,'הגדרות'!$A$11:$D$25,3,FALSE),"") | AE14: =IF('לוח בקרה'!$A$2="הכל",TRUE,OR(Q14='לוח בקרה'!$A$2,R14='לוח בקרה'!$A$2,S14='לוח בקרה'!$A$2,T14='לוח בקרה'!$A$2)) | AF14: =AND(AE14,OR(AND(O14="כן",U14="כן"),AND(P14="כן",V14="כן"))) | AG14: =AND(AE14,OR(O14="כן",P14="כן"),NOT(OR(AND(O14="כן",U14="כן"),AND(P14="כן",V14="כן")))) | AH14: =AND(AE14,OR(U14="כן",V14="כן"),NOT(OR(O14="כן",P14="כן"))) | AI14: =AND(X14="מושאל",AB14<>"",AB14<TODAY())
E15: =IFERROR(INDEX('הגדרות'!$D$104:$D$123,MATCH(B15&G15&C15,'הגדרות'!$A$104:$A$123&'הגדרות'!$B$104:$B$123&'הגדרות'!$C$104:$C$123,0)),"") | Q15: =IFERROR(VLOOKUP(M15,'הגדרות'!$A$11:$D$25,2,FALSE),"") | R15: =IFERROR(VLOOKUP(M15,'הגדרות'!$A$11:$D$25,3,FALSE),"") | S15: =IFERROR(VLOOKUP(N15,'הגדרות'!$A$11:$D$25,2,FALSE),"") | T15: =IFERROR(VLOOKUP(N15,'הגדרות'!$A$11:$D$25,3,FALSE),"") | AE15: =IF('לוח בקרה'!$A$2="הכל",TRUE,OR(Q15='לוח בקרה'!$A$2,R15='לוח בקרה'!$A$2,S15='לוח בקרה'!$A$2,T15='לוח בקרה'!$A$2)) | AF15: =AND(AE15,OR(AND(O15="כן",U15="כן"),AND(P15="כן",V15="כן"))) | AG15: =AND(AE15,OR(O15="כן",P15="כן"),NOT(OR(AND(O15="כן",U15="כן"),AND(P15="כן",V15="כן")))) | AH15: =AND(AE15,OR(U15="כן",V15="כן"),NOT(OR(O15="כן",P15="כן"))) | AI15: =AND(X15="מושאל",AB15<>"",AB15<TODAY())
E16: =IFERROR(INDEX('הגדרות'!$D$104:$D$123,MATCH(B16&G16&C16,'הגדרות'!$A$104:$A$123&'הגדרות'!$B$104:$B$123&'הגדרות'!$C$104:$C$123,0)),"") | Q16: =IFERROR(VLOOKUP(M16,'הגדרות'!$A$11:$D$25,2,FALSE),"") | R16: =IFERROR(VLOOKUP(M16,'הגדרות'!$A$11:$D$25,3,FALSE),"") | S16: =IFERROR(VLOOKUP(N16,'הגדרות'!$A$11:$D$25,2,FALSE),"") | T16: =IFERROR(VLOOKUP(N16,'הגדרות'!$A$11:$D$25,3,FALSE),"") | AE16: =IF('לוח בקרה'!$A$2="הכל",TRUE,OR(Q16='לוח בקרה'!$A$2,R16='לוח בקרה'!$A$2,S16='לוח בקרה'!$A$2,T16='לוח בקרה'!$A$2)) | AF16: =AND(AE16,OR(AND(O16="כן",U16="כן"),AND(P16="כן",V16="כן"))) | AG16: =AND(AE16,OR(O16="כן",P16="כן"),NOT(OR(AND(O16="כן",U16="כן"),AND(P16="כן",V16="כן")))) | AH16: =AND(AE16,OR(U16="כן",V16="כן"),NOT(OR(O16="כן",P16="כן"))) | AI16: =AND(X16="מושאל",AB16<>"",AB16<TODAY())
E17: =IFERROR(INDEX('הגדרות'!$D$104:$D$123,MATCH(B17&G17&C17,'הגדרות'!$A$104:$A$123&'הגדרות'!$B$104:$B$123&'הגדרות'!$C$104:$C$123,0)),"") | Q17: =IFERROR(VLOOKUP(M17,'הגדרות'!$A$11:$D$25,2,FALSE),"") | R17: =IFERROR(VLOOKUP(M17,'הגדרות'!$A$11:$D$25,3,FALSE),"") | S17: =IFERROR(VLOOKUP(N17,'הגדרות'!$A$11:$D$25,2,FALSE),"") | T17: =IFERROR(VLOOKUP(N17,'הגדרות'!$A$11:$D$25,3,FALSE),"") | AE17: =IF('לוח בקרה'!$A$2="הכל",TRUE,OR(Q17='לוח בקרה'!$A$2,R17='לוח בקרה'!$A$2,S17='לוח בקרה'!$A$2,T17='לוח בקרה'!$A$2)) | AF17: =AND(AE17,OR(AND(O17="כן",U17="כן"),AND(P17="כן",V17="כן"))) | AG17: =AND(AE17,OR(O17="כן",P17="כן"),NOT(OR(AND(O17="כן",U17="כן"),AND(P17="כן",V17="כן")))) | AH17: =AND(AE17,OR(U17="כן",V17="כן"),NOT(OR(O17="כן",P17="כן"))) | AI17: =AND(X17="מושאל",AB17<>"",AB17<TODAY())
E18: =IFERROR(INDEX('הגדרות'!$D$104:$D$123,MATCH(B18&G18&C18,'הגדרות'!$A$104:$A$123&'הגדרות'!$B$104:$B$123&'הגדרות'!$C$104:$C$123,0)),"") | Q18: =IFERROR(VLOOKUP(M18,'הגדרות'!$A$11:$D$25,2,FALSE),"") | R18: =IFERROR(VLOOKUP(M18,'הגדרות'!$A$11:$D$25,3,FALSE),"") | S18: =IFERROR(VLOOKUP(N18,'הגדרות'!$A$11:$D$25,2,FALSE),"") | T18: =IFERROR(VLOOKUP(N18,'הגדרות'!$A$11:$D$25,3,FALSE),"") | AE18: =IF('לוח בקרה'!$A$2="הכל",TRUE,OR(Q18='לוח בקרה'!$A$2,R18='לוח בקרה'!$A$2,S18='לוח בקרה'!$A$2,T18='לוח בקרה'!$A$2)) | AF18: =AND(AE18,OR(AND(O18="כן",U18="כן"),AND(P18="כן",V18="כן"))) | AG18: =AND(AE18,OR(O18="כן",P18="כן"),NOT(OR(AND(O18="כן",U18="כן"),AND(P18="כן",V18="כן")))) | AH18: =AND(AE18,OR(U18="כן",V18="כן"),NOT(OR(O18="כן",P18="כן"))) | AI18: =AND(X18="מושאל",AB18<>"",AB18<TODAY())
... E500: =IFERROR(INDEX('הגדרות'!$D$104:$D$123,MATCH(B500&G500&C500,'הגדרות'!$A$104:$A$123&'הגדרות'!$B$104:$B$123&'הגדרות'!$C$104:$C$123,0)),"") | Q500: =IFERROR(VLOOKUP(M500,'הגדרות'!$A$11:$D$25,2,FALSE),"") | R500: =IFERROR(VLOOKUP(M500,'הגדרות'!$A$11:$D$25,3,FALSE),"") | S500: =IFERROR(VLOOKUP(N500,'הגדרות'!$A$11:$D$25,2,FALSE),"") | T500: =IFERROR(VLOOKUP(N500,'הגדרות'!$A$11:$D$25,3,FALSE),"") | AE500: =IF('לוח בקרה'!$A$2="הכל",TRUE,OR(Q500='לוח בקרה'!$A$2,R500='לוח בקרה'!$A$2,S500='לוח בקרה'!$A$2,T500='לוח בקרה'!$A$2)) | AF500: =AND(AE500,OR(AND(O500="כן",U500="כן"),AND(P500="כן",V500="כן"))) | AG500: =AND(AE500,OR(O500="כן",P500="כן"),NOT(OR(AND(O500="כן",U500="כן"),AND(P500="כן",V500="כן")))) | AH500: =AND(AE500,OR(U500="כן",V500="כן"),NOT(OR(O500="כן",P500="כן"))) | AI500: =AND(X500="מושאל",AB500<>"",AB500<TODAY())

Sheet השאלות
A1: מדינה | B1: מושאל ל | C1: אחראי מהחברה | D1: באיחור
A4: מזהה ייחודי | B4: שם מוצר | C4: גרסה | D4: מושאל ל | E4: מדינה | F4: אחראי מהחברה | G4: תאריך השאלה | H4: החזרה משוערת | I4: באיחור | J4: הערות | K4: row_ref
A5: =IF($K5="","",INDEX(מלאי!$D$2:$D$500,$K5)) | B5: =IF($K5="","",INDEX(מלאי!$B$2:$B$500,$K5)) | C5: =IF($K5="","",INDEX(מלאי!$C$2:$C$500,$K5)) | D5: =IF($K5="","",INDEX(מלאי!$Y$2:$Y$500,$K5)) | E5: =IF($K5="","",INDEX(מלאי!$Z$2:$Z$500,$K5)) | F5: =IF($K5="","",INDEX(מלאי!$AA$2:$AA$500,$K5)) | G5: =IF($K5="","",INDEX(מלאי!$F$2:$F$500,$K5)) | H5: =IF($K5="","",INDEX(מלאי!$AB$2:$AB$500,$K5)) | I5: =IF($K5="","",IF(AND(INDEX(מלאי!$AB$2:$AB$500,$K5)<>"",INDEX(מלאי!$AB$2:$AB$500,$K5)<TODAY()),"באיחור!","תקין")) | J5: =IF($K5="","",INDEX(מלאי!$AC$2:$AC$500,$K5)) | K5: =IFERROR(SMALL(IF((מלאי!$X$2:$X$500="מושאל")*(IF($A$2="",1,מלאי!$Z$2:$Z$500=$A$2))*(IF($B$2="",1,מלאי!$Y$2:$Y$500=$B$2))*(IF($C$2="",1,מלאי!$AA$2:$AA$500=$C$2))*(IF($D$2="",1,IF($D$2="כן",(מלאי!$AB$2:$AB$500<>"")*(מלאי!$AB$2:$AB$500<TODAY()),1-(מלאי!$AB$2:$AB$500<>"")*(מלאי!$AB$2:$AB$500<TODAY())))),ROW(מלאי!$A$2:$A$500)-ROW(מלאי!$A$2)+1,""),1),"")
A6: =IF($K6="","",INDEX(מלאי!$D$2:$D$500,$K6)) | B6: =IF($K6="","",INDEX(מלאי!$B$2:$B$500,$K6)) | C6: =IF($K6="","",INDEX(מלאי!$C$2:$C$500,$K6)) | D6: =IF($K6="","",INDEX(מלאי!$Y$2:$Y$500,$K6)) | E6: =IF($K6="","",INDEX(מלאי!$Z$2:$Z$500,$K6)) | F6: =IF($K6="","",INDEX(מלאי!$AA$2:$AA$500,$K6)) | G6: =IF($K6="","",INDEX(מלאי!$F$2:$F$500,$K6)) | H6: =IF($K6="","",INDEX(מלאי!$AB$2:$AB$500,$K6)) | I6: =IF($K6="","",IF(AND(INDEX(מלאי!$AB$2:$AB$500,$K6)<>"",INDEX(מלאי!$AB$2:$AB$500,$K6)<TODAY()),"באיחור!","תקין")) | J6: =IF($K6="","",INDEX(מלאי!$AC$2:$AC$500,$K6)) | K6: =IFERROR(SMALL(IF((מלאי!$X$2:$X$500="מושאל")*(IF($A$2="",1,מלאי!$Z$2:$Z$500=$A$2))*(IF($B$2="",1,מלאי!$Y$2:$Y$500=$B$2))*(IF($C$2="",1,מלאי!$AA$2:$AA$500=$C$2))*(IF($D$2="",1,IF($D$2="כן",(מלאי!$AB$2:$AB$500<>"")*(מלאי!$AB$2:$AB$500<TODAY()),1-(מלאי!$AB$2:$AB$500<>"")*(מלאי!$AB$2:$AB$500<TODAY())))),ROW(מלאי!$A$2:$A$500)-ROW(מלאי!$A$2)+1,""),2),"")
A7: =IF($K7="","",INDEX(מלאי!$D$2:$D$500,$K7)) | B7: =IF($K7="","",INDEX(מלאי!$B$2:$B$500,$K7)) | C7: =IF($K7="","",INDEX(מלאי!$C$2:$C$500,$K7)) | D7: =IF($K7="","",INDEX(מלאי!$Y$2:$Y$500,$K7)) | E7: =IF($K7="","",INDEX(מלאי!$Z$2:$Z$500,$K7)) | F7: =IF($K7="","",INDEX(מלאי!$AA$2:$AA$500,$K7)) | G7: =IF($K7="","",INDEX(מלאי!$F$2:$F$500,$K7)) | H7: =IF($K7="","",INDEX(מלאי!$AB$2:$AB$500,$K7)) | I7: =IF($K7="","",IF(AND(INDEX(מלאי!$AB$2:$AB$500,$K7)<>"",INDEX(מלאי!$AB$2:$AB$500,$K7)<TODAY()),"באיחור!","תקין")) | J7: =IF($K7="","",INDEX(מלאי!$AC$2:$AC$500,$K7)) | K7: =IFERROR(SMALL(IF((מלאי!$X$2:$X$500="מושאל")*(IF($A$2="",1,מלאי!$Z$2:$Z$500=$A$2))*(IF($B$2="",1,מלאי!$Y$2:$Y$500=$B$2))*(IF($C$2="",1,מלאי!$AA$2:$AA$500=$C$2))*(IF($D$2="",1,IF($D$2="כן",(מלאי!$AB$2:$AB$500<>"")*(מלאי!$AB$2:$AB$500<TODAY()),1-(מלאי!$AB$2:$AB$500<>"")*(מלאי!$AB$2:$AB$500<TODAY())))),ROW(מלאי!$A$2:$A$500)-ROW(מלאי!$A$2)+1,""),3),"")
A8: =IF($K8="","",INDEX(מלאי!$D$2:$D$500,$K8)) | B8: =IF($K8="","",INDEX(מלאי!$B$2:$B$500,$K8)) | C8: =IF($K8="","",INDEX(מלאי!$C$2:$C$500,$K8)) | D8: =IF($K8="","",INDEX(מלאי!$Y$2:$Y$500,$K8)) | E8: =IF($K8="","",INDEX(מלאי!$Z$2:$Z$500,$K8)) | F8: =IF($K8="","",INDEX(מלאי!$AA$2:$AA$500,$K8)) | G8: =IF($K8="","",INDEX(מלאי!$F$2:$F$500,$K8)) | H8: =IF($K8="","",INDEX(מלאי!$AB$2:$AB$500,$K8)) | I8: =IF($K8="","",IF(AND(INDEX(מלאי!$AB$2:$AB$500,$K8)<>"",INDEX(מלאי!$AB$2:$AB$500,$K8)<TODAY()),"באיחור!","תקין")) | J8: =IF($K8="","",INDEX(מלאי!$AC$2:$AC$500,$K8)) | K8: =IFERROR(SMALL(IF((מלאי!$X$2:$X$500="מושאל")*(IF($A$2="",1,מלאי!$Z$2:$Z$500=$A$2))*(IF($B$2="",1,מלאי!$Y$2:$Y$500=$B$2))*(IF($C$2="",1,מלאי!$AA$2:$AA$500=$C$2))*(IF($D$2="",1,IF($D$2="כן",(מלאי!$AB$2:$AB$500<>"")*(מלאי!$AB$2:$AB$500<TODAY()),1-(מלאי!$AB$2:$AB$500<>"")*(מלאי!$AB$2:$AB$500<TODAY())))),ROW(מלאי!$A$2:$A$500)-ROW(מלאי!$A$2)+1,""),4),"")
A9: =IF($K9="","",INDEX(מלאי!$D$2:$D$500,$K9)) | B9: =IF($K9="","",INDEX(מלאי!$B$2:$B$500,$K9)) | C9: =IF($K9="","",INDEX(מלאי!$C$2:$C$500,$K9)) | D9: =IF($K9="","",INDEX(מלאי!$Y$2:$Y$500,$K9)) | E9: =IF($K9="","",INDEX(מלאי!$Z$2:$Z$500,$K9)) | F9: =IF($K9="","",INDEX(מלאי!$AA$2:$AA$500,$K9)) | G9: =IF($K9="","",INDEX(מלאי!$F$2:$F$500,$K9)) | H9: =IF($K9="","",INDEX(מלאי!$AB$2:$AB$500,$K9)) | I9: =IF($K9="","",IF(AND(INDEX(מלאי!$AB$2:$AB$500,$K9)<>"",INDEX(מלאי!$AB$2:$AB$500,$K9)<TODAY()),"באיחור!","תקין")) | J9: =IF($K9="","",INDEX(מלאי!$AC$2:$AC$500,$K9)) | K9: =IFERROR(SMALL(IF((מלאי!$X$2:$X$500="מושאל")*(IF($A$2="",1,מלאי!$Z$2:$Z$500=$A$2))*(IF($B$2="",1,מלאי!$Y$2:$Y$500=$B$2))*(IF($C$2="",1,מלאי!$AA$2:$AA$500=$C$2))*(IF($D$2="",1,IF($D$2="כן",(מלאי!$AB$2:$AB$500<>"")*(מלאי!$AB$2:$AB$500<TODAY()),1-(מלאי!$AB$2:$AB$500<>"")*(מלאי!$AB$2:$AB$500<TODAY())))),ROW(מלאי!$A$2:$A$500)-ROW(מלאי!$A$2)+1,""),5),"")
A10: =IF($K10="","",INDEX(מלאי!$D$2:$D$500,$K10)) | B10: =IF($K10="","",INDEX(מלאי!$B$2:$B$500,$K10)) | C10: =IF($K10="","",INDEX(מלאי!$C$2:$C$500,$K10)) | D10: =IF($K10="","",INDEX(מלאי!$Y$2:$Y$500,$K10)) | E10: =IF($K10="","",INDEX(מלאי!$Z$2:$Z$500,$K10)) | F10: =IF($K10="","",INDEX(מלאי!$AA$2:$AA$500,$K10)) | G10: =IF($K10="","",INDEX(מלאי!$F$2:$F$500,$K10)) | H10: =IF($K10="","",INDEX(מלאי!$AB$2:$AB$500,$K10)) | I10: =IF($K10="","",IF(AND(INDEX(מלאי!$AB$2:$AB$500,$K10)<>"",INDEX(מלאי!$AB$2:$AB$500,$K10)<TODAY()),"באיחור!","תקין")) | J10: =IF($K10="","",INDEX(מלאי!$AC$2:$AC$500,$K10)) | K10: =IFERROR(SMALL(IF((מלאי!$X$2:$X$500="מושאל")*(IF($A$2="",1,מלאי!$Z$2:$Z$500=$A$2))*(IF($B$2="",1,מלאי!$Y$2:$Y$500=$B$2))*(IF($C$2="",1,מלאי!$AA$2:$AA$500=$C$2))*(IF($D$2="",1,IF($D$2="כן",(מלאי!$AB$2:$AB$500<>"")*(מלאי!$AB$2:$AB$500<TODAY()),1-(מלאי!$AB$2:$AB$500<>"")*(מלאי!$AB$2:$AB$500<TODAY())))),ROW(מלאי!$A$2:$A$500)-ROW(מלאי!$A$2)+1,""),6),"")
A11: =IF($K11="","",INDEX(מלאי!$D$2:$D$500,$K11)) | B11: =IF($K11="","",INDEX(מלאי!$B$2:$B$500,$K11)) | C11: =IF($K11="","",INDEX(מלאי!$C$2:$C$500,$K11)) | D11: =IF($K11="","",INDEX(מלאי!$Y$2:$Y$500,$K11)) | E11: =IF($K11="","",INDEX(מלאי!$Z$2:$Z$500,$K11)) | F11: =IF($K11="","",INDEX(מלאי!$AA$2:$AA$500,$K11)) | G11: =IF($K11="","",INDEX(מלאי!$F$2:$F$500,$K11)) | H11: =IF($K11="","",INDEX(מלאי!$AB$2:$AB$500,$K11)) | I11: =IF($K11="","",IF(AND(INDEX(מלאי!$AB$2:$AB$500,$K11)<>"",INDEX(מלאי!$AB$2:$AB$500,$K11)<TODAY()),"באיחור!","תקין")) | J11: =IF($K11="","",INDEX(מלאי!$AC$2:$AC$500,$K11)) | K11: =IFERROR(SMALL(IF((מלאי!$X$2:$X$500="מושאל")*(IF($A$2="",1,מלאי!$Z$2:$Z$500=$A$2))*(IF($B$2="",1,מלאי!$Y$2:$Y$500=$B$2))*(IF($C$2="",1,מלאי!$AA$2:$AA$500=$C$2))*(IF($D$2="",1,IF($D$2="כן",(מלאי!$AB$2:$AB$500<>"")*(מלאי!$AB$2:$AB$500<TODAY()),1-(מלאי!$AB$2:$AB$500<>"")*(מלאי!$AB$2:$AB$500<TODAY())))),ROW(מלאי!$A$2:$A$500)-ROW(מלאי!$A$2)+1,""),7),"")
A12: =IF($K12="","",INDEX(מלאי!$D$2:$D$500,$K12)) | B12: =IF($K12="","",INDEX(מלאי!$B$2:$B$500,$K12)) | C12: =IF($K12="","",INDEX(מלאי!$C$2:$C$500,$K12)) | D12: =IF($K12="","",INDEX(מלאי!$Y$2:$Y$500,$K12)) | E12: =IF($K12="","",INDEX(מלאי!$Z$2:$Z$500,$K12)) | F12: =IF($K12="","",INDEX(מלאי!$AA$2:$AA$500,$K12)) | G12: =IF($K12="","",INDEX(מלאי!$F$2:$F$500,$K12)) | H12: =IF($K12="","",INDEX(מלאי!$AB$2:$AB$500,$K12)) | I12: =IF($K12="","",IF(AND(INDEX(מלאי!$AB$2:$AB$500,$K12)<>"",INDEX(מלאי!$AB$2:$AB$500,$K12)<TODAY()),"באיחור!","תקין")) | J12: =IF($K12="","",INDEX(מלאי!$AC$2:$AC$500,$K12)) | K12: =IFERROR(SMALL(IF((מלאי!$X$2:$X$500="מושאל")*(IF($A$2="",1,מלאי!$Z$2:$Z$500=$A$2))*(IF($B$2="",1,מלאי!$Y$2:$Y$500=$B$2))*(IF($C$2="",1,מלאי!$AA$2:$AA$500=$C$2))*(IF($D$2="",1,IF($D$2="כן",(מלאי!$AB$2:$AB$500<>"")*(מלאי!$AB$2:$AB$500<TODAY()),1-(מלאי!$AB$2:$AB$500<>"")*(מלאי!$AB$2:$AB$500<TODAY())))),ROW(מלאי!$A$2:$A$500)-ROW(מלאי!$A$2)+1,""),8),"")
A13: =IF($K13="","",INDEX(מלאי!$D$2:$D$500,$K13)) | B13: =IF($K13="","",INDEX(מלאי!$B$2:$B$500,$K13)) | C13: =IF($K13="","",INDEX(מלאי!$C$2:$C$500,$K13)) | D13: =IF($K13="","",INDEX(מלאי!$Y$2:$Y$500,$K13)) | E13: =IF($K13="","",INDEX(מלאי!$Z$2:$Z$500,$K13)) | F13: =IF($K13="","",INDEX(מלאי!$AA$2:$AA$500,$K13)) | G13: =IF($K13="","",INDEX(מלאי!$F$2:$F$500,$K13)) | H13: =IF($K13="","",INDEX(מלאי!$AB$2:$AB$500,$K13)) | I13: =IF($K13="","",IF(AND(INDEX(מלאי!$AB$2:$AB$500,$K13)<>"",INDEX(מלאי!$AB$2:$AB$500,$K13)<TODAY()),"באיחור!","תקין")) | J13: =IF($K13="","",INDEX(מלאי!$AC$2:$AC$500,$K13)) | K13: =IFERROR(SMALL(IF((מלאי!$X$2:$X$500="מושאל")*(IF($A$2="",1,מלאי!$Z$2:$Z$500=$A$2))*(IF($B$2="",1,מלאי!$Y$2:$Y$500=$B$2))*(IF($C$2="",1,מלאי!$AA$2:$AA$500=$C$2))*(IF($D$2="",1,IF($D$2="כן",(מלאי!$AB$2:$AB$500<>"")*(מלאי!$AB$2:$AB$500<TODAY()),1-(מלאי!$AB$2:$AB$500<>"")*(מלאי!$AB$2:$AB$500<TODAY())))),ROW(מלאי!$A$2:$A$500)-ROW(מלאי!$A$2)+1,""),9),"")
A14: =IF($K14="","",INDEX(מלאי!$D$2:$D$500,$K14)) | B14: =IF($K14="","",INDEX(מלאי!$B$2:$B$500,$K14)) | C14: =IF($K14="","",INDEX(מלאי!$C$2:$C$500,$K14)) | D14: =IF($K14="","",INDEX(מלאי!$Y$2:$Y$500,$K14)) | E14: =IF($K14="","",INDEX(מלאי!$Z$2:$Z$500,$K14)) | F14: =IF($K14="","",INDEX(מלאי!$AA$2:$AA$500,$K14)) | G14: =IF($K14="","",INDEX(מלאי!$F$2:$F$500,$K14)) | H14: =IF($K14="","",INDEX(מלאי!$AB$2:$AB$500,$K14)) | I14: =IF($K14="","",IF(AND(INDEX(מלאי!$AB$2:$AB$500,$K14)<>"",INDEX(מלאי!$AB$2:$AB$500,$K14)<TODAY()),"באיחור!","תקין")) | J14: =IF($K14="","",INDEX(מלאי!$AC$2:$AC$500,$K14)) | K14: =IFERROR(SMALL(IF((מלאי!$X$2:$X$500="מושאל")*(IF($A$2="",1,מלאי!$Z$2:$Z$500=$A$2))*(IF($B$2="",1,מלאי!$Y$2:$Y$500=$B$2))*(IF($C$2="",1,מלאי!$AA$2:$AA$500=$C$2))*(IF($D$2="",1,IF($D$2="כן",(מלאי!$AB$2:$AB$500<>"")*(מלאי!$AB$2:$AB$500<TODAY()),1-(מלאי!$AB$2:$AB$500<>"")*(מלאי!$AB$2:$AB$500<TODAY())))),ROW(מלאי!$A$2:$A$500)-ROW(מלאי!$A$2)+1,""),10),"")
A15: =IF($K15="","",INDEX(מלאי!$D$2:$D$500,$K15)) | B15: =IF($K15="","",INDEX(מלאי!$B$2:$B$500,$K15)) | C15: =IF($K15="","",INDEX(מלאי!$C$2:$C$500,$K15)) | D15: =IF($K15="","",INDEX(מלאי!$Y$2:$Y$500,$K15)) | E15: =IF($K15="","",INDEX(מלאי!$Z$2:$Z$500,$K15)) | F15: =IF($K15="","",INDEX(מלאי!$AA$2:$AA$500,$K15)) | G15: =IF($K15="","",INDEX(מלאי!$F$2:$F$500,$K15)) | H15: =IF($K15="","",INDEX(מלאי!$AB$2:$AB$500,$K15)) | I15: =IF($K15="","",IF(AND(INDEX(מלאי!$AB$2:$AB$500,$K15)<>"",INDEX(מלאי!$AB$2:$AB$500,$K15)<TODAY()),"באיחור!","תקין")) | J15: =IF($K15="","",INDEX(מלאי!$AC$2:$AC$500,$K15)) | K15: =IFERROR(SMALL(IF((מלאי!$X$2:$X$500="מושאל")*(IF($A$2="",1,מלאי!$Z$2:$Z$500=$A$2))*(IF($B$2="",1,מלאי!$Y$2:$Y$500=$B$2))*(IF($C$2="",1,מלאי!$AA$2:$AA$500=$C$2))*(IF($D$2="",1,IF($D$2="כן",(מלאי!$AB$2:$AB$500<>"")*(מלאי!$AB$2:$AB$500<TODAY()),1-(מלאי!$AB$2:$AB$500<>"")*(מלאי!$AB$2:$AB$500<TODAY())))),ROW(מלאי!$A$2:$A$500)-ROW(מלאי!$A$2)+1,""),11),"")
A16: =IF($K16="","",INDEX(מלאי!$D$2:$D$500,$K16)) | B16: =IF($K16="","",INDEX(מלאי!$B$2:$B$500,$K16)) | C16: =IF($K16="","",INDEX(מלאי!$C$2:$C$500,$K16)) | D16: =IF($K16="","",INDEX(מלאי!$Y$2:$Y$500,$K16)) | E16: =IF($K16="","",INDEX(מלאי!$Z$2:$Z$500,$K16)) | F16: =IF($K16="","",INDEX(מלאי!$AA$2:$AA$500,$K16)) | G16: =IF($K16="","",INDEX(מלאי!$F$2:$F$500,$K16)) | H16: =IF($K16="","",INDEX(מלאי!$AB$2:$AB$500,$K16)) | I16: =IF($K16="","",IF(AND(INDEX(מלאי!$AB$2:$AB$500,$K16)<>"",INDEX(מלאי!$AB$2:$AB$500,$K16)<TODAY()),"באיחור!","תקין")) | J16: =IF($K16="","",INDEX(מלאי!$AC$2:$AC$500,$K16)) | K16: =IFERROR(SMALL(IF((מלאי!$X$2:$X$500="מושאל")*(IF($A$2="",1,מלאי!$Z$2:$Z$500=$A$2))*(IF($B$2="",1,מלאי!$Y$2:$Y$500=$B$2))*(IF($C$2="",1,מלאי!$AA$2:$AA$500=$C$2))*(IF($D$2="",1,IF($D$2="כן",(מלאי!$AB$2:$AB$500<>"")*(מלאי!$AB$2:$AB$500<TODAY()),1-(מלאי!$AB$2:$AB$500<>"")*(מלאי!$AB$2:$AB$500<TODAY())))),ROW(מלאי!$A$2:$A$500)-ROW(מלאי!$A$2)+1,""),12),"")
A17: =IF($K17="","",INDEX(מלאי!$D$2:$D$500,$K17)) | B17: =IF($K17="","",INDEX(מלאי!$B$2:$B$500,$K17)) | C17: =IF($K17="","",INDEX(מלאי!$C$2:$C$500,$K17)) | D17: =IF($K17="","",INDEX(מלאי!$Y$2:$Y$500,$K17)) | E17: =IF($K17="","",INDEX(מלאי!$Z$2:$Z$500,$K17)) | F17: =IF($K17="","",INDEX(מלאי!$AA$2:$AA$500,$K17)) | G17: =IF($K17="","",INDEX(מלאי!$F$2:$F$500,$K17)) | H17: =IF($K17="","",INDEX(מלאי!$AB$2:$AB$500,$K17)) | I17: =IF($K17="","",IF(AND(INDEX(מלאי!$AB$2:$AB$500,$K17)<>"",INDEX(מלאי!$AB$2:$AB$500,$K17)<TODAY()),"באיחור!","תקין")) | J17: =IF($K17="","",INDEX(מלאי!$AC$2:$AC$500,$K17)) | K17: =IFERROR(SMALL(IF((מלאי!$X$2:$X$500="מושאל")*(IF($A$2="",1,מלאי!$Z$2:$Z$500=$A$2))*(IF($B$2="",1,מלאי!$Y$2:$Y$500=$B$2))*(IF($C$2="",1,מלאי!$AA$2:$AA$500=$C$2))*(IF($D$2="",1,IF($D$2="כן",(מלאי!$AB$2:$AB$500<>"")*(מלאי!$AB$2:$AB$500<TODAY()),1-(מלאי!$AB$2:$AB$500<>"")*(מלאי!$AB$2:$AB$500<TODAY())))),ROW(מלאי!$A$2:$A$500)-ROW(מלאי!$A$2)+1,""),13),"")
A18: =IF($K18="","",INDEX(מלאי!$D$2:$D$500,$K18)) | B18: =IF($K18="","",INDEX(מלאי!$B$2:$B$500,$K18)) | C18: =IF($K18="","",INDEX(מלאי!$C$2:$C$500,$K18)) | D18: =IF($K18="","",INDEX(מלאי!$Y$2:$Y$500,$K18)) | E18: =IF($K18="","",INDEX(מלאי!$Z$2:$Z$500,$K18)) | F18: =IF($K18="","",INDEX(מלאי!$AA$2:$AA$500,$K18)) | G18: =IF($K18="","",INDEX(מלאי!$F$2:$F$500,$K18)) | H18: =IF($K18="","",INDEX(מלאי!$AB$2:$AB$500,$K18)) | I18: =IF($K18="","",IF(AND(INDEX(מלאי!$AB$2:$AB$500,$K18)<>"",INDEX(מלאי!$AB$2:$AB$500,$K18)<TODAY()),"באיחור!","תקין")) | J18: =IF($K18="","",INDEX(מלאי!$AC$2:$AC$500,$K18)) | K18: =IFERROR(SMALL(IF((מלאי!$X$2:$X$500="מושאל")*(IF($A$2="",1,מלאי!$Z$2:$Z$500=$A$2))*(IF($B$2="",1,מלאי!$Y$2:$Y$500=$B$2))*(IF($C$2="",1,מלאי!$AA$2:$AA$500=$C$2))*(IF($D$2="",1,IF($D$2="כן",(מלאי!$AB$2:$AB$500<>"")*(מלאי!$AB$2:$AB$500<TODAY()),1-(מלאי!$AB$2:$AB$500<>"")*(מלאי!$AB$2:$AB$500<TODAY())))),ROW(מלאי!$A$2:$A$500)-ROW(מלאי!$A$2)+1,""),14),"")
A19: =IF($K19="","",INDEX(מלאי!$D$2:$D$500,$K19)) | B19: =IF($K19="","",INDEX(מלאי!$B$2:$B$500,$K19)) | C19: =IF($K19="","",INDEX(מלאי!$C$2:$C$500,$K19)) | D19: =IF($K19="","",INDEX(מלאי!$Y$2:$Y$500,$K19)) | E19: =IF($K19="","",INDEX(מלאי!$Z$2:$Z$500,$K19)) | F19: =IF($K19="","",INDEX(מלאי!$AA$2:$AA$500,$K19)) | G19: =IF($K19="","",INDEX(מלאי!$F$2:$F$500,$K19)) | H19: =IF($K19="","",INDEX(מלאי!$AB$2:$AB$500,$K19)) | I19: =IF($K19="","",IF(AND(INDEX(מלאי!$AB$2:$AB$500,$K19)<>"",INDEX(מלאי!$AB$2:$AB$500,$K19)<TODAY()),"באיחור!","תקין")) | J19: =IF($K19="","",INDEX(מלאי!$AC$2:$AC$500,$K19)) | K19: =IFERROR(SMALL(IF((מלאי!$X$2:$X$500="מושאל")*(IF($A$2="",1,מלאי!$Z$2:$Z$500=$A$2))*(IF($B$2="",1,מלאי!$Y$2:$Y$500=$B$2))*(IF($C$2="",1,מלאי!$AA$2:$AA$500=$C$2))*(IF($D$2="",1,IF($D$2="כן",(מלאי!$AB$2:$AB$500<>"")*(מלאי!$AB$2:$AB$500<TODAY()),1-(מלאי!$AB$2:$AB$500<>"")*(מלאי!$AB$2:$AB$500<TODAY())))),ROW(מלאי!$A$2:$A$500)-ROW(מלאי!$A$2)+1,""),15),"")
A20: =IF($K20="","",INDEX(מלאי!$D$2:$D$500,$K20)) | B20: =IF($K20="","",INDEX(מלאי!$B$2:$B$500,$K20)) | C20: =IF($K20="","",INDEX(מלאי!$C$2:$C$500,$K20)) | D20: =IF($K20="","",INDEX(מלאי!$Y$2:$Y$500,$K20)) | E20: =IF($K20="","",INDEX(מלאי!$Z$2:$Z$500,$K20)) | F20: =IF($K20="","",INDEX(מלאי!$AA$2:$AA$500,$K20)) | G20: =IF($K20="","",INDEX(מלאי!$F$2:$F$500,$K20)) | H20: =IF($K20="","",INDEX(מלאי!$AB$2:$AB$500,$K20)) | I20: =IF($K20="","",IF(AND(INDEX(מלאי!$AB$2:$AB$500,$K20)<>"",INDEX(מלאי!$AB$2:$AB$500,$K20)<TODAY()),"באיחור!","תקין")) | J20: =IF($K20="","",INDEX(מלאי!$AC$2:$AC$500,$K20)) | K20: =IFERROR(SMALL(IF((מלאי!$X$2:$X$500="מושאל")*(IF($A$2="",1,מלאי!$Z$2:$Z$500=$A$2))*(IF($B$2="",1,מלאי!$Y$2:$Y$500=$B$2))*(IF($C$2="",1,מלאי!$AA$2:$AA$500=$C$2))*(IF($D$2="",1,IF($D$2="כן",(מלאי!$AB$2:$AB$500<>"")*(מלאי!$AB$2:$AB$500<TODAY()),1-(מלאי!$AB$2:$AB$500<>"")*(מלאי!$AB$2:$AB$500<TODAY())))),ROW(מלאי!$A$2:$A$500)-ROW(מלאי!$A$2)+1,""),16),"")
