Workbook

Sheet מלאי
A1: זיהוי מוצר | C1: פרטים | F1: בד | H1: הדפסים | J1: תקינות ומאפיינים | T1: סטטוס | U1: הערות | V1: השאלה
A2: קו מוצר | B2: שם מוצר | C2: גרסה | D2: מזהה ייחודי | E2: מק"ט (אוטומטי) | F2: סוג בד 1 | G2: סוג בד 2 | H2: הדפס צד א' | I2: הדפס צד ב' | J2: תקין ויזואלית א' | K2: תקין ויזואלית ב' | L2: תקין תרמית A' | M2: תקין תרמית ב' | N2: פיצ'רים תקינים | O2: גרסה סופית | P2: הערות גרסה/פיצ'רים | Q2: גרסה מיוחדת(פיתוח) | R2: מידה | S2: פער בתכולה | T2: סטטוס | U2: הערות | V2: מושאל ל | W2: מדינה | X2: אחראי מהחברה | Y2: החזרה משוערת | Z2: סביבה A' | AA2: סביבה משנית A' | AB2: סביבה ב' | AC2: סביבה משנית ב' | AD2: מסנן בקרה | AE2: מסנן טכנו
A3: Blankets | B3: 3D Survival Blanket | C3: V1 | D3: יריעה 3D הדגמה 1 | E3: =IFERROR(INDEX(הגדרות!$I$2:$I$47,MATCH(B3,הגדרות!$H$2:$H$47,0)),"") -> 9029-00 | F3: Mesh | G3: 3D | H3: Ever-Green | I3: Kestrel | J3: כן | K3: כן | L3: כן | M3: כן | O3: כן | Q3: לא | S3: לא | T3: במלאי | Z3: =IFERROR(INDEX(הגדרות!$B$2:$B$17,MATCH(H3,הגדרות!$A$2:$A$17,0)),"") -> מיוער | AA3: =IFERROR(INDEX(הגדרות!$C$2:$C$17,MATCH(H3,הגדרות!$A$2:$A$17,0)),"") -> 0 | AB3: =IFERROR(INDEX(הגדרות!$B$2:$B$17,MATCH(I3,הגדרות!$A$2:$A$17,0)),"") -> מיוער | AC3: =IFERROR(INDEX(הגדרות!$C$2:$C$17,MATCH(I3,הגדרות!$A$2:$A$17,0)),"") -> 0 | AD3: =IF(AND(מלאי!D58<>"",OR(#REF!="הכל",מלאי!Z58=#REF!,מלאי!AA58=#REF!,מלאי!AB58=#REF!,מלאי!AC58=#REF!),OR(#REF!="הכל",מלאי!A58=#REF!),OR(#REF!="הכל",מלאי!B58=#REF!),OR(#REF!="הכל",מלאי!F58=#REF!,מלאי!G58=#REF!),OR(#REF!="הכל",מלאי!T58=#REF!),OR(#REF!="הכל",מלאי!Q58=#REF!),OR(#REF!="הכל",מלאי!J58=#REF!),OR(#REF!="הכל",מלאי!L58=#REF!),OR(#REF!="הכל",מלאי!O58=#REF!),OR(#REF!="הכל",מלאי!R58=#REF!),OR(#REF!="הכל",#REF!="",מלאי!W58=#REF!),OR(#REF!="הכל",#REF!="",ISNUMBER(SEARCH(#REF!,מלאי!C58)))),1,0) -> #REF! | AE3: =IF(AND(מלאי!D58<>"",OR(#REF!="הכל",מלאי!Z58=#REF!,מלאי!AA58=#REF!,מלאי!AB58=#REF!,מלאי!AC58=#REF!),OR(#REF!="הכל",מלאי!A58=#REF!),OR(#REF!="הכל",מלאי!B58=#REF!),OR(#REF!="הכל",מלאי!F58=#REF!,מלאי!G58=#REF!),OR(#REF!="הכל",מלאי!T58=#REF!),OR(#REF!="הכל",מלאי!Q58=#REF!),OR(#REF!="הכל",מלאי!J58=#REF!),OR(#REF!="הכל",מלאי!L58=#REF!),OR(#REF!="הכל",מלאי!O58=#REF!),OR(#REF!="הכל",מלאי!R58=#REF!),OR(#REF!="הכל",#REF!="",מלאי!W58=#REF!),OR(#REF!="הכל",#REF!="",ISNUMBER(SEARCH(#REF!,מלאי!C58))),OR(#REF!="הכל",מלאי!#REF!=#REF!)),1,0) -> #REF! | AF3: =IF(AD3=1,COUNTIF($AD$3:$AD3,1),"") -> #REF! | AG3: =IF(AE3=1,COUNTIF($AE$3:$AE3,1),"") -> #REF!
A4: Blankets | B4: 3D Survival Blanket | C4: V1 | D4: יריעה 3D תצוגה 2 | E4: =IFERROR(INDEX(הגדרות!$I$2:$I$47,MATCH(B4,הגדרות!$H$2:$H$47,0)),"") -> 9029-00 | F4: Mesh | G4: 3D | H4: Ever-Green | I4: Kestrel | J4: כן | K4: כן | L4: כן | M4: כן | O4: כן | Q4: לא | S4: לא | T4: במלאי | Z4: =IFERROR(INDEX(הגדרות!$B$2:$B$17,MATCH(H4,הגדרות!$A$2:$A$17,0)),"") -> מיוער | AA4: =IFERROR(INDEX(הגדרות!$C$2:$C$17,MATCH(H4,הגדרות!$A$2:$A$17,0)),"") -> 0 | AB4: =IFERROR(INDEX(הגדרות!$B$2:$B$17,MATCH(I4,הגדרות!$A$2:$A$17,0)),"") -> מיוער | AC4: =IFERROR(INDEX(הגדרות!$C$2:$C$17,MATCH(I4,הגדרות!$A$2:$A$17,0)),"") -> 0 | AD4: =IF(AND(מלאי!D59<>"",OR(#REF!="הכל",מלאי!Z59=#REF!,מלאי!AA59=#REF!,מלאי!AB59=#REF!,מלאי!AC59=#REF!),OR(#REF!="הכל",מלאי!A59=#REF!),OR(#REF!="הכל",מלאי!B59=#REF!),OR(#REF!="הכל",מלאי!F59=#REF!,מלאי!G59=#REF!),OR(#REF!="הכל",מלאי!T59=#REF!),OR(#REF!="הכל",מלאי!Q59=#REF!),OR(#REF!="הכל",מלאי!J59=#REF!),OR(#REF!="הכל",מלאי!L59=#REF!),OR(#REF!="הכל",מלאי!O59=#REF!),OR(#REF!="הכל",מלאי!R59=#REF!),OR(#REF!="הכל",#REF!="",מלאי!W59=#REF!),OR(#REF!="הכל",#REF!="",ISNUMBER(SEARCH(#REF!,מלאי!C59)))),1,0) -> #REF! | AE4: =IF(AND(מלאי!D59<>"",OR(#REF!="הכל",מלאי!Z59=#REF!,מלאי!AA59=#REF!,מלאי!AB59=#REF!,מלאי!AC59=#REF!),OR(#REF!="הכל",מלאי!A59=#REF!),OR(#REF!="הכל",מלאי!B59=#REF!),OR(#REF!="הכל",מלאי!F59=#REF!,מלאי!G59=#REF!),OR(#REF!="הכל",מלאי!T59=#REF!),OR(#REF!="הכל",מלאי!Q59=#REF!),OR(#REF!="הכל",מלאי!J59=#REF!),OR(#REF!="הכל",מלאי!L59=#REF!),OR(#REF!="הכל",מלאי!O59=#REF!),OR(#REF!="הכל",מלאי!R59=#REF!),OR(#REF!="הכל",#REF!="",מלאי!W59=#REF!),OR(#REF!="הכל",#REF!="",ISNUMBER(SEARCH(#REF!,מלאי!C59))),OR(#REF!="הכל",מלאי!#REF!=#REF!)),1,0) -> #REF! | AF4: =IF(AD4=1,COUNTIF($AD$3:$AD4,1),"") -> #REF! | AG4: =IF(AE4=1,COUNTIF($AE$3:$AE4,1),"") -> #REF!
A5: Hide Site | B5: 6X6 Hide Site | C5: V1 | E5: =IFERROR(INDEX(הגדרות!$I$2:$I$47,MATCH(B5,הגדרות!$H$2:$H$47,0)),"") -> 9095-00 | F5: MRG | H5: Ever-Green | I5: Desert | J5: כן | K5: כן | L5: כן | M5: כן | O5: לא | Q5: כן | T5: במלאי | U5: הזמנה מיוחדת | Z5: =IFERROR(INDEX(הגדרות!$B$2:$B$17,MATCH(H5,הגדרות!$A$2:$A$17,0)),"") -> מיוער | AA5: =IFERROR(INDEX(הגדרות!$C$2:$C$17,MATCH(H5,הגדרות!$A$2:$A$17,0)),"") -> 0 | AB5: =IFERROR(INDEX(הגדרות!$B$2:$B$17,MATCH(I5,הגדרות!$A$2:$A$17,0)),"") -> מדברי | AC5: =IFERROR(INDEX(הגדרות!$C$2:$C$17,MATCH(I5,הגדרות!$A$2:$A$17,0)),"") -> 0 | AD5: =IF(AND(מלאי!D127<>"",OR(#REF!="הכל",מלאי!Z127=#REF!,מלאי!AA127=#REF!,מלאי!AB127=#REF!,מלאי!AC127=#REF!),OR(#REF!="הכל",מלאי!A127=#REF!),OR(#REF!="הכל",מלאי!B127=#REF!),OR(#REF!="הכל",מלאי!F127=#REF!,מלאי!G127=#REF!),OR(#REF!="הכל",מלאי!T127=#REF!),OR(#REF!="הכל",מלאי!Q127=#REF!),OR(#REF!="הכל",מלאי!J127=#REF!),OR(#REF!="הכל",מלאי!L127=#REF!),OR(#REF!="הכל",מלאי!O127=#REF!),OR(#REF!="הכל",מלאי!R127=#REF!),OR(#REF!="הכל",#REF!="",מלאי!W127=#REF!),OR(#REF!="הכל",#REF!="",ISNUMBER(SEARCH(#REF!,מלאי!C127)))),1,0) -> #REF! | AE5: =IF(AND(מלאי!D127<>"",OR(#REF!="הכל",מלאי!Z127=#REF!,מלאי!AA127=#REF!,מלאי!AB127=#REF!,מלאי!AC127=#REF!),OR(#REF!="הכל",מלאי!A127=#REF!),OR(#REF!="הכל",מלאי!B127=#REF!),OR(#REF!="הכל",מלאי!F127=#REF!,מלאי!G127=#REF!),OR(#REF!="הכל",מלאי!T127=#REF!),OR(#REF!="הכל",מלאי!Q127=#REF!),OR(#REF!="הכל",מלאי!J127=#REF!),OR(#REF!="הכל",מלאי!L127=#REF!),OR(#REF!="הכל",מלאי!O127=#REF!),OR(#REF!="הכל",מלאי!R127=#REF!),OR(#REF!="הכל",#REF!="",מלאי!W127=#REF!),OR(#REF!="הכל",#REF!="",ISNUMBER(SEARCH(#REF!,מלאי!C127))),OR(#REF!="הכל",מלאי!#REF!=#REF!)),1,0) -> #REF! | AF5: =IF(AD5=1,COUNTIF($AD$3:$AD5,1),"") -> #REF! | AG5: =IF(AE5=1,COUNTIF($AE$3:$AE5,1),"") -> #REF!
A6: Hide Site | B6: 6X6 Hide Site | C6: V1 | E6: =IFERROR(INDEX(הגדרות!$I$2:$I$47,MATCH(B6,הגדרות!$H$2:$H$47,0)),"") -> 9095-00 | F6: Beti | H6: Ever-Green | I6: Desert | J6: כן | K6: כן | L6: כן | M6: כן | O6: לא | Q6: כן | T6: במלאי | U6: הזמנה מיוחדת | Z6: =IFERROR(INDEX(הגדרות!$B$2:$B$17,MATCH(H6,הגדרות!$A$2:$A$17,0)),"") -> מיוער | AA6: =IFERROR(INDEX(הגדרות!$C$2:$C$17,MATCH(H6,הגדרות!$A$2:$A$17,0)),"") -> 0 | AB6: =IFERROR(INDEX(הגדרות!$B$2:$B$17,MATCH(I6,הגדרות!$A$2:$A$17,0)),"") -> מדברי | AC6: =IFERROR(INDEX(הגדרות!$C$2:$C$17,MATCH(I6,הגדרות!$A$2:$A$17,0)),"") -> 0 | AD6: =IF(AND(מלאי!D128<>"",OR(#REF!="הכל",מלאי!Z128=#REF!,מלאי!AA128=#REF!,מלאי!AB128=#REF!,מלאי!AC128=#REF!),OR(#REF!="הכל",מלאי!A128=#REF!),OR(#REF!="הכל",מלאי!B128=#REF!),OR(#REF!="הכל",מלאי!F128=#REF!,מלאי!G128=#REF!),OR(#REF!="הכל",מלאי!T128=#REF!),OR(#REF!="הכל",מלאי!Q128=#REF!),OR(#REF!="הכל",מלאי!J128=#REF!),OR(#REF!="הכל",מלאי!L128=#REF!),OR(#REF!="הכל",מלאי!O128=#REF!),OR(#REF!="הכל",מלאי!R128=#REF!),OR(#REF!="הכל",#REF!="",מלאי!W128=#REF!),OR(#REF!="הכל",#REF!="",ISNUMBER(SEARCH(#REF!,מלאי!C128)))),1,0) -> #REF! | AE6: =IF(AND(מלאי!D128<>"",OR(#REF!="הכל",מלאי!Z128=#REF!,מלאי!AA128=#REF!,מלאי!AB128=#REF!,מלאי!AC128=#REF!),OR(#REF!="הכל",מלאי!A128=#REF!),OR(#REF!="הכל",מלאי!B128=#REF!),OR(#REF!="הכל",מלאי!F128=#REF!,מלאי!G128=#REF!),OR(#REF!="הכל",מלאי!T128=#REF!),OR(#REF!="הכל",מלאי!Q128=#REF!),OR(#REF!="הכל",מלאי!J128=#REF!),OR(#REF!="הכל",מלאי!L128=#REF!),OR(#REF!="הכל",מלאי!O128=#REF!),OR(#REF!="הכל",מלאי!R128=#REF!),OR(#REF!="הכל",#REF!="",מלאי!W128=#REF!),OR(#REF!="הכל",#REF!="",ISNUMBER(SEARCH(#REF!,מלאי!C128))),OR(#REF!="הכל",מלאי!#REF!=#REF!)),1,0) -> #REF! | AF6: =IF(AD6=1,COUNTIF($AD$3:$AD6,1),"") -> #REF! | AG6: =IF(AE6=1,COUNTIF($AE$3:$AE6,1),"") -> #REF!
A7: OverGarment | B7: Arctic Jacket | C7: V1 | D7: Arctic Jacket Fresh 1 | E7: =IFERROR(INDEX(הגדרות!$I$2:$I$47,MATCH(B7,הגדרות!$H$2:$H$47,0)),"") -> 7051-00 | F7: RIPSTOP Double Layer | H7: Fresh Snow | J7: כן | K7: כן | L7: כן | M7: כן | N7: לא | P7: אקססוריז לא בלבן | T7: במלאי | Z7: =IFERROR(INDEX(הגדרות!$B$2:$B$17,MATCH(H7,הגדרות!$A$2:$A$17,0)),"") -> שלג | AA7: =IFERROR(INDEX(הגדרות!$C$2:$C$17,MATCH(H7,הגדרות!$A$2:$A$17,0)),"") -> 0 | AB7: =IFERROR(INDEX(הגדרות!$B$2:$B$17,MATCH(I7,הגדרות!$A$2:$A$17,0)),"") | AC7: =IFERROR(INDEX(הגדרות!$C$2:$C$17,MATCH(I7,הגדרות!$A$2:$A$17,0)),"") | AD7: =IF(AND(מלאי!D96<>"",OR(#REF!="הכל",מלאי!Z96=#REF!,מלאי!AA96=#REF!,מלאי!AB96=#REF!,מלאי!AC96=#REF!),OR(#REF!="הכל",מלאי!A96=#REF!),OR(#REF!="הכל",מלאי!B96=#REF!),OR(#REF!="הכל",מלאי!F96=#REF!,מלאי!G96=#REF!),OR(#REF!="הכל",מלאי!T96=#REF!),OR(#REF!="הכל",מלאי!Q96=#REF!),OR(#REF!="הכל",מלאי!J96=#REF!),OR(#REF!="הכל",מלאי!L96=#REF!),OR(#REF!="הכל",מלאי!O96=#REF!),OR(#REF!="הכל",מלאי!R96=#REF!),OR(#REF!="הכל",#REF!="",מלאי!W96=#REF!),OR(#REF!="הכל",#REF!="",ISNUMBER(SEARCH(#REF!,מלאי!C96)))),1,0) -> #REF! | AE7: =IF(AND(מלאי!D96<>"",OR(#REF!="הכל",מלאי!Z96=#REF!,מלאי!AA96=#REF!,מלאי!AB96=#REF!,מלאי!AC96=#REF!),OR(#REF!="הכל",מלאי!A96=#REF!),OR(#REF!="הכל",מלאי!B96=#REF!),OR(#REF!="הכל",מלאי!F96=#REF!,מלאי!G96=#REF!),OR(#REF!="הכל",מלאי!T96=#REF!),OR(#REF!="הכל",מלאי!Q96=#REF!),OR(#REF!="הכל",מלאי!J96=#REF!),OR(#REF!="הכל",מלאי!L96=#REF!),OR(#REF!="הכל",מלאי!O96=#REF!),OR(#REF!="הכל",מלאי!R96=#REF!),OR(#REF!="הכל",#REF!="",מלאי!W96=#REF!),OR(#REF!="הכל",#REF!="",ISNUMBER(SEARCH(#REF!,מלאי!C96))),OR(#REF!="הכל",מלאי!#REF!=#REF!)),1,0) -> #REF! | AF7: =IF(AD7=1,COUNTIF($AD$3:$AD7,1),"") -> #REF! | AG7: =IF(AE7=1,COUNTIF($AE$3:$AE7,1),"") -> #REF!
A8: OverGarment | B8: Arctic Jacket | C8: V1 | D8: Arctic Suit Top Fresh 1 | E8: =IFERROR(INDEX(הגדרות!$I$2:$I$47,MATCH(B8,הגדרות!$H$2:$H$47,0)),"") -> 7051-00 | F8: RIPSTOP Double Layer | H8: Fresh Snow | J8: כן | K8: כן | L8: כן | M8: כן | N8: כן | T8: במלאי | Z8: =IFERROR(INDEX(הגדרות!$B$2:$B$17,MATCH(H8,הגדרות!$A$2:$A$17,0)),"") -> שלג | AA8: =IFERROR(INDEX(הגדרות!$C$2:$C$17,MATCH(H8,הגדרות!$A$2:$A$17,0)),"") -> 0 | AB8: =IFERROR(INDEX(הגדרות!$B$2:$B$17,MATCH(I8,הגדרות!$A$2:$A$17,0)),"") | AC8: =IFERROR(INDEX(הגדרות!$C$2:$C$17,MATCH(I8,הגדרות!$A$2:$A$17,0)),"") | AD8: =IF(AND(מלאי!D97<>"",OR(#REF!="הכל",מלאי!Z97=#REF!,מלאי!AA97=#REF!,מלאי!AB97=#REF!,מלאי!AC97=#REF!),OR(#REF!="הכל",מלאי!A97=#REF!),OR(#REF!="הכל",מלאי!B97=#REF!),OR(#REF!="הכל",מלאי!F97=#REF!,מלאי!G97=#REF!),OR(#REF!="הכל",מלאי!T97=#REF!),OR(#REF!="הכל",מלאי!Q97=#REF!),OR(#REF!="הכל",מלאי!J97=#REF!),OR(#REF!="הכל",מלאי!L97=#REF!),OR(#REF!="הכל",מלאי!O97=#REF!),OR(#REF!="הכל",מלאי!R97=#REF!),OR(#REF!="הכל",#REF!="",מלאי!W97=#REF!),OR(#REF!="הכל",#REF!="",ISNUMBER(SEARCH(#REF!,מלאי!C97)))),1,0) -> #REF! | AE8: =IF(AND(מלאי!D97<>"",OR(#REF!="הכל",מלאי!Z97=#REF!,מלאי!AA97=#REF!,מלאי!AB97=#REF!,מלאי!AC97=#REF!),OR(#REF!="הכל",מלאי!A97=#REF!),OR(#REF!="הכל",מלאי!B97=#REF!),OR(#REF!="הכל",מלאי!F97=#REF!,מלאי!G97=#REF!),OR(#REF!="הכל",מלאי!T97=#REF!),OR(#REF!="הכל",מלאי!Q97=#REF!),OR(#REF!="הכל",מלאי!J97=#REF!),OR(#REF!="הכל",מלאי!L97=#REF!),OR(#REF!="הכל",מלאי!O97=#REF!),OR(#REF!="הכל",מלאי!R97=#REF!),OR(#REF!="הכל",#REF!="",מלאי!W97=#REF!),OR(#REF!="הכל",#REF!="",ISNUMBER(SEARCH(#REF!,מלאי!C97))),OR(#REF!="הכל",מלאי!#REF!=#REF!)),1,0) -> #REF! | AF8: =IF(AD8=1,COUNTIF($AD$3:$AD8,1),"") -> #REF! | AG8: =IF(AE8=1,COUNTIF($AE$3:$AE8,1),"") -> #REF!
A9: OverGarment | B9: Arctic Jacket | C9: V1 | D9: Arctic Suit Bot Fresh 1 | E9: =IFERROR(INDEX(הגדרות!$I$2:$I$47,MATCH(B9,הגדרות!$H$2:$H$47,0)),"") -> 7051-00 | F9: RIPSTOP Double Layer | H9: Fresh Snow | J9: כן | K9: כן | L9: כן | M9: כן | N9: כן | T9: במלאי | Z9: =IFERROR(INDEX(הגדרות!$B$2:$B$17,MATCH(H9,הגדרות!$A$2:$A$17,0)),"") -> שלג | AA9: =IFERROR(INDEX(הגדרות!$C$2:$C$17,MATCH(H9,הגדרות!$A$2:$A$17,0)),"") -> 0 | AB9: =IFERROR(INDEX(הגדרות!$B$2:$B$17,MATCH(I9,הגדרות!$A$2:$A$17,0)),"") | AC9: =IFERROR(INDEX(הגדרות!$C$2:$C$17,MATCH(I9,הגדרות!$A$2:$A$17,0)),"") | AD9: =IF(AND(מלאי!D98<>"",OR(#REF!="הכל",מלאי!Z98=#REF!,מלאי!AA98=#REF!,מלאי!AB98=#REF!,מלאי!AC98=#REF!),OR(#REF!="הכל",מלאי!A98=#REF!),OR(#REF!="הכל",מלאי!B98=#REF!),OR(#REF!="הכל",מלאי!F98=#REF!,מלאי!G98=#REF!),OR(#REF!="הכל",מלאי!T98=#REF!),OR(#REF!="הכל",מלאי!Q98=#REF!),OR(#REF!="הכל",מלאי!J98=#REF!),OR(#REF!="הכל",מלאי!L98=#REF!),OR(#REF!="הכל",מלאי!O98=#REF!),OR(#REF!="הכל",מלאי!R98=#REF!),OR(#REF!="הכל",#REF!="",מלאי!W98=#REF!),OR(#REF!="הכל",#REF!="",ISNUMBER(SEARCH(#REF!,מלאי!C98)))),1,0) -> #REF! | AE9: =IF(AND(מלאי!D98<>"",OR(#REF!="הכל",מלאי!Z98=#REF!,מלאי!AA98=#REF!,מלאי!AB98=#REF!,מלאי!AC98=#REF!),OR(#REF!="הכל",מלאי!A98=#REF!),OR(#REF!="הכל",מלאי!B98=#REF!),OR(#REF!="הכל",מלאי!F98=#REF!,מלאי!G98=#REF!),OR(#REF!="הכל",מלאי!T98=#REF!),OR(#REF!="הכל",מלאי!Q98=#REF!),OR(#REF!="הכל",מלאי!J98=#REF!),OR(#REF!="הכל",מלאי!L98=#REF!),OR(#REF!="הכל",מלאי!O98=#REF!),OR(#REF!="הכל",מלאי!R98=#REF!),OR(#REF!="הכל",#REF!="",מלאי!W98=#REF!),OR(#REF!="הכל",#REF!="",ISNUMBER(SEARCH(#REF!,מלאי!C98))),OR(#REF!="הכל",מלאי!#REF!=#REF!)),1,0) -> #REF! | AF9: =IF(AD9=1,COUNTIF($AD$3:$AD9,1),"") -> #REF! | AG9: =IF(AE9=1,COUNTIF($AE$3:$AE9,1),"") -> #REF!
A10: OverGarment | B10: Arctic Jacket | C10: V1 | D10: Arctic Jacket Snirt 1 | E10: =IFERROR(INDEX(הגדרות!$I$2:$I$47,MATCH(B10,הגדרות!$H$2:$H$47,0)),"") -> 7051-00 | F10: RIPSTOP Double Layer | H10: Snirt Snow | J10: כן | K10: כן | L10: כן | M10: כן | N10: כן | T10: במלאי | Z10: =IFERROR(INDEX(הגדרות!$B$2:$B$17,MATCH(H10,הגדרות!$A$2:$A$17,0)),"") -> שלג | AA10: =IFERROR(INDEX(הגדרות!$C$2:$C$17,MATCH(H10,הגדרות!$A$2:$A$17,0)),"") -> 0 | AB10: =IFERROR(INDEX(הגדרות!$B$2:$B$17,MATCH(I10,הגדרות!$A$2:$A$17,0)),"") | AC10: =IFERROR(INDEX(הגדרות!$C$2:$C$17,MATCH(I10,הגדרות!$A$2:$A$17,0)),"") | AD10: =IF(AND(מלאי!D93<>"",OR(#REF!="הכל",מלאי!Z99=#REF!,מלאי!AA99=#REF!,מלאי!AB99=#REF!,מלאי!AC99=#REF!),OR(#REF!="הכל",מלאי!A99=#REF!),OR(#REF!="הכל",מלאי!B99=#REF!),OR(#REF!="הכל",מלאי!F99=#REF!,מלאי!G99=#REF!),OR(#REF!="הכל",מלאי!T99=#REF!),OR(#REF!="הכל",מלאי!Q99=#REF!),OR(#REF!="הכל",מלאי!J99=#REF!),OR(#REF!="הכל",מלאי!L99=#REF!),OR(#REF!="הכל",מלאי!O99=#REF!),OR(#REF!="הכל",מלאי!R99=#REF!),OR(#REF!="הכל",#REF!="",מלאי!W99=#REF!),OR(#REF!="הכל",#REF!="",ISNUMBER(SEARCH(#REF!,מלאי!C99)))),1,0) -> #REF! | AE10: =IF(AND(מלאי!D93<>"",OR(#REF!="הכל",מלאי!Z99=#REF!,מלאי!AA99=#REF!,מלאי!AB99=#REF!,מלאי!AC99=#REF!),OR(#REF!="הכל",מלאי!A99=#REF!),OR(#REF!="הכל",מלאי!B99=#REF!),OR(#REF!="הכל",מלאי!F99=#REF!,מלאי!G99=#REF!),OR(#REF!="הכל",מלאי!T99=#REF!),OR(#REF!="הכל",מלאי!Q99=#REF!),OR(#REF!="הכל",מלאי!J99=#REF!),OR(#REF!="הכל",מלאי!L99=#REF!),OR(#REF!="הכל",מלאי!O99=#REF!),OR(#REF!="הכל",מלאי!R99=#REF!),OR(#REF!="הכל",#REF!="",מלאי!W99=#REF!),OR(#REF!="הכל",#REF!="",ISNUMBER(SEARCH(#REF!,מלאי!C99))),OR(#REF!="הכל",מלאי!#REF!=#REF!)),1,0) -> #REF! | AF10: =IF(AD10=1,COUNTIF($AD$3:$AD10,1),"") -> #REF! | AG10: =IF(AE10=1,COUNTIF($AE$3:$AE10,1),"") -> #REF!
A11: OverGarment | B11: Arctic Jacket | C11: V1 | D11: Arctic Jacket Snirt 2 | E11: =IFERROR(INDEX(הגדרות!$I$2:$I$47,MATCH(B11,הגדרות!$H$2:$H$47,0)),"") -> 7051-00 | F11: RIPSTOP Double Layer | H11: Snirt Snow | J11: כן | K11: כן | L11: כן | M11: כן | N11: לא | P11: אקססוריז לא בלבן | T11: במלאי | Z11: =IFERROR(INDEX(הגדרות!$B$2:$B$17,MATCH(H11,הגדרות!$A$2:$A$17,0)),"") -> שלג | AA11: =IFERROR(INDEX(הגדרות!$C$2:$C$17,MATCH(H11,הגדרות!$A$2:$A$17,0)),"") -> 0 | AB11: =IFERROR(INDEX(הגדרות!$B$2:$B$17,MATCH(I11,הגדרות!$A$2:$A$17,0)),"") | AC11: =IFERROR(INDEX(הגדרות!$C$2:$C$17,MATCH(I11,הגדרות!$A$2:$A$17,0)),"") | AD11: =IF(AND(מלאי!D100<>"",OR(#REF!="הכל",מלאי!Z100=#REF!,מלאי!AA100=#REF!,מלאי!AB100=#REF!,מלאי!AC100=#REF!),OR(#REF!="הכל",מלאי!A100=#REF!),OR(#REF!="הכל",מלאי!B100=#REF!),OR(#REF!="הכל",מלאי!F100=#REF!,מלאי!G100=#REF!),OR(#REF!="הכל",מלאי!T100=#REF!),OR(#REF!="הכל",מלאי!Q100=#REF!),OR(#REF!="הכל",מלאי!J100=#REF!),OR(#REF!="הכל",מלאי!L100=#REF!),OR(#REF!="הכל",מלאי!O100=#REF!),OR(#REF!="הכל",מלאי!R100=#REF!),OR(#REF!="הכל",#REF!="",מלאי!W100=#REF!),OR(#REF!="הכל",#REF!="",ISNUMBER(SEARCH(#REF!,מלאי!C100)))),1,0) -> #REF! | AE11: =IF(AND(מלאי!D100<>"",OR(#REF!="הכל",מלאי!Z100=#REF!,מלאי!AA100=#REF!,מלאי!AB100=#REF!,מלאי!AC100=#REF!),OR(#REF!="הכל",מלאי!A100=#REF!),OR(#REF!="הכל",מלאי!B100=#REF!),OR(#REF!="הכל",מלאי!F100=#REF!,מלאי!G100=#REF!),OR(#REF!="הכל",מלאי!T100=#REF!),OR(#REF!="הכל",מלאי!Q100=#REF!),OR(#REF!="הכל",מלאי!J100=#REF!),OR(#REF!="הכל",מלאי!L100=#REF!),OR(#REF!="הכל",מלאי!O100=#REF!),OR(#REF!="הכל",מלאי!R100=#REF!),OR(#REF!="הכל",#REF!="",מלאי!W100=#REF!),OR(#REF!="הכל",#REF!="",ISNUMBER(SEARCH(#REF!,מלאי!C100))),OR(#REF!="הכל",מלאי!#REF!=#REF!)),1,0) -> #REF! | AF11: =IF(AD11=1,COUNTIF($AD$3:$AD11,1),"") -> #REF! | AG11: =IF(AE11=1,COUNTIF($AE$3:$AE11,1),"") -> #REF!
A12: OverGarment | B12: Arctic Jacket | C12: V1 | D12: Arctic Jacket sampels Snirt | E12: =IFERROR(INDEX(הגדרות!$I$2:$I$47,MATCH(B12,הגדרות!$H$2:$H$47,0)),"") -> 7051-00 | F12: RIPSTOP Double Layer | H12: Snirt Snow | J12: כן | K12: כן | L12: כן | M12: כן | N12: כן | T12: במלאי | Z12: =IFERROR(INDEX(הגדרות!$B$2:$B$17,MATCH(H12,הגדרות!$A$2:$A$17,0)),"") -> שלג | AA12: =IFERROR(INDEX(הגדרות!$C$2:$C$17,MATCH(H12,הגדרות!$A$2:$A$17,0)),"") -> 0 | AB12: =IFERROR(INDEX(הגדרות!$B$2:$B$17,MATCH(I12,הגדרות!$A$2:$A$17,0)),"") | AC12: =IFERROR(INDEX(הגדרות!$C$2:$C$17,MATCH(I12,הגדרות!$A$2:$A$17,0)),"") | AD12: =IF(AND(מלאי!D149<>"",OR(#REF!="הכל",מלאי!Z149=#REF!,מלאי!AA149=#REF!,מלאי!AB149=#REF!,מלאי!AC149=#REF!),OR(#REF!="הכל",מלאי!A149=#REF!),OR(#REF!="הכל",מלאי!B149=#REF!),OR(#REF!="הכל",מלאי!F149=#REF!,מלאי!G149=#REF!),OR(#REF!="הכל",מלאי!T149=#REF!),OR(#REF!="הכל",מלאי!Q149=#REF!),OR(#REF!="הכל",מלאי!J149=#REF!),OR(#REF!="הכל",מלאי!L149=#REF!),OR(#REF!="הכל",מלאי!O149=#REF!),OR(#REF!="הכל",מלאי!R149=#REF!),OR(#REF!="הכל",#REF!="",מלאי!W149=#REF!),OR(#REF!="הכל",#REF!="",ISNUMBER(SEARCH(#REF!,מלאי!C149)))),1,0) -> #REF! | AE12: =IF(AND(מלאי!D149<>"",OR(#REF!="הכל",מלאי!Z149=#REF!,מלאי!AA149=#REF!,מלאי!AB149=#REF!,מלאי!AC149=#REF!),OR(#REF!="הכל",מלאי!A149=#REF!),OR(#REF!="הכל",מלאי!B149=#REF!),OR(#REF!="הכל",מלאי!F149=#REF!,מלאי!G149=#REF!),OR(#REF!="הכל",מלאי!T149=#REF!),OR(#REF!="הכל",מלאי!Q149=#REF!),OR(#REF!="הכל",מלאי!J149=#REF!),OR(#REF!="הכל",מלאי!L149=#REF!),OR(#REF!="הכל",מלאי!O149=#REF!),OR(#REF!="הכל",מלאי!R149=#REF!),OR(#REF!="הכל",#REF!="",מלאי!W149=#REF!),OR(#REF!="הכל",#REF!="",ISNUMBER(SEARCH(#REF!,מלאי!C149))),OR(#REF!="הכל",מלאי!#REF!=#REF!)),1,0) -> #REF! | AF12: =IF(AD12=1,COUNTIF($AD$3:$AD12,1),"") -> #REF! | AG12: =IF(AE12=1,COUNTIF($AE$3:$AE12,1),"") -> #REF!
A13: OverGarment | B13: Arctic Jacket | C13: V1 | D13: Arctic Jacket sampels Fresh | E13: =IFERROR(INDEX(הגדרות!$I$2:$I$47,MATCH(B13,הגדרות!$H$2:$H$47,0)),"") -> 7051-00 | F13: RIPSTOP Double Layer | H13: Fresh Snow | J13: כן | K13: כן | L13: כן | M13: כן | N13: כן | T13: במלאי | Z13: =IFERROR(INDEX(הגדרות!$B$2:$B$17,MATCH(H13,הגדרות!$A$2:$A$17,0)),"") -> שלג | AA13: =IFERROR(INDEX(הגדרות!$C$2:$C$17,MATCH(H13,הגדרות!$A$2:$A$17,0)),"") -> 0 | AB13: =IFERROR(INDEX(הגדרות!$B$2:$B$17,MATCH(I13,הגדרות!$A$2:$A$17,0)),"") | AC13: =IFERROR(INDEX(הגדרות!$C$2:$C$17,MATCH(I13,הגדרות!$A$2:$A$17,0)),"") | AD13: =IF(AND(מלאי!D154<>"",OR(#REF!="הכל",מלאי!Z154=#REF!,מלאי!AA154=#REF!,מלאי!AB154=#REF!,מלאי!AC154=#REF!),OR(#REF!="הכל",מלאי!A154=#REF!),OR(#REF!="הכל",מלאי!B154=#REF!),OR(#REF!="הכל",מלאי!F154=#REF!,מלאי!G154=#REF!),OR(#REF!="הכל",מלאי!T154=#REF!),OR(#REF!="הכל",מלאי!Q154=#REF!),OR(#REF!="הכל",מלאי!J154=#REF!),OR(#REF!="הכל",מלאי!L154=#REF!),OR(#REF!="הכל",מלאי!O154=#REF!),OR(#REF!="הכל",מלאי!R154=#REF!),OR(#REF!="הכל",#REF!="",מלאי!W154=#REF!),OR(#REF!="הכל",#REF!="",ISNUMBER(SEARCH(#REF!,מלאי!C154)))),1,0) -> #REF! | AE13: =IF(AND(מלאי!D154<>"",OR(#REF!="הכל",מלאי!Z154=#REF!,מלאי!AA154=#REF!,מלאי!AB154=#REF!,מלאי!AC154=#REF!),OR(#REF!="הכל",מלאי!A154=#REF!),OR(#REF!="הכל",מלאי!B154=#REF!),OR(#REF!="הכל",מלאי!F154=#REF!,מלאי!G154=#REF!),OR(#REF!="הכל",מלאי!T154=#REF!),OR(#REF!="הכל",מלאי!Q154=#REF!),OR(#REF!="הכל",מלאי!J154=#REF!),OR(#REF!="הכל",מלאי!L154=#REF!),OR(#REF!="הכל",מלאי!O154=#REF!),OR(#REF!="הכל",מלאי!R154=#REF!),OR(#REF!="הכל",#REF!="",מלאי!W154=#REF!),OR(#REF!="הכל",#REF!="",ISNUMBER(SEARCH(#REF!,מלאי!C154))),OR(#REF!="הכל",מלאי!#REF!=#REF!)),1,0) -> #REF! | AF13: =IF(AD13=1,COUNTIF($AD$3:$AD13,1),"") -> #REF! | AG13: =IF(AE13=1,COUNTIF($AE$3:$AE13,1),"") -> #REF!
A14: OverGarment | B14: Arctic Overpants | C14: V1 | D14: Arctic Pants Fresh 1 | E14: =IFERROR(INDEX(הגדרות!$I$2:$I$47,MATCH(B14,הגדרות!$H$2:$H$47,0)),"") -> 7052-00 | F14: RIPSTOP Double Layer | H14: Fresh Snow | J14: כן | K14: כן | L14: כן | M14: כן | N14: כן | T14: במלאי | Z14: =IFERROR(INDEX(הגדרות!$B$2:$B$17,MATCH(H14,הגדרות!$A$2:$A$17,0)),"") -> שלג | AA14: =IFERROR(INDEX(הגדרות!$C$2:$C$17,MATCH(H14,הגדרות!$A$2:$A$17,0)),"") -> 0 | AB14: =IFERROR(INDEX(הגדרות!$B$2:$B$17,MATCH(I14,הגדרות!$A$2:$A$17,0)),"") | AC14: =IFERROR(INDEX(הגדרות!$C$2:$C$17,MATCH(I14,הגדרות!$A$2:$A$17,0)),"") | AD14: =IF(AND(מלאי!D101<>"",OR(#REF!="הכל",מלאי!Z101=#REF!,מלאי!AA101=#REF!,מלאי!AB101=#REF!,מלאי!AC101=#REF!),OR(#REF!="הכל",מלאי!A101=#REF!),OR(#REF!="הכל",מלאי!B101=#REF!),OR(#REF!="הכל",מלאי!F101=#REF!,מלאי!G101=#REF!),OR(#REF!="הכל",מלאי!T101=#REF!),OR(#REF!="הכל",מלאי!Q101=#REF!),OR(#REF!="הכל",מלאי!J101=#REF!),OR(#REF!="הכל",מלאי!L101=#REF!),OR(#REF!="הכל",מלאי!O101=#REF!),OR(#REF!="הכל",מלאי!R101=#REF!),OR(#REF!="הכל",#REF!="",מלאי!W101=#REF!),OR(#REF!="הכל",#REF!="",ISNUMBER(SEARCH(#REF!,מלאי!C101)))),1,0) -> #REF! | AE14: =IF(AND(מלאי!D101<>"",OR(#REF!="הכל",מלאי!Z101=#REF!,מלאי!AA101=#REF!,מלאי!AB101=#REF!,מלאי!AC101=#REF!),OR(#REF!="הכל",מלאי!A101=#REF!),OR(#REF!="הכל",מלאי!B101=#REF!),OR(#REF!="הכל",מלאי!F101=#REF!,מלאי!G101=#REF!),OR(#REF!="הכל",מלאי!T101=#REF!),OR(#REF!="הכל",מלאי!Q101=#REF!),OR(#REF!="הכל",מלאי!J101=#REF!),OR(#REF!="הכל",מלאי!L101=#REF!),OR(#REF!="הכל",מלאי!O101=#REF!),OR(#REF!="הכל",מלאי!R101=#REF!),OR(#REF!="הכל",#REF!="",מלאי!W101=#REF!),OR(#REF!="הכל",#REF!="",ISNUMBER(SEARCH(#REF!,מלאי!C101))),OR(#REF!="הכל",מלאי!#REF!=#REF!)),1,0) -> #REF! | AF14: =IF(AD14=1,COUNTIF($AD$3:$AD14,1),"") -> #REF! | AG14: =IF(AE14=1,COUNTIF($AE$3:$AE14,1),"") -> #REF!
A15: OverGarment | B15: Arctic Overpants | C15: V1 | D15: Arctic Pants Snirt 1 | E15: =IFERROR(INDEX(הגדרות!$I$2:$I$47,MATCH(B15,הגדרות!$H$2:$H$47,0)),"") -> 7052-00 | F15: RIPSTOP Double Layer | H15: Snirt Snow | J15: כן | K15: כן | L15: כן | M15: כן | N15: לא | P15: אקססוריז לא בלבן | T15: במלאי | Z15: =IFERROR(INDEX(הגדרות!$B$2:$B$17,MATCH(H15,הגדרות!$A$2:$A$17,0)),"") -> שלג | AA15: =IFERROR(INDEX(הגדרות!$C$2:$C$17,MATCH(H15,הגדרות!$A$2:$A$17,0)),"") -> 0 | AB15: =IFERROR(INDEX(הגדרות!$B$2:$B$17,MATCH(I15,הגדרות!$A$2:$A$17,0)),"") | AC15: =IFERROR(INDEX(הגדרות!$C$2:$C$17,MATCH(I15,הגדרות!$A$2:$A$17,0)),"") | AD15: =IF(AND(מלאי!D102<>"",OR(#REF!="הכל",מלאי!Z102=#REF!,מלאי!AA102=#REF!,מלאי!AB102=#REF!,מלאי!AC102=#REF!),OR(#REF!="הכל",מלאי!A102=#REF!),OR(#REF!="הכל",מלאי!B102=#REF!),OR(#REF!="הכל",מלאי!F102=#REF!,מלאי!G102=#REF!),OR(#REF!="הכל",מלאי!T102=#REF!),OR(#REF!="הכל",מלאי!Q102=#REF!),OR(#REF!="הכל",מלאי!J102=#REF!),OR(#REF!="הכל",מלאי!L102=#REF!),OR(#REF!="הכל",מלאי!O102=#REF!),OR(#REF!="הכל",מלאי!R102=#REF!),OR(#REF!="הכל",#REF!="",מלאי!W102=#REF!),OR(#REF!="הכל",#REF!="",ISNUMBER(SEARCH(#REF!,מלאי!C102)))),1,0) -> #REF! | AE15: =IF(AND(מלאי!D102<>"",OR(#REF!="הכל",מלאי!Z102=#REF!,מלאי!AA102=#REF!,מלאי!AB102=#REF!,מלאי!AC102=#REF!),OR(#REF!="הכל",מלאי!A102=#REF!),OR(#REF!="הכל",מלאי!B102=#REF!),OR(#REF!="הכל",מלאי!F102=#REF!,מלאי!G102=#REF!),OR(#REF!="הכל",מלאי!T102=#REF!),OR(#REF!="הכל",מלאי!Q102=#REF!),OR(#REF!="הכל",מלאי!J102=#REF!),OR(#REF!="הכל",מלאי!L102=#REF!),OR(#REF!="הכל",מלאי!O102=#REF!),OR(#REF!="הכל",מלאי!R102=#REF!),OR(#REF!="הכל",#REF!="",מלאי!W102=#REF!),OR(#REF!="הכל",#REF!="",ISNUMBER(SEARCH(#REF!,מלאי!C102))),OR(#REF!="הכל",מלאי!#REF!=#REF!)),1,0) -> #REF! | AF15: =IF(AD15=1,COUNTIF($AD$3:$AD15,1),"") -> #REF! | AG15: =IF(AE15=1,COUNTIF($AE$3:$AE15,1),"") -> #REF!
A16: OverGarment | B16: Arctic Overpants | C16: V1 | D16: Arctic Pants Fresh 2 | E16: =IFERROR(INDEX(הגדרות!$I$2:$I$47,MATCH(B16,הגדרות!$H$2:$H$47,0)),"") -> 7052-00 | F16: RIPSTOP Double Layer | H16: Fresh Snow | J16: כן | K16: כן | L16: כן | M16: כן | N16: לא | P16: אקססוריז לא בלבן | T16: במלאי | Z16: =IFERROR(INDEX(הגדרות!$B$2:$B$17,MATCH(H16,הגדרות!$A$2:$A$17,0)),"") -> שלג | AA16: =IFERROR(INDEX(הגדרות!$C$2:$C$17,MATCH(H16,הגדרות!$A$2:$A$17,0)),"") -> 0 | AB16: =IFERROR(INDEX(הגדרות!$B$2:$B$17,MATCH(I16,הגדרות!$A$2:$A$17,0)),"") | AC16: =IFERROR(INDEX(הגדרות!$C$2:$C$17,MATCH(I16,הגדרות!$A$2:$A$17,0)),"") | AD16: =IF(AND(מלאי!D110<>"",OR(#REF!="הכל",מלאי!Z110=#REF!,מלאי!AA110=#REF!,מלאי!AB110=#REF!,מלאי!AC110=#REF!),OR(#REF!="הכל",מלאי!A110=#REF!),OR(#REF!="הכל",מלאי!B110=#REF!),OR(#REF!="הכל",מלאי!F110=#REF!,מלאי!G110=#REF!),OR(#REF!="הכל",מלאי!T110=#REF!),OR(#REF!="הכל",מלאי!Q110=#REF!),OR(#REF!="הכל",מלאי!J110=#REF!),OR(#REF!="הכל",מלאי!L110=#REF!),OR(#REF!="הכל",מלאי!O110=#REF!),OR(#REF!="הכל",מלאי!R110=#REF!),OR(#REF!="הכל",#REF!="",מלאי!W110=#REF!),OR(#REF!="הכל",#REF!="",ISNUMBER(SEARCH(#REF!,מלאי!C110)))),1,0) -> #REF! | AE16: =IF(AND(מלאי!D110<>"",OR(#REF!="הכל",מלאי!Z110=#REF!,מלאי!AA110=#REF!,מלאי!AB110=#REF!,מלאי!AC110=#REF!),OR(#REF!="הכל",מלאי!A110=#REF!),OR(#REF!="הכל",מלאי!B110=#REF!),OR(#REF!="הכל",מלאי!F110=#REF!,מלאי!G110=#REF!),OR(#REF!="הכל",מלאי!T110=#REF!),OR(#REF!="הכל",מלאי!Q110=#REF!),OR(#REF!="הכל",מלאי!J110=#REF!),OR(#REF!="הכל",מלאי!L110=#REF!),OR(#REF!="הכל",מלאי!O110=#REF!),OR(#REF!="הכל",מלאי!R110=#REF!),OR(#REF!="הכל",#REF!="",מלאי!W110=#REF!),OR(#REF!="הכל",#REF!="",ISNUMBER(SEARCH(#REF!,מלאי!C110))),OR(#REF!="הכל",מלאי!#REF!=#REF!)),1,0) -> #REF! | AF16: =IF(AD16=1,COUNTIF($AD$3:$AD16,1),"") -> #REF! | AG16: =IF(AE16=1,COUNTIF($AE$3:$AE16,1),"") -> #REF!
A17: OverGarment | B17: Arctic Overpants | C17: V1 | D17: Arctic Pants sampels Snirt | E17: =IFERROR(INDEX(הגדרות!$I$2:$I$47,MATCH(B17,הגדרות!$H$2:$H$47,0)),"") -> 7052-00 | F17: RIPSTOP Double Layer | H17: Snirt Snow | J17: כן | K17: כן | L17: כן | M17: כן | N17: כן | T17: במלאי | Z17: =IFERROR(INDEX(הגדרות!$B$2:$B$17,MATCH(H17,הגדרות!$A$2:$A$17,0)),"") -> שלג | AA17: =IFERROR(INDEX(הגדרות!$C$2:$C$17,MATCH(H17,הגדרות!$A$2:$A$17,0)),"") -> 0 | AB17: =IFERROR(INDEX(הגדרות!$B$2:$B$17,MATCH(I17,הגדרות!$A$2:$A$17,0)),"") | AC17: =IFERROR(INDEX(הגדרות!$C$2:$C$17,MATCH(I17,הגדרות!$A$2:$A$17,0)),"") | AD17: =IF(AND(מלאי!D150<>"",OR(#REF!="הכל",מלאי!Z150=#REF!,מלאי!AA150=#REF!,מלאי!AB150=#REF!,מלאי!AC150=#REF!),OR(#REF!="הכל",מלאי!A150=#REF!),OR(#REF!="הכל",מלאי!B150=#REF!),OR(#REF!="הכל",מלאי!F150=#REF!,מלאי!G150=#REF!),OR(#REF!="הכל",מלאי!T150=#REF!),OR(#REF!="הכל",מלאי!Q150=#REF!),OR(#REF!="הכל",מלאי!J150=#REF!),OR(#REF!="הכל",מלאי!L150=#REF!),OR(#REF!="הכל",מלאי!O150=#REF!),OR(#REF!="הכל",מלאי!R150=#REF!),OR(#REF!="הכל",#REF!="",מלאי!W150=#REF!),OR(#REF!="הכל",#REF!="",ISNUMBER(SEARCH(#REF!,מלאי!C150)))),1,0) -> #REF! | AE17: =IF(AND(מלאי!D150<>"",OR(#REF!="הכל",מלאי!Z150=#REF!,מלאי!AA150=#REF!,מלאי!AB150=#REF!,מלאי!AC150=#REF!),OR(#REF!="הכל",מלאי!A150=#REF!),OR(#REF!="הכל",מלאי!B150=#REF!),OR(#REF!="הכל",מלאי!F150=#REF!,מלאי!G150=#REF!),OR(#REF!="הכל",מלאי!T150=#REF!),OR(#REF!="הכל",מלאי!Q150=#REF!),OR(#REF!="הכל",מלאי!J150=#REF!),OR(#REF!="הכל",מלאי!L150=#REF!),OR(#REF!="הכל",מלאי!O150=#REF!),OR(#REF!="הכל",מלאי!R150=#REF!),OR(#REF!="הכל",#REF!="",מלאי!W150=#REF!),OR(#REF!="הכל",#REF!="",ISNUMBER(SEARCH(#REF!,מלאי!C150))),OR(#REF!="הכל",מלאי!#REF!=#REF!)),1,0) -> #REF! | AF17: =IF(AD17=1,COUNTIF($AD$3:$AD17,1),"") -> #REF! | AG17: =IF(AE17=1,COUNTIF($AE$3:$AE17,1),"") -> #REF!
A18: OverGarment | B18: Arctic Overpants | C18: V1 | D18: Arctic Pants sampels Fresh | E18: =IFERROR(INDEX(הגדרות!$I$2:$I$47,MATCH(B18,הגדרות!$H$2:$H$47,0)),"") -> 7052-00 | F18: RIPSTOP Double Layer | H18: Fresh Snow | J18: כן | K18: כן | L18: כן | M18: כן | N18: כן | T18: במלאי | Z18: =IFERROR(INDEX(הגדרות!$B$2:$B$17,MATCH(H18,הגדרות!$A$2:$A$17,0)),"") -> שלג | AA18: =IFERROR(INDEX(הגדרות!$C$2:$C$17,MATCH(H18,הגדרות!$A$2:$A$17,0)),"") -> 0 | AB18: =IFERROR(INDEX(הגדרות!$B$2:$B$17,MATCH(I18,הגדרות!$A$2:$A$17,0)),"") | AC18: =IFERROR(INDEX(הגדרות!$C$2:$C$17,MATCH(I18,הגדרות!$A$2:$A$17,0)),"") | AD18: =IF(AND(מלאי!D155<>"",OR(#REF!="הכל",מלאי!Z155=#REF!,מלאי!AA155=#REF!,מלאי!AB155=#REF!,מלאי!AC155=#REF!),OR(#REF!="הכל",מלאי!A155=#REF!),OR(#REF!="הכל",מלאי!B155=#REF!),OR(#REF!="הכל",מלאי!F155=#REF!,מלאי!G155=#REF!),OR(#REF!="הכל",מלאי!T155=#REF!),OR(#REF!="הכל",מלאי!Q155=#REF!),OR(#REF!="הכל",מלאי!J155=#REF!),OR(#REF!="הכל",מלאי!L155=#REF!),OR(#REF!="הכל",מלאי!O155=#REF!),OR(#REF!="הכל",מלאי!R155=#REF!),OR(#REF!="הכל",#REF!="",מלאי!W155=#REF!),OR(#REF!="הכל",#REF!="",ISNUMBER(SEARCH(#REF!,מלאי!C155)))),1,0) -> #REF! | AE18: =IF(AND(מלאי!D155<>"",OR(#REF!="הכל",מלאי!Z155=#REF!,מלאי!AA155=#REF!,מלאי!AB155=#REF!,מלאי!AC155=#REF!),OR(#REF!="הכל",מלאי!A155=#REF!),OR(#REF!="הכל",מלאי!B155=#REF!),OR(#REF!="הכל",מלאי!F155=#REF!,מלאי!G155=#REF!),OR(#REF!="הכל",מלאי!T155=#REF!),OR(#REF!="הכל",מלאי!Q155=#REF!),OR(#REF!="הכל",מלאי!J155=#REF!),OR(#REF!="הכל",מלאי!L155=#REF!),OR(#REF!="הכל",מלאי!O155=#REF!),OR(#REF!="הכל",מלאי!R155=#REF!),OR(#REF!="הכל",#REF!="",מלאי!W155=#REF!),OR(#REF!="הכל",#REF!="",ISNUMBER(SEARCH(#REF!,מלאי!C155))),OR(#REF!="הכל",מלאי!#REF!=#REF!)),1,0) -> #REF! | AF18: =IF(AD18=1,COUNTIF($AD$3:$AD18,1),"") -> #REF! | AG18: =IF(AE18=1,COUNTIF($AE$3:$AE18,1),"") -> #REF!
A19: OverGarment | B19: Arctic Poncho SRV | C19: V1 | D19: Arctic poncho Snirt 1 | E19: =IFERROR(INDEX(הגדרות!$I$2:$I$47,MATCH(B19,הגדרות!$H$2:$H$47,0)),"") -> 0 | F19: RIPSTOP Double Layer | H19: Snirt Snow | J19: כן | K19: כן | L19: כן | M19: כן | N19: לא | T19: במלאי | Z19: =IFERROR(INDEX(הגדרות!$B$2:$B$17,MATCH(H19,הגדרות!$A$2:$A$17,0)),"") -> שלג | AA19: =IFERROR(INDEX(הגדרות!$C$2:$C$17,MATCH(H19,הגדרות!$A$2:$A$17,0)),"") -> 0 | AB19: =IFERROR(INDEX(הגדרות!$B$2:$B$17,MATCH(I19,הגדרות!$A$2:$A$17,0)),"") | AC19: =IFERROR(INDEX(הגדרות!$C$2:$C$17,MATCH(I19,הגדרות!$A$2:$A$17,0)),"") | AD19: =IF(AND(מלאי!#REF!<>"",OR(#REF!="הכל",מלאי!Z93=#REF!,מלאי!AA93=#REF!,מלאי!AB93=#REF!,מלאי!AC93=#REF!),OR(#REF!="הכל",מלאי!A93=#REF!),OR(#REF!="הכל",מלאי!B93=#REF!),OR(#REF!="הכל",מלאי!F93=#REF!,מלאי!G93=#REF!),OR(#REF!="הכל",מלאי!T93=#REF!),OR(#REF!="הכל",מלאי!Q93=#REF!),OR(#REF!="הכל",מלאי!J93=#REF!),OR(#REF!="הכל",מלאי!L93=#REF!),OR(#REF!="הכל",מלאי!O93=#REF!),OR(#REF!="הכל",מלאי!R93=#REF!),OR(#REF!="הכל",#REF!="",מלאי!W93=#REF!),OR(#REF!="הכל",#REF!="",ISNUMBER(SEARCH(#REF!,מלאי!C93)))),1,0) -> #REF! | AE19: =IF(AND(מלאי!#REF!<>"",OR(#REF!="הכל",מלאי!Z93=#REF!,מלאי!AA93=#REF!,מלאי!AB93=#REF!,מלאי!AC93=#REF!),OR(#REF!="הכל",מלאי!A93=#REF!),OR(#REF!="הכל",מלאי!B93=#REF!),OR(#REF!="הכל",מלאי!F93=#REF!,מלאי!G93=#REF!),OR(#REF!="הכל",מלאי!T93=#REF!),OR(#REF!="הכל",מלאי!Q93=#REF!),OR(#REF!="הכל",מלאי!J93=#REF!),OR(#REF!="הכל",מלאי!L93=#REF!),OR(#REF!="הכל",מלאי!O93=#REF!),OR(#REF!="הכל",מלאי!R93=#REF!),OR(#REF!="הכל",#REF!="",מלאי!W93=#REF!),OR(#REF!="הכל",#REF!="",ISNUMBER(SEARCH(#REF!,מלאי!C93))),OR(#REF!="הכל",מלאי!#REF!=#REF!)),1,0) -> #REF! | AF19: =IF(AD19=1,COUNTIF($AD$3:$AD19,1),"") -> #REF! | AG19: =IF(AE19=1,COUNTIF($AE$3:$AE19,1),"") -> #REF!
A20: OverGarment | B20: Arctic Poncho SRV | C20: V1 | D20: Arctic poncho Snirt 2 | E20: =IFERROR(INDEX(הגדרות!$I$2:$I$47,MATCH(B20,הגדרות!$H$2:$H$47,0)),"") -> 0 | F20: RIPSTOP Double Layer | H20: Snirt Snow | J20: כן | K20: כן | L20: כן | M20: כן | N20: כן | T20: במלאי | Z20: =IFERROR(INDEX(הגדרות!$B$2:$B$17,MATCH(H20,הגדרות!$A$2:$A$17,0)),"") -> שלג | AA20: =IFERROR(INDEX(הגדרות!$C$2:$C$17,MATCH(H20,הגדרות!$A$2:$A$17,0)),"") -> 0 | AB20: =IFERROR(INDEX(הגדרות!$B$2:$B$17,MATCH(I20,הגדרות!$A$2:$A$17,0)),"") | AC20: =IFERROR(INDEX(הגדרות!$C$2:$C$17,MATCH(I20,הגדרות!$A$2:$A$17,0)),"") | AD20: =IF(AND(מלאי!D99<>"",OR(#REF!="הכל",מלאי!Z94=#REF!,מלאי!AA94=#REF!,מלאי!AB94=#REF!,מלאי!AC94=#REF!),OR(#REF!="הכל",מלאי!A94=#REF!),OR(#REF!="הכל",מלאי!B94=#REF!),OR(#REF!="הכל",מלאי!F94=#REF!,מלאי!G94=#REF!),OR(#REF!="הכל",מלאי!T94=#REF!),OR(#REF!="הכל",מלאי!Q94=#REF!),OR(#REF!="הכל",מלאי!J94=#REF!),OR(#REF!="הכל",מלאי!L94=#REF!),OR(#REF!="הכל",מלאי!O94=#REF!),OR(#REF!="הכל",מלאי!R94=#REF!),OR(#REF!="הכל",#REF!="",מלאי!W94=#REF!),OR(#REF!="הכל",#REF!="",ISNUMBER(SEARCH(#REF!,מלאי!C94)))),1,0) -> #REF! | AE20: =IF(AND(מלאי!D99<>"",OR(#REF!="הכל",מלאי!Z94=#REF!,מלאי!AA94=#REF!,מלאי!AB94=#REF!,מלאי!AC94=#REF!),OR(#REF!="הכל",מלאי!A94=#REF!),OR(#REF!="הכל",מלאי!B94=#REF!),OR(#REF!="הכל",מלאי!F94=#REF!,מלאי!G94=#REF!),OR(#REF!="הכל",מלאי!T94=#REF!),OR(#REF!="הכל",מלאי!Q94=#REF!),OR(#REF!="הכל",מלאי!J94=#REF!),OR(#REF!="הכל",מלאי!L94=#REF!),OR(#REF!="הכל",מלאי!O94=#REF!),OR(#REF!="הכל",מלאי!R94=#REF!),OR(#REF!="הכל",#REF!="",מלאי!W94=#REF!),OR(#REF!="הכל",#REF!="",ISNUMBER(SEARCH(#REF!,מלאי!C94))),OR(#REF!="הכל",מלאי!#REF!=#REF!)),1,0) -> #REF! | AF20: =IF(AD20=1,COUNTIF($AD$3:$AD20,1),"") -> #REF! | AG20: =IF(AE20=1,COUNTIF($AE$3:$AE20,1),"") -> #REF!
A21: OverGarment | B21: Arctic Poncho SRV | C21: V1 | D21: Arctic poncho Fresh 1 | E21: =IFERROR(INDEX(הגדרות!$I$2:$I$47,MATCH(B21,הגדרות!$H$2:$H$47,0)),"") -> 0 | F21: RIPSTOP Double Layer | H21: Fresh Snow | J21: כן | K21: כן | L21: כן | M21: כן | N21: כן | T21: במלאי | Z21: =IFERROR(INDEX(הגדרות!$B$2:$B$17,MATCH(H21,הגדרות!$A$2:$A$17,0)),"") -> שלג | AA21: =IFERROR(INDEX(הגדרות!$C$2:$C$17,MATCH(H21,הגדרות!$A$2:$A$17,0)),"") -> 0 | AB21: =IFERROR(INDEX(הגדרות!$B$2:$B$17,MATCH(I21,הגדרות!$A$2:$A$17,0)),"") | AC21: =IFERROR(INDEX(הגדרות!$C$2:$C$17,MATCH(I21,הגדרות!$A$2:$A$17,0)),"") | AD21: =IF(AND(מלאי!D95<>"",OR(#REF!="הכל",מלאי!Z95=#REF!,מלאי!AA95=#REF!,מלאי!AB95=#REF!,מלאי!AC95=#REF!),OR(#REF!="הכל",מלאי!A95=#REF!),OR(#REF!="הכל",מלאי!B95=#REF!),OR(#REF!="הכל",מלאי!F95=#REF!,מלאי!G95=#REF!),OR(#REF!="הכל",מלאי!T95=#REF!),OR(#REF!="הכל",מלאי!Q95=#REF!),OR(#REF!="הכל",מלאי!J95=#REF!),OR(#REF!="הכל",מלאי!L95=#REF!),OR(#REF!="הכל",מלאי!O95=#REF!),OR(#REF!="הכל",מלאי!R95=#REF!),OR(#REF!="הכל",#REF!="",מלאי!W95=#REF!),OR(#REF!="הכל",#REF!="",ISNUMBER(SEARCH(#REF!,מלאי!C95)))),1,0) -> #REF! | AE21: =IF(AND(מלאי!D95<>"",OR(#REF!="הכל",מלאי!Z95=#REF!,מלאי!AA95=#REF!,מלאי!AB95=#REF!,מלאי!AC95=#REF!),OR(#REF!="הכל",מלאי!A95=#REF!),OR(#REF!="הכל",מלאי!B95=#REF!),OR(#REF!="הכל",מלאי!F95=#REF!,מלאי!G95=#REF!),OR(#REF!="הכל",מלאי!T95=#REF!),OR(#REF!="הכל",מלאי!Q95=#REF!),OR(#REF!="הכל",מלאי!J95=#REF!),OR(#REF!="הכל",מלאי!L95=#REF!),OR(#REF!="הכל",מלאי!O95=#REF!),OR(#REF!="הכל",מלאי!R95=#REF!),OR(#REF!="הכל",#REF!="",מלאי!W95=#REF!),OR(#REF!="הכל",#REF!="",ISNUMBER(SEARCH(#REF!,מלאי!C95))),OR(#REF!="הכל",מלאי!#REF!=#REF!)),1,0) -> #REF! | AF21: =IF(AD21=1,COUNTIF($AD$3:$AD21,1),"") -> #REF! | AG21: =IF(AE21=1,COUNTIF($AE$3:$AE21,1),"") -> #REF!
A22: OverGarment | B22: Arctic Poncho SRV | C22: V1 | D22: Arctic poncho Fresh 3 | E22: =IFERROR(INDEX(הגדרות!$I$2:$I$47,MATCH(B22,הגדרות!$H$2:$H$47,0)),"") -> 0 | F22: RIPSTOP Double Layer | H22: Fresh Snow | J22: כן | K22: כן | L22: כן | M22: כן | N22: לא | P22: אקססוריז לא בלבן | T22: במלאי | Z22: =IFERROR(INDEX(הגדרות!$B$2:$B$17,MATCH(H22,הגדרות!$A$2:$A$17,0)),"") -> שלג | AA22: =IFERROR(INDEX(הגדרות!$C$2:$C$17,MATCH(H22,הגדרות!$A$2:$A$17,0)),"") -> 0 | AB22: =IFERROR(INDEX(הגדרות!$B$2:$B$17,MATCH(I22,הגדרות!$A$2:$A$17,0)),"") | AC22: =IFERROR(INDEX(הגדרות!$C$2:$C$17,MATCH(I22,הגדרות!$A$2:$A$17,0)),"") | AD22: =IF(AND(מלאי!D108<>"",OR(#REF!="הכל",מלאי!Z108=#REF!,מלאי!AA108=#REF!,מלאי!AB108=#REF!,מלאי!AC108=#REF!),OR(#REF!="הכל",מלאי!A108=#REF!),OR(#REF!="הכל",מלאי!B108=#REF!),OR(#REF!="הכל",מלאי!F108=#REF!,מלאי!G108=#REF!),OR(#REF!="הכל",מלאי!T108=#REF!),OR(#REF!="הכל",מלאי!Q108=#REF!),OR(#REF!="הכל",מלאי!J108=#REF!),OR(#REF!="הכל",מלאי!L108=#REF!),OR(#REF!="הכל",מלאי!O108=#REF!),OR(#REF!="הכל",מלאי!R108=#REF!),OR(#REF!="הכל",#REF!="",מלאי!W108=#REF!),OR(#REF!="הכל",#REF!="",ISNUMBER(SEARCH(#REF!,מלאי!C108)))),1,0) -> #REF! | AE22: =IF(AND(מלאי!D108<>"",OR(#REF!="הכל",מלאי!Z108=#REF!,מלאי!AA108=#REF!,מלאי!AB108=#REF!,מלאי!AC108=#REF!),OR(#REF!="הכל",מלאי!A108=#REF!),OR(#REF!="הכל",מלאי!B108=#REF!),OR(#REF!="הכל",מלאי!F108=#REF!,מלאי!G108=#REF!),OR(#REF!="הכל",מלאי!T108=#REF!),OR(#REF!="הכל",מלאי!Q108=#REF!),OR(#REF!="הכל",מלאי!J108=#REF!),OR(#REF!="הכל",מלאי!L108=#REF!),OR(#REF!="הכל",מלאי!O108=#REF!),OR(#REF!="הכל",מלאי!R108=#REF!),OR(#REF!="הכל",#REF!="",מלאי!W108=#REF!),OR(#REF!="הכל",#REF!="",ISNUMBER(SEARCH(#REF!,מלאי!C108))),OR(#REF!="הכל",מלאי!#REF!=#REF!)),1,0) -> #REF! | AF22: =IF(AD22=1,COUNTIF($AD$3:$AD22,1),"") -> #REF! | AG22: =IF(AE22=1,COUNTIF($AE$3:$AE22,1),"") -> #REF!
A23: OverGarment | B23: Arctic Poncho SRV | C23: V1 | D23: Arctic poncho Fresh 2 | E23: =IFERROR(INDEX(הגדרות!$I$2:$I$47,MATCH(B23,הגדרות!$H$2:$H$47,0)),"") -> 0 | F23: RIPSTOP Double Layer | H23: Fresh Snow | J23: כן | K23: כן | L23: כן | M23: כן | N23: כן | T23: במלאי | Z23: =IFERROR(INDEX(הגדרות!$B$2:$B$17,MATCH(H23,הגדרות!$A$2:$A$17,0)),"") -> שלג | AA23: =IFERROR(INDEX(הגדרות!$C$2:$C$17,MATCH(H23,הגדרות!$A$2:$A$17,0)),"") -> 0 | AB23: =IFERROR(INDEX(הגדרות!$B$2:$B$17,MATCH(I23,הגדרות!$A$2:$A$17,0)),"") | AC23: =IFERROR(INDEX(הגדרות!$C$2:$C$17,MATCH(I23,הגדרות!$A$2:$A$17,0)),"") | AD23: =IF(AND(מלאי!D111<>"",OR(#REF!="הכל",מלאי!Z111=#REF!,מלאי!AA111=#REF!,מלאי!AB111=#REF!,מלאי!AC111=#REF!),OR(#REF!="הכל",מלאי!A111=#REF!),OR(#REF!="הכל",מלאי!B111=#REF!),OR(#REF!="הכל",מלאי!F111=#REF!,מלאי!G111=#REF!),OR(#REF!="הכל",מלאי!T111=#REF!),OR(#REF!="הכל",מלאי!Q111=#REF!),OR(#REF!="הכל",מלאי!J111=#REF!),OR(#REF!="הכל",מלאי!L111=#REF!),OR(#REF!="הכל",מלאי!O111=#REF!),OR(#REF!="הכל",מלאי!R111=#REF!),OR(#REF!="הכל",#REF!="",מלאי!W111=#REF!),OR(#REF!="הכל",#REF!="",ISNUMBER(SEARCH(#REF!,מלאי!C111)))),1,0) -> #REF! | AE23: =IF(AND(מלאי!D111<>"",OR(#REF!="הכל",מלאי!Z111=#REF!,מלאי!AA111=#REF!,מלאי!AB111=#REF!,מלאי!AC111=#REF!),OR(#REF!="הכל",מלאי!A111=#REF!),OR(#REF!="הכל",מלאי!B111=#REF!),OR(#REF!="הכל",מלאי!F111=#REF!,מלאי!G111=#REF!),OR(#REF!="הכל",מלאי!T111=#REF!),OR(#REF!="הכל",מלאי!Q111=#REF!),OR(#REF!="הכל",מלאי!J111=#REF!),OR(#REF!="הכל",מלאי!L111=#REF!),OR(#REF!="הכל",מלאי!O111=#REF!),OR(#REF!="הכל",מלאי!R111=#REF!),OR(#REF!="הכל",#REF!="",מלאי!W111=#REF!),OR(#REF!="הכל",#REF!="",ISNUMBER(SEARCH(#REF!,מלאי!C111))),OR(#REF!="הכל",מלאי!#REF!=#REF!)),1,0) -> #REF! | AF23: =IF(AD23=1,COUNTIF($AD$3:$AD23,1),"") -> #REF! | AG23: =IF(AE23=1,COUNTIF($AE$3:$AE23,1),"") -> #REF!
A24: OverGarment | B24: Arctic Poncho SRV | C24: V1 | D24: Arctic poncho sampels Snirt | E24: =IFERROR(INDEX(הגדרות!$I$2:$I$47,MATCH(B24,הגדרות!$H$2:$H$47,0)),"") -> 0 | F24: RIPSTOP Double Layer | H24: Snirt Snow | J24: כן | K24: כן | L24: כן | M24: כן | N24: כן | T24: במלאי | Z24: =IFERROR(INDEX(הגדרות!$B$2:$B$17,MATCH(H24,הגדרות!$A$2:$A$17,0)),"") -> שלג | AA24: =IFERROR(INDEX(הגדרות!$C$2:$C$17,MATCH(H24,הגדרות!$A$2:$A$17,0)),"") -> 0 | AB24: =IFERROR(INDEX(הגדרות!$B$2:$B$17,MATCH(I24,הגדרות!$A$2:$A$17,0)),"") | AC24: =IFERROR(INDEX(הגדרות!$C$2:$C$17,MATCH(I24,הגדרות!$A$2:$A$17,0)),"") | AD24: =IF(AND(מלאי!D156<>"",OR(#REF!="הכל",מלאי!Z151=#REF!,מלאי!AA151=#REF!,מלאי!AB151=#REF!,מלאי!AC151=#REF!),OR(#REF!="הכל",מלאי!A151=#REF!),OR(#REF!="הכל",מלאי!B151=#REF!),OR(#REF!="הכל",מלאי!F151=#REF!,מלאי!G151=#REF!),OR(#REF!="הכל",מלאי!T151=#REF!),OR(#REF!="הכל",מלאי!Q151=#REF!),OR(#REF!="הכל",מלאי!J151=#REF!),OR(#REF!="הכל",מלאי!L151=#REF!),OR(#REF!="הכל",מלאי!O151=#REF!),OR(#REF!="הכל",מלאי!R151=#REF!),OR(#REF!="הכל",#REF!="",מלאי!W151=#REF!),OR(#REF!="הכל",#REF!="",ISNUMBER(SEARCH(#REF!,מלאי!C151)))),1,0) -> #REF! | AE24: =IF(AND(מלאי!D156<>"",OR(#REF!="הכל",מלאי!Z151=#REF!,מלאי!AA151=#REF!,מלאי!AB151=#REF!,מלאי!AC151=#REF!),OR(#REF!="הכל",מלאי!A151=#REF!),OR(#REF!="הכל",מלאי!B151=#REF!),OR(#REF!="הכל",מלאי!F151=#REF!,מלאי!G151=#REF!),OR(#REF!="הכל",מלאי!T151=#REF!),OR(#REF!="הכל",מלאי!Q151=#REF!),OR(#REF!="הכל",מלאי!J151=#REF!),OR(#REF!="הכל",מלאי!L151=#REF!),OR(#REF!="הכל",מלאי!O151=#REF!),OR(#REF!="הכל",מלאי!R151=#REF!),OR(#REF!="הכל",#REF!="",מלאי!W151=#REF!),OR(#REF!="הכל",#REF!="",ISNUMBER(SEARCH(#REF!,מלאי!C151))),OR(#REF!="הכל",מלאי!#REF!=#REF!)),1,0) -> #REF! | AF24: =IF(AD24=1,COUNTIF($AD$3:$AD24,1),"") -> #REF! | AG24: =IF(AE24=1,COUNTIF($AE$3:$AE24,1),"") -> #REF!
A25: OverGarment | B25: Arctic Poncho SRV | C25: V1 | D25: Arctic poncho sampels Fresh | E25: =IFERROR(INDEX(הגדרות!$I$2:$I$47,MATCH(B25,הגדרות!$H$2:$H$47,0)),"") -> 0 | F25: RIPSTOP Double Layer | H25: Fresh Snow | J25: כן | K25: כן | L25: כן | M25: כן | N25: כן | T25: במלאי | Z25: =IFERROR(INDEX(הגדרות!$B$2:$B$17,MATCH(H25,הגדרות!$A$2:$A$17,0)),"") -> שלג | AA25: =IFERROR(INDEX(הגדרות!$C$2:$C$17,MATCH(H25,הגדרות!$A$2:$A$17,0)),"") -> 0 | AB25: =IFERROR(INDEX(הגדרות!$B$2:$B$17,MATCH(I25,הגדרות!$A$2:$A$17,0)),"") | AC25: =IFERROR(INDEX(הגדרות!$C$2:$C$17,MATCH(I25,הגדרות!$A$2:$A$17,0)),"") | AD25: =IF(AND(מלאי!D161<>"",OR(#REF!="הכל",מלאי!Z156=#REF!,מלאי!AA156=#REF!,מלאי!AB156=#REF!,מלאי!AC156=#REF!),OR(#REF!="הכל",מלאי!A156=#REF!),OR(#REF!="הכל",מלאי!B156=#REF!),OR(#REF!="הכל",מלאי!F156=#REF!,מלאי!G156=#REF!),OR(#REF!="הכל",מלאי!T156=#REF!),OR(#REF!="הכל",מלאי!Q156=#REF!),OR(#REF!="הכל",מלאי!J156=#REF!),OR(#REF!="הכל",מלאי!L156=#REF!),OR(#REF!="הכל",מלאי!O156=#REF!),OR(#REF!="הכל",מלאי!R156=#REF!),OR(#REF!="הכל",#REF!="",מלאי!W156=#REF!),OR(#REF!="הכל",#REF!="",ISNUMBER(SEARCH(#REF!,מלאי!C156)))),1,0) -> #REF! | AE25: =IF(AND(מלאי!D161<>"",OR(#REF!="הכל",מלאי!Z156=#REF!,מלאי!AA156=#REF!,מלאי!AB156=#REF!,מלאי!AC156=#REF!),OR(#REF!="הכל",מלאי!A156=#REF!),OR(#REF!="הכל",מלאי!B156=#REF!),OR(#REF!="הכל",מלאי!F156=#REF!,מלאי!G156=#REF!),OR(#REF!="הכל",מלאי!T156=#REF!),OR(#REF!="הכל",מלאי!Q156=#REF!),OR(#REF!="הכל",מלאי!J156=#REF!),OR(#REF!="הכל",מלאי!L156=#REF!),OR(#REF!="הכל",מלאי!O156=#REF!),OR(#REF!="הכל",מלאי!R156=#REF!),OR(#REF!="הכל",#REF!="",מלאי!W156=#REF!),OR(#REF!="הכל",#REF!="",ISNUMBER(SEARCH(#REF!,מלאי!C156))),OR(#REF!="הכל",מלאי!#REF!=#REF!)),1,0) -> #REF! | AF25: =IF(AD25=1,COUNTIF($AD$3:$AD25,1),"") -> #REF! | AG25: =IF(AE25=1,COUNTIF($AE$3:$AE25,1),"") -> #REF!
A26: Blankets | B26: Arctic Survival Blanket | C26: V1 | D26: SRV Blanket Arc 1 | E26: =IFERROR(INDEX(הגדרות!$I$2:$I$47,MATCH(B26,הגדרות!$H$2:$H$47,0)),"") -> 0 | F26: RIPSTOP Double Layer | H26: Fresh Snow | T26: במלאי | Z26: =IFERROR(INDEX(הגדרות!$B$2:$B$17,MATCH(H26,הגדרות!$A$2:$A$17,0)),"") -> שלג | AA26: =IFERROR(INDEX(הגדרות!$C$2:$C$17,MATCH(H26,הגדרות!$A$2:$A$17,0)),"") -> 0 | AB26: =IFERROR(INDEX(הגדרות!$B$2:$B$17,MATCH(I26,הגדרות!$A$2:$A$17,0)),"") | AC26: =IFERROR(INDEX(הגדרות!$C$2:$C$17,MATCH(I26,הגדרות!$A$2:$A$17,0)),"") | AD26: =IF(AND(מלאי!D105<>"",OR(#REF!="הכל",מלאי!Z105=#REF!,מלאי!AA105=#REF!,מלאי!AB105=#REF!,מלאי!AC105=#REF!),OR(#REF!="הכל",מלאי!A105=#REF!),OR(#REF!="הכל",מלאי!B105=#REF!),OR(#REF!="הכל",מלאי!F105=#REF!,מלאי!G105=#REF!),OR(#REF!="הכל",מלאי!T105=#REF!),OR(#REF!="הכל",מלאי!Q105=#REF!),OR(#REF!="הכל",מלאי!J105=#REF!),OR(#REF!="הכל",מלאי!L105=#REF!),OR(#REF!="הכל",מלאי!O105=#REF!),OR(#REF!="הכל",מלאי!R105=#REF!),OR(#REF!="הכל",#REF!="",מלאי!W105=#REF!),OR(#REF!="הכל",#REF!="",ISNUMBER(SEARCH(#REF!,מלאי!C105)))),1,0) -> #REF! | AE26: =IF(AND(מלאי!D105<>"",OR(#REF!="הכל",מלאי!Z105=#REF!,מלאי!AA105=#REF!,מלאי!AB105=#REF!,מלאי!AC105=#REF!),OR(#REF!="הכל",מלאי!A105=#REF!),OR(#REF!="הכל",מלאי!B105=#REF!),OR(#REF!="הכל",מלאי!F105=#REF!,מלאי!G105=#REF!),OR(#REF!="הכל",מלאי!T105=#REF!),OR(#REF!="הכל",מלאי!Q105=#REF!),OR(#REF!="הכל",מלאי!J105=#REF!),OR(#REF!="הכל",מלאי!L105=#REF!),OR(#REF!="הכל",מלאי!O105=#REF!),OR(#REF!="הכל",מלאי!R105=#REF!),OR(#REF!="הכל",#REF!="",מלאי!W105=#REF!),OR(#REF!="הכל",#REF!="",ISNUMBER(SEARCH(#REF!,מלאי!C105))),OR(#REF!="הכל",מלאי!#REF!=#REF!)),1,0) -> #REF! | AF26: =IF(AD26=1,COUNTIF($AD$3:$AD26,1),"") -> #REF! | AG26: =IF(AE26=1,COUNTIF($AE$3:$AE26,1),"") -> #REF!
A27: Accessories | B27: Bag cover 90L | D27: B03 | E27: =IFERROR(INDEX(הגדרות!$I$2:$I$47,MATCH(B27,הגדרות!$H$2:$H$47,0)),"") -> 7009-01 | F27: Mesh | H27: Desert | J27: כן | T27: במלאי | Z27: =IFERROR(INDEX(הגדרות!$B$2:$B$17,MATCH(H27,הגדרות!$A$2:$A$17,0)),"") -> מדברי | AA27: =IFERROR(INDEX(הגדרות!$C$2:$C$17,MATCH(H27,הגדרות!$A$2:$A$17,0)),"") -> 0 | AB27: =IFERROR(INDEX(הגדרות!$B$2:$B$17,MATCH(I27,הגדרות!$A$2:$A$17,0)),"") | AC27: =IFERROR(INDEX(הגדרות!$C$2:$C$17,MATCH(I27,הגדרות!$A$2:$A$17,0)),"") | AD27: =IF(AND(מלאי!D182<>"",OR(#REF!="הכל",מלאי!Z182=#REF!,מלאי!AA182=#REF!,מלאי!AB182=#REF!,מלאי!AC182=#REF!),OR(#REF!="הכל",מלאי!A182=#REF!),OR(#REF!="הכל",מלאי!B182=#REF!),OR(#REF!="הכל",מלאי!F182=#REF!,מלאי!G182=#REF!),OR(#REF!="הכל",מלאי!T182=#REF!),OR(#REF!="הכל",מלאי!Q182=#REF!),OR(#REF!="הכל",מלאי!J182=#REF!),OR(#REF!="הכל",מלאי!L182=#REF!),OR(#REF!="הכל",מלאי!O182=#REF!),OR(#REF!="הכל",מלאי!R182=#REF!),OR(#REF!="הכל",#REF!="",מלאי!W182=#REF!),OR(#REF!="הכל",#REF!="",ISNUMBER(SEARCH(#REF!,מלאי!C182)))),1,0) -> #REF! | AE27: =IF(AND(מלאי!D182<>"",OR(#REF!="הכל",מלאי!Z182=#REF!,מלאי!AA182=#REF!,מלאי!AB182=#REF!,מלאי!AC182=#REF!),OR(#REF!="הכל",מלאי!A182=#REF!),OR(#REF!="הכל",מלאי!B182=#REF!),OR(#REF!="הכל",מלאי!F182=#REF!,מלאי!G182=#REF!),OR(#REF!="הכל",מלאי!T182=#REF!),OR(#REF!="הכל",מלאי!Q182=#REF!),OR(#REF!="הכל",מלאי!J182=#REF!),OR(#REF!="הכל",מלאי!L182=#REF!),OR(#REF!="הכל",מלאי!O182=#REF!),OR(#REF!="הכל",מלאי!R182=#REF!),OR(#REF!="הכל",#REF!="",מלאי!W182=#REF!),OR(#REF!="הכל",#REF!="",ISNUMBER(SEARCH(#REF!,מלאי!C182))),OR(#REF!="הכל",מלאי!#REF!=#REF!)),1,0) -> #REF! | AF27: =IF(AD27=1,COUNTIF($AD$3:$AD27,1),"") -> #REF! | AG27: =IF(AE27=1,COUNTIF($AE$3:$AE27,1),"") -> #REF!
A28: Accessories | B28: Bag cover 90L | D28: B04 | E28: =IFERROR(INDEX(הגדרות!$I$2:$I$47,MATCH(B28,הגדרות!$H$2:$H$47,0)),"") -> 7009-01 | F28: Mesh | H28: Kestrel | J28: כן | T28: במלאי | Z28: =IFERROR(INDEX(הגדרות!$B$2:$B$17,MATCH(H28,הגדרות!$A$2:$A$17,0)),"") -> מיוער | AA28: =IFERROR(INDEX(הגדרות!$C$2:$C$17,MATCH(H28,הגדרות!$A$2:$A$17,0)),"") -> 0 | AB28: =IFERROR(INDEX(הגדרות!$B$2:$B$17,MATCH(I28,הגדרות!$A$2:$A$17,0)),"") | AC28: =IFERROR(INDEX(הגדרות!$C$2:$C$17,MATCH(I28,הגדרות!$A$2:$A$17,0)),"") | AD28: =IF(AND(מלאי!D183<>"",OR(#REF!="הכל",מלאי!Z183=#REF!,מלאי!AA183=#REF!,מלאי!AB183=#REF!,מלאי!AC183=#REF!),OR(#REF!="הכל",מלאי!A183=#REF!),OR(#REF!="הכל",מלאי!B183=#REF!),OR(#REF!="הכל",מלאי!F183=#REF!,מלאי!G183=#REF!),OR(#REF!="הכל",מלאי!T183=#REF!),OR(#REF!="הכל",מלאי!Q183=#REF!),OR(#REF!="הכל",מלאי!J183=#REF!),OR(#REF!="הכל",מלאי!L183=#REF!),OR(#REF!="הכל",מלאי!O183=#REF!),OR(#REF!="הכל",מלאי!R183=#REF!),OR(#REF!="הכל",#REF!="",מלאי!W183=#REF!),OR(#REF!="הכל",#REF!="",ISNUMBER(SEARCH(#REF!,מלאי!C183)))),1,0) -> #REF! | AE28: =IF(AND(מלאי!D183<>"",OR(#REF!="הכל",מלאי!Z183=#REF!,מלאי!AA183=#REF!,מלאי!AB183=#REF!,מלאי!AC183=#REF!),OR(#REF!="הכל",מלאי!A183=#REF!),OR(#REF!="הכל",מלאי!B183=#REF!),OR(#REF!="הכל",מלאי!F183=#REF!,מלאי!G183=#REF!),OR(#REF!="הכל",מלאי!T183=#REF!),OR(#REF!="הכל",מלאי!Q183=#REF!),OR(#REF!="הכל",מלאי!J183=#REF!),OR(#REF!="הכל",מלאי!L183=#REF!),OR(#REF!="הכל",מלאי!O183=#REF!),OR(#REF!="הכל",מלאי!R183=#REF!),OR(#REF!="הכל",#REF!="",מלאי!W183=#REF!),OR(#REF!="הכל",#REF!="",ISNUMBER(SEARCH(#REF!,מלאי!C183))),OR(#REF!="הכל",מלאי!#REF!=#REF!)),1,0) -> #REF! | AF28: =IF(AD28=1,COUNTIF($AD$3:$AD28,1),"") -> #REF! | AG28: =IF(AE28=1,COUNTIF($AE$3:$AE28,1),"") -> #REF!
A29: Accessories | B29: Bag cover 90L | D29: B05 | E29: =IFERROR(INDEX(הגדרות!$I$2:$I$47,MATCH(B29,הגדרות!$H$2:$H$47,0)),"") -> 7009-01 | F29: Mesh | H29: Desert | J29: כן | T29: במלאי | Z29: =IFERROR(INDEX(הגדרות!$B$2:$B$17,MATCH(H29,הגדרות!$A$2:$A$17,0)),"") -> מדברי | AA29: =IFERROR(INDEX(הגדרות!$C$2:$C$17,MATCH(H29,הגדרות!$A$2:$A$17,0)),"") -> 0 | AB29: =IFERROR(INDEX(הגדרות!$B$2:$B$17,MATCH(I29,הגדרות!$A$2:$A$17,0)),"") | AC29: =IFERROR(INDEX(הגדרות!$C$2:$C$17,MATCH(I29,הגדרות!$A$2:$A$17,0)),"") | AD29: =IF(AND(מלאי!D184<>"",OR(#REF!="הכל",מלאי!Z184=#REF!,מלאי!AA184=#REF!,מלאי!AB184=#REF!,מלאי!AC184=#REF!),OR(#REF!="הכל",מלאי!A184=#REF!),OR(#REF!="הכל",מלאי!B184=#REF!),OR(#REF!="הכל",מלאי!F184=#REF!,מלאי!G184=#REF!),OR(#REF!="הכל",מלאי!T184=#REF!),OR(#REF!="הכל",מלאי!Q184=#REF!),OR(#REF!="הכל",מלאי!J184=#REF!),OR(#REF!="הכל",מלאי!L184=#REF!),OR(#REF!="הכל",מלאי!O184=#REF!),OR(#REF!="הכל",מלאי!R184=#REF!),OR(#REF!="הכל",#REF!="",מלאי!W184=#REF!),OR(#REF!="הכל",#REF!="",ISNUMBER(SEARCH(#REF!,מלאי!C184)))),1,0) -> #REF! | AE29: =IF(AND(מלאי!D184<>"",OR(#REF!="הכל",מלאי!Z184=#REF!,מלאי!AA184=#REF!,מלאי!AB184=#REF!,מלאי!AC184=#REF!),OR(#REF!="הכל",מלאי!A184=#REF!),OR(#REF!="הכל",מלאי!B184=#REF!),OR(#REF!="הכל",מלאי!F184=#REF!,מלאי!G184=#REF!),OR(#REF!="הכל",מלאי!T184=#REF!),OR(#REF!="הכל",מלאי!Q184=#REF!),OR(#REF!="הכל",מלאי!J184=#REF!),OR(#REF!="הכל",מלאי!L184=#REF!),OR(#REF!="הכל",מלאי!O184=#REF!),OR(#REF!="הכל",מלאי!R184=#REF!),OR(#REF!="הכל",#REF!="",מלאי!W184=#REF!),OR(#REF!="הכל",#REF!="",ISNUMBER(SEARCH(#REF!,מלאי!C184))),OR(#REF!="הכל",מלאי!#REF!=#REF!)),1,0) -> #REF! | AF29: =IF(AD29=1,COUNTIF($AD$3:$AD29,1),"") -> #REF! | AG29: =IF(AE29=1,COUNTIF($AE$3:$AE29,1),"") -> #REF!
A30: Accessories | B30: Bag cover 90L | D30: B06 | E30: =IFERROR(INDEX(הגדרות!$I$2:$I$47,MATCH(B30,הגדרות!$H$2:$H$47,0)),"") -> 7009-01 | F30: Mesh | H30: Kestrel | J30: כן | T30: במלאי | Z30: =IFERROR(INDEX(הגדרות!$B$2:$B$17,MATCH(H30,הגדרות!$A$2:$A$17,0)),"") -> מיוער | AA30: =IFERROR(INDEX(הגדרות!$C$2:$C$17,MATCH(H30,הגדרות!$A$2:$A$17,0)),"") -> 0 | AB30: =IFERROR(INDEX(הגדרות!$B$2:$B$17,MATCH(I30,הגדרות!$A$2:$A$17,0)),"") | AC30: =IFERROR(INDEX(הגדרות!$C$2:$C$17,MATCH(I30,הגדרות!$A$2:$A$17,0)),"") | AD30: =IF(AND(מלאי!D185<>"",OR(#REF!="הכל",מלאי!Z185=#REF!,מלאי!AA185=#REF!,מלאי!AB185=#REF!,מלאי!AC185=#REF!),OR(#REF!="הכל",מלאי!A185=#REF!),OR(#REF!="הכל",מלאי!B185=#REF!),OR(#REF!="הכל",מלאי!F185=#REF!,מלאי!G185=#REF!),OR(#REF!="הכל",מלאי!T185=#REF!),OR(#REF!="הכל",מלאי!Q185=#REF!),OR(#REF!="הכל",מלאי!J185=#REF!),OR(#REF!="הכל",מלאי!L185=#REF!),OR(#REF!="הכל",מלאי!O185=#REF!),OR(#REF!="הכל",מלאי!R185=#REF!),OR(#REF!="הכל",#REF!="",מלאי!W185=#REF!),OR(#REF!="הכל",#REF!="",ISNUMBER(SEARCH(#REF!,מלאי!C185)))),1,0) -> #REF! | AE30: =IF(AND(מלאי!D185<>"",OR(#REF!="הכל",מלאי!Z185=#REF!,מלאי!AA185=#REF!,מלאי!AB185=#REF!,מלאי!AC185=#REF!),OR(#REF!="הכל",מלאי!A185=#REF!),OR(#REF!="הכל",מלאי!B185=#REF!),OR(#REF!="הכל",מלאי!F185=#REF!,מלאי!G185=#REF!),OR(#REF!="הכל",מלאי!T185=#REF!),OR(#REF!="הכל",מלאי!Q185=#REF!),OR(#REF!="הכל",מלאי!J185=#REF!),OR(#REF!="הכל",מלאי!L185=#REF!),OR(#REF!="הכל",מלאי!O185=#REF!),OR(#REF!="הכל",מלאי!R185=#REF!),OR(#REF!="הכל",#REF!="",מלאי!W185=#REF!),OR(#REF!="הכל",#REF!="",ISNUMBER(SEARCH(#REF!,מלאי!C185))),OR(#REF!="הכל",מלאי!#REF!=#REF!)),1,0) -> #REF! | AF30: =IF(AD30=1,COUNTIF($AD$3:$AD30,1),"") -> #REF! | AG30: =IF(AE30=1,COUNTIF($AE$3:$AE30,1),"") -> #REF!
A31: Uniform | B31: Balaclava | D31: בלקלבה מלאי 01 | E31: =IFERROR(INDEX(הגדרות!$I$2:$I$47,MATCH(B31,הגדרות!$H$2:$H$47,0)),"") -> 8006-00 | F31: Stretch | Z31: =IFERROR(INDEX(הגדרות!$B$2:$B$17,MATCH(H31,הגדרות!$A$2:$A$17,0)),"") | AA31: =IFERROR(INDEX(הגדרות!$C$2:$C$17,MATCH(H31,הגדרות!$A$2:$A$17,0)),"") | AB31: =IFERROR(INDEX(הגדרות!$B$2:$B$17,MATCH(I31,הגדרות!$A$2:$A$17,0)),"") | AC31: =IFERROR(INDEX(הגדרות!$C$2:$C$17,MATCH(I31,הגדרות!$A$2:$A$17,0)),"") | AD31: =IF(AND(מלאי!D165<>"",OR(#REF!="הכל",מלאי!Z165=#REF!,מלאי!AA165=#REF!,מלאי!AB165=#REF!,מלאי!AC165=#REF!),OR(#REF!="הכל",מלאי!A165=#REF!),OR(#REF!="הכל",מלאי!B165=#REF!),OR(#REF!="הכל",מלאי!F165=#REF!,מלאי!G165=#REF!),OR(#REF!="הכל",מלאי!T165=#REF!),OR(#REF!="הכל",מלאי!Q165=#REF!),OR(#REF!="הכל",מלאי!J165=#REF!),OR(#REF!="הכל",מלאי!L165=#REF!),OR(#REF!="הכל",מלאי!O165=#REF!),OR(#REF!="הכל",מלאי!R165=#REF!),OR(#REF!="הכל",#REF!="",מלאי!W165=#REF!),OR(#REF!="הכל",#REF!="",ISNUMBER(SEARCH(#REF!,מלאי!C165)))),1,0) -> #REF! | AE31: =IF(AND(מלאי!D165<>"",OR(#REF!="הכל",מלאי!Z165=#REF!,מלאי!AA165=#REF!,מלאי!AB165=#REF!,מלאי!AC165=#REF!),OR(#REF!="הכל",מלאי!A165=#REF!),OR(#REF!="הכל",מלאי!B165=#REF!),OR(#REF!="הכל",מלאי!F165=#REF!,מלאי!G165=#REF!),OR(#REF!="הכל",מלאי!T165=#REF!),OR(#REF!="הכל",מלאי!Q165=#REF!),OR(#REF!="הכל",מלאי!J165=#REF!),OR(#REF!="הכל",מלאי!L165=#REF!),OR(#REF!="הכל",מלאי!O165=#REF!),OR(#REF!="הכל",מלאי!R165=#REF!),OR(#REF!="הכל",#REF!="",מלאי!W165=#REF!),OR(#REF!="הכל",#REF!="",ISNUMBER(SEARCH(#REF!,מלאי!C165))),OR(#REF!="הכל",מלאי!#REF!=#REF!)),1,0) -> #REF! | AF31: =IF(AD31=1,COUNTIF($AD$3:$AD31,1),"") -> #REF! | AG31: =IF(AE31=1,COUNTIF($AE$3:$AE31,1),"") -> #REF!
A32: Uniform | B32: Balaclava | D32: B01 | E32: =IFERROR(INDEX(הגדרות!$I$2:$I$47,MATCH(B32,הגדרות!$H$2:$H$47,0)),"") -> 8006-00 | F32: Stretch | H32: Marine | J32: כן | T32: במלאי | Z32: =IFERROR(INDEX(הגדרות!$B$2:$B$17,MATCH(H32,הגדרות!$A$2:$A$17,0)),"") -> ימי | AA32: =IFERROR(INDEX(הגדרות!$C$2:$C$17,MATCH(H32,הגדרות!$A$2:$A$17,0)),"") -> 0 | AB32: =IFERROR(INDEX(הגדרות!$B$2:$B$17,MATCH(I32,הגדרות!$A$2:$A$17,0)),"") | AC32: =IFERROR(INDEX(הגדרות!$C$2:$C$17,MATCH(I32,הגדרות!$A$2:$A$17,0)),"") | AD32: =IF(AND(מלאי!D180<>"",OR(#REF!="הכל",מלאי!Z180=#REF!,מלאי!AA180=#REF!,מלאי!AB180=#REF!,מלאי!AC180=#REF!),OR(#REF!="הכל",מלאי!A180=#REF!),OR(#REF!="הכל",מלאי!B180=#REF!),OR(#REF!="הכל",מלאי!F180=#REF!,מלאי!G180=#REF!),OR(#REF!="הכל",מלאי!T180=#REF!),OR(#REF!="הכל",מלאי!Q180=#REF!),OR(#REF!="הכל",מלאי!J180=#REF!),OR(#REF!="הכל",מלאי!L180=#REF!),OR(#REF!="הכל",מלאי!O180=#REF!),OR(#REF!="הכל",מלאי!R180=#REF!),OR(#REF!="הכל",#REF!="",מלאי!W180=#REF!),OR(#REF!="הכל",#REF!="",ISNUMBER(SEARCH(#REF!,מלאי!C180)))),1,0) -> #REF! | AE32: =IF(AND(מלאי!D180<>"",OR(#REF!="הכל",מלאי!Z180=#REF!,מלאי!AA180=#REF!,מלאי!AB180=#REF!,מלאי!AC180=#REF!),OR(#REF!="הכל",מלאי!A180=#REF!),OR(#REF!="הכל",מלאי!B180=#REF!),OR(#REF!="הכל",מלאי!F180=#REF!,מלאי!G180=#REF!),OR(#REF!="הכל",מלאי!T180=#REF!),OR(#REF!="הכל",מלאי!Q180=#REF!),OR(#REF!="הכל",מלאי!J180=#REF!),OR(#REF!="הכל",מלאי!L180=#REF!),OR(#REF!="הכל",מלאי!O180=#REF!),OR(#REF!="הכל",מלאי!R180=#REF!),OR(#REF!="הכל",#REF!="",מלאי!W180=#REF!),OR(#REF!="הכל",#REF!="",ISNUMBER(SEARCH(#REF!,מלאי!C180))),OR(#REF!="הכל",מלאי!#REF!=#REF!)),1,0) -> #REF! | AF32: =IF(AD32=1,COUNTIF($AD$3:$AD32,1),"") -> #REF! | AG32: =IF(AE32=1,COUNTIF($AE$3:$AE32,1),"") -> #REF!
A33: Uniform | B33: Balaclava | D33: B02 | E33: =IFERROR(INDEX(הגדרות!$I$2:$I$47,MATCH(B33,הגדרות!$H$2:$H$47,0)),"") -> 8006-00 | F33: Stretch | H33: Marine | J33: כן | L33: לא | T33: במלאי | Z33: =IFERROR(INDEX(הגדרות!$B$2:$B$17,MATCH(H33,הגדרות!$A$2:$A$17,0)),"") -> ימי | AA33: =IFERROR(INDEX(הגדרות!$C$2:$C$17,MATCH(H33,הגדרות!$A$2:$A$17,0)),"") -> 0 | AB33: =IFERROR(INDEX(הגדרות!$B$2:$B$17,MATCH(I33,הגדרות!$A$2:$A$17,0)),"") | AC33: =IFERROR(INDEX(הגדרות!$C$2:$C$17,MATCH(I33,הגדרות!$A$2:$A$17,0)),"") | AD33: =IF(AND(מלאי!D181<>"",OR(#REF!="הכל",מלאי!Z181=#REF!,מלאי!AA181=#REF!,מלאי!AB181=#REF!,מלאי!AC181=#REF!),OR(#REF!="הכל",מלאי!A181=#REF!),OR(#REF!="הכל",מלאי!B181=#REF!),OR(#REF!="הכל",מלאי!F181=#REF!,מלאי!G181=#REF!),OR(#REF!="הכל",מלאי!T181=#REF!),OR(#REF!="הכל",מלאי!Q181=#REF!),OR(#REF!="הכל",מלאי!J181=#REF!),OR(#REF!="הכל",מלאי!L181=#REF!),OR(#REF!="הכל",מלאי!O181=#REF!),OR(#REF!="הכל",מלאי!R181=#REF!),OR(#REF!="הכל",#REF!="",מלאי!W181=#REF!),OR(#REF!="הכל",#REF!="",ISNUMBER(SEARCH(#REF!,מלאי!C181)))),1,0) -> #REF! | AE33: =IF(AND(מלאי!D181<>"",OR(#REF!="הכל",מלאי!Z181=#REF!,מלאי!AA181=#REF!,מלאי!AB181=#REF!,מלאי!AC181=#REF!),OR(#REF!="הכל",מלאי!A181=#REF!),OR(#REF!="הכל",מלאי!B181=#REF!),OR(#REF!="הכל",מלאי!F181=#REF!,מלאי!G181=#REF!),OR(#REF!="הכל",מלאי!T181=#REF!),OR(#REF!="הכל",מלאי!Q181=#REF!),OR(#REF!="הכל",מלאי!J181=#REF!),OR(#REF!="הכל",מלאי!L181=#REF!),OR(#REF!="הכל",מלאי!O181=#REF!),OR(#REF!="הכל",מלאי!R181=#REF!),OR(#REF!="הכל",#REF!="",מלאי!W181=#REF!),OR(#REF!="הכל",#REF!="",ISNUMBER(SEARCH(#REF!,מלאי!C181))),OR(#REF!="הכל",מלאי!#REF!=#REF!)),1,0) -> #REF! | AF33: =IF(AD33=1,COUNTIF($AD$3:$AD33,1),"") -> #REF! | AG33: =IF(AE33=1,COUNTIF($AE$3:$AE33,1),"") -> #REF!
A34: Uniform | B34: Balaclava | D34: UNI034 | E34: =IFERROR(INDEX(הגדרות!$I$2:$I$47,MATCH(B34,הגדרות!$H$2:$H$47,0)),"") -> 8006-00 | F34: Stretch | H34: Fresh Snow | J34: כן | T34: במלאי | Z34: =IFERROR(INDEX(הגדרות!$B$2:$B$17,MATCH(H34,הגדרות!$A$2:$A$17,0)),"") -> שלג | AA34: =IFERROR(INDEX(הגדרות!$C$2:$C$17,MATCH(H34,הגדרות!$A$2:$A$17,0)),"") -> 0 | AB34: =IFERROR(INDEX(הגדרות!$B$2:$B$17,MATCH(I34,הגדרות!$A$2:$A$17,0)),"") | AC34: =IFERROR(INDEX(הגדרות!$C$2:$C$17,MATCH(I34,הגדרות!$A$2:$A$17,0)),"") | AD34: =IF(AND(מלאי!D189<>"",OR(#REF!="הכל",מלאי!Z189=#REF!,מלאי!AA189=#REF!,מלאי!AB189=#REF!,מלאי!AC189=#REF!),OR(#REF!="הכל",מלאי!A189=#REF!),OR(#REF!="הכל",מלאי!B189=#REF!),OR(#REF!="הכל",מלאי!F189=#REF!,מלאי!G189=#REF!),OR(#REF!="הכל",מלאי!T189=#REF!),OR(#REF!="הכל",מלאי!Q189=#REF!),OR(#REF!="הכל",מלאי!J189=#REF!),OR(#REF!="הכל",מלאי!L189=#REF!),OR(#REF!="הכל",מלאי!O189=#REF!),OR(#REF!="הכל",מלאי!R189=#REF!),OR(#REF!="הכל",#REF!="",מלאי!W189=#REF!),OR(#REF!="הכל",#REF!="",ISNUMBER(SEARCH(#REF!,מלאי!C189)))),1,0) -> #REF! | AE34: =IF(AND(מלאי!D189<>"",OR(#REF!="הכל",מלאי!Z189=#REF!,מלאי!AA189=#REF!,מלאי!AB189=#REF!,מלאי!AC189=#REF!),OR(#REF!="הכל",מלאי!A189=#REF!),OR(#REF!="הכל",מלאי!B189=#REF!),OR(#REF!="הכל",מלאי!F189=#REF!,מלאי!G189=#REF!),OR(#REF!="הכל",מלאי!T189=#REF!),OR(#REF!="הכל",מלאי!Q189=#REF!),OR(#REF!="הכל",מלאי!J189=#REF!),OR(#REF!="הכל",מלאי!L189=#REF!),OR(#REF!="הכל",מלאי!O189=#REF!),OR(#REF!="הכל",מלאי!R189=#REF!),OR(#REF!="הכל",#REF!="",מלאי!W189=#REF!),OR(#REF!="הכל",#REF!="",ISNUMBER(SEARCH(#REF!,מלאי!C189))),OR(#REF!="הכל",מלאי!#REF!=#REF!)),1,0) -> #REF! | AF34: =IF(AD34=1,COUNTIF($AD$3:$AD34,1),"") -> #REF! | AG34: =IF(AE34=1,COUNTIF($AE$3:$AE34,1),"") -> #REF!
A35: Uniform | B35: Boonie hat | C35: V1 | D35: UNI 003 | E35: =IFERROR(INDEX(הגדרות!$I$2:$I$47,MATCH(B35,הגדרות!$H$2:$H$47,0)),"") -> 7022-00 | F35: Stretch | H35: Kestrel | J35: כן | Q35: כן | T35: במלאי | Z35: =IFERROR(INDEX(הגדרות!$B$2:$B$17,MATCH(H35,הגדרות!$A$2:$A$17,0)),"") -> מיוער | AA35: =IFERROR(INDEX(הגדרות!$C$2:$C$17,MATCH(H35,הגדרות!$A$2:$A$17,0)),"") -> 0 | AB35: =IFERROR(INDEX(הגדרות!$B$2:$B$17,MATCH(I35,הגדרות!$A$2:$A$17,0)),"") | AC35: =IFERROR(INDEX(הגדרות!$C$2:$C$17,MATCH(I35,הגדרות!$A$2:$A$17,0)),"") | AD35: =IF(AND(מלאי!D169<>"",OR(#REF!="הכל",מלאי!Z169=#REF!,מלאי!AA169=#REF!,מלאי!AB169=#REF!,מלאי!AC169=#REF!),OR(#REF!="הכל",מלאי!A169=#REF!),OR(#REF!="הכל",מלאי!B169=#REF!),OR(#REF!="הכל",מלאי!F169=#REF!,מלאי!G169=#REF!),OR(#REF!="הכל",מלאי!T169=#REF!),OR(#REF!="הכל",מלאי!Q169=#REF!),OR(#REF!="הכל",מלאי!J169=#REF!),OR(#REF!="הכל",מלאי!L169=#REF!),OR(#REF!="הכל",מלאי!O169=#REF!),OR(#REF!="הכל",מלאי!R169=#REF!),OR(#REF!="הכל",#REF!="",מלאי!W169=#REF!),OR(#REF!="הכל",#REF!="",ISNUMBER(SEARCH(#REF!,מלאי!C169)))),1,0) -> #REF! | AE35: =IF(AND(מלאי!D169<>"",OR(#REF!="הכל",מלאי!Z169=#REF!,מלאי!AA169=#REF!,מלאי!AB169=#REF!,מלאי!AC169=#REF!),OR(#REF!="הכל",מלאי!A169=#REF!),OR(#REF!="הכל",מלאי!B169=#REF!),OR(#REF!="הכל",מלאי!F169=#REF!,מלאי!G169=#REF!),OR(#REF!="הכל",מלאי!T169=#REF!),OR(#REF!="הכל",מלאי!Q169=#REF!),OR(#REF!="הכל",מלאי!J169=#REF!),OR(#REF!="הכל",מלאי!L169=#REF!),OR(#REF!="הכל",מלאי!O169=#REF!),OR(#REF!="הכל",מלאי!R169=#REF!),OR(#REF!="הכל",#REF!="",מלאי!W169=#REF!),OR(#REF!="הכל",#REF!="",ISNUMBER(SEARCH(#REF!,מלאי!C169))),OR(#REF!="הכל",מלאי!#REF!=#REF!)),1,0) -> #REF! | AF35: =IF(AD35=1,COUNTIF($AD$3:$AD35,1),"") -> #REF! | AG35: =IF(AE35=1,COUNTIF($AE$3:$AE35,1),"") -> #REF!
